Workbook
Name P2_PRINT_RANGE: OFFSET('Печать'!$A$1,0,0,MAX(8,8+COUNT('Печать'!$K$5:$K$104)),10)

Sheet Реестр
A1: Расчёт стоимости дополнительных работ
A2: Расчёт № {{НОМЕР}} от {{ДАТА}} к договору № {{НОМЕР_ДОГОВОРА}} от {{ДАТА_ДОГОВОРА}}. Объект: {{ОБЪЕКТ}}. Подрядчик: {{ПОДРЯДЧИК}}. Заказчик: {{ЗАКАЗЧИК}}.
A3: № | B3: Работа/ресурс | C3: Ед. | D3: Кол-во | E3: Цена | F3: Сумма | G3: Источник цены | H3: Коэффициент | I3: Итого с коэффициентом | J3: Комментарий
F4: =IF(COUNTA(B4:E4,G4:H4)=0,"",IF(OR(B4="",NOT(ISNUMBER(D4)),NOT(ISNUMBER(E4)),D4<=0,E4<0),"НЕ ЗАВЕРШЕНО",D4*E4)) | I4: =IF(F4="","",IF(OR(NOT(ISNUMBER(F4)),AND(H4<>"",OR(NOT(ISNUMBER(H4)),H4<=0))),"НЕ ЗАВЕРШЕНО",F4*IF(H4="",1,H4)))
F5: =IF(COUNTA(B5:E5,G5:H5)=0,"",IF(OR(B5="",NOT(ISNUMBER(D5)),NOT(ISNUMBER(E5)),D5<=0,E5<0),"НЕ ЗАВЕРШЕНО",D5*E5)) | I5: =IF(F5="","",IF(OR(NOT(ISNUMBER(F5)),AND(H5<>"",OR(NOT(ISNUMBER(H5)),H5<=0))),"НЕ ЗАВЕРШЕНО",F5*IF(H5="",1,H5)))
F6: =IF(COUNTA(B6:E6,G6:H6)=0,"",IF(OR(B6="",NOT(ISNUMBER(D6)),NOT(ISNUMBER(E6)),D6<=0,E6<0),"НЕ ЗАВЕРШЕНО",D6*E6)) | I6: =IF(F6="","",IF(OR(NOT(ISNUMBER(F6)),AND(H6<>"",OR(NOT(ISNUMBER(H6)),H6<=0))),"НЕ ЗАВЕРШЕНО",F6*IF(H6="",1,H6)))
F7: =IF(COUNTA(B7:E7,G7:H7)=0,"",IF(OR(B7="",NOT(ISNUMBER(D7)),NOT(ISNUMBER(E7)),D7<=0,E7<0),"НЕ ЗАВЕРШЕНО",D7*E7)) | I7: =IF(F7="","",IF(OR(NOT(ISNUMBER(F7)),AND(H7<>"",OR(NOT(ISNUMBER(H7)),H7<=0))),"НЕ ЗАВЕРШЕНО",F7*IF(H7="",1,H7)))
F8: =IF(COUNTA(B8:E8,G8:H8)=0,"",IF(OR(B8="",NOT(ISNUMBER(D8)),NOT(ISNUMBER(E8)),D8<=0,E8<0),"НЕ ЗАВЕРШЕНО",D8*E8)) | I8: =IF(F8="","",IF(OR(NOT(ISNUMBER(F8)),AND(H8<>"",OR(NOT(ISNUMBER(H8)),H8<=0))),"НЕ ЗАВЕРШЕНО",F8*IF(H8="",1,H8)))
F9: =IF(COUNTA(B9:E9,G9:H9)=0,"",IF(OR(B9="",NOT(ISNUMBER(D9)),NOT(ISNUMBER(E9)),D9<=0,E9<0),"НЕ ЗАВЕРШЕНО",D9*E9)) | I9: =IF(F9="","",IF(OR(NOT(ISNUMBER(F9)),AND(H9<>"",OR(NOT(ISNUMBER(H9)),H9<=0))),"НЕ ЗАВЕРШЕНО",F9*IF(H9="",1,H9)))
F10: =IF(COUNTA(B10:E10,G10:H10)=0,"",IF(OR(B10="",NOT(ISNUMBER(D10)),NOT(ISNUMBER(E10)),D10<=0,E10<0),"НЕ ЗАВЕРШЕНО",D10*E10)) | I10: =IF(F10="","",IF(OR(NOT(ISNUMBER(F10)),AND(H10<>"",OR(NOT(ISNUMBER(H10)),H10<=0))),"НЕ ЗАВЕРШЕНО",F10*IF(H10="",1,H10)))
F11: =IF(COUNTA(B11:E11,G11:H11)=0,"",IF(OR(B11="",NOT(ISNUMBER(D11)),NOT(ISNUMBER(E11)),D11<=0,E11<0),"НЕ ЗАВЕРШЕНО",D11*E11)) | I11: =IF(F11="","",IF(OR(NOT(ISNUMBER(F11)),AND(H11<>"",OR(NOT(ISNUMBER(H11)),H11<=0))),"НЕ ЗАВЕРШЕНО",F11*IF(H11="",1,H11)))
F12: =IF(COUNTA(B12:E12,G12:H12)=0,"",IF(OR(B12="",NOT(ISNUMBER(D12)),NOT(ISNUMBER(E12)),D12<=0,E12<0),"НЕ ЗАВЕРШЕНО",D12*E12)) | I12: =IF(F12="","",IF(OR(NOT(ISNUMBER(F12)),AND(H12<>"",OR(NOT(ISNUMBER(H12)),H12<=0))),"НЕ ЗАВЕРШЕНО",F12*IF(H12="",1,H12)))
F13: =IF(COUNTA(B13:E13,G13:H13)=0,"",IF(OR(B13="",NOT(ISNUMBER(D13)),NOT(ISNUMBER(E13)),D13<=0,E13<0),"НЕ ЗАВЕРШЕНО",D13*E13)) | I13: =IF(F13="","",IF(OR(NOT(ISNUMBER(F13)),AND(H13<>"",OR(NOT(ISNUMBER(H13)),H13<=0))),"НЕ ЗАВЕРШЕНО",F13*IF(H13="",1,H13)))
F14: =IF(COUNTA(B14:E14,G14:H14)=0,"",IF(OR(B14="",NOT(ISNUMBER(D14)),NOT(ISNUMBER(E14)),D14<=0,E14<0),"НЕ ЗАВЕРШЕНО",D14*E14)) | I14: =IF(F14="","",IF(OR(NOT(ISNUMBER(F14)),AND(H14<>"",OR(NOT(ISNUMBER(H14)),H14<=0))),"НЕ ЗАВЕРШЕНО",F14*IF(H14="",1,H14)))
F15: =IF(COUNTA(B15:E15,G15:H15)=0,"",IF(OR(B15="",NOT(ISNUMBER(D15)),NOT(ISNUMBER(E15)),D15<=0,E15<0),"НЕ ЗАВЕРШЕНО",D15*E15)) | I15: =IF(F15="","",IF(OR(NOT(ISNUMBER(F15)),AND(H15<>"",OR(NOT(ISNUMBER(H15)),H15<=0))),"НЕ ЗАВЕРШЕНО",F15*IF(H15="",1,H15)))
... F103: =IF(COUNTA(B103:E103,G103:H103)=0,"",IF(OR(B103="",NOT(ISNUMBER(D103)),NOT(ISNUMBER(E103)),D103<=0,E103<0),"НЕ ЗАВЕРШЕНО",D103*E103)) | I103: =IF(F103="","",IF(OR(NOT(ISNUMBER(F103)),AND(H103<>"",OR(NOT(ISNUMBER(H103)),H103<=0))),"НЕ ЗАВЕРШЕНО",F103*IF(H103="",1,H103)))
A104: =IF(COUNTA(B4:E103,G4:H103)=0,"НЕТ ДАННЫХ",IF(COUNTIF(I4:I103,"НЕ ЗАВЕРШЕНО")>0,"Предварительно; неполных: "&COUNTIF(I4:I103,"НЕ ЗАВЕРШЕНО"),"Позиции заполнены")) -> НЕТ ДАННЫХ | F104: =SUM(F4:F103) | H104: Итого | I104: =SUM(I4:I103)
A106: Подрядчик | F106: Заказчик
A107: {{ДОЛЖНОСТЬ_ФИО_ПОЛНОМОЧИЯ}} Подпись __________________ Дата __________________ | F107: {{ДОЛЖНОСТЬ_ФИО_ПОЛНОМОЧИЯ}} Подпись __________________ Дата __________________

Sheet Инструкция
A1: Расчёт стоимости дополнительных работ
A3: По каждой позиции укажите работу или ресурс, единицу измерения, количество, цену и источник цены с номером и датой документа. Коэффициент 1,15 увеличивает стоимость на 15%; пустая ячейка коэффициента учитывается как 1. Проверьте суммы, договорные реквизиты и подписи. Приложите согласованный расчёт к соглашению 11.

Sheet Печать
A1: Расчёт стоимости дополнительных работ
A2: Расчёт № {{НОМЕР}} от {{ДАТА}} к договору № {{НОМЕР_ДОГОВОРА}} от {{ДАТА_ДОГОВОРА}}. Объект: {{ОБЪЕКТ}}. Подрядчик: {{ПОДРЯДЧИК}}. Заказчик: {{ЗАКАЗЧИК}}.
A3: ="Статус: "&'Реестр'!A104&" | Количество позиций: "&$K$3 | K3: =COUNT($K$5:$K$104)
A4: № | B4: Работа/ресурс | C4: Ед. | D4: Кол-во | E4: Цена | F4: Сумма | G4: Источник цены | H4: Коэффициент | I4: Итого с коэффициентом | J4: Комментарий
A5: =IF(ISNUMBER($K5),$K5,"") | B5: =IF(ISNUMBER($K5),IF(INDEX('Реестр'!$B$4:$B$103,$K5)="","",INDEX('Реестр'!$B$4:$B$103,$K5)),IF(ROW()=$K$3+5,"ИТОГО",IF(ROW()=$K$3+6,"ПОДРЯДЧИК",IF(ROW()=$K$3+7,"Должн./ФИО:",IF(ROW()=$K$3+8,"Подпись:",""))))) | C5: =IF(ISNUMBER($K5),IF(INDEX('Реестр'!$C$4:$C$103,$K5)="","",INDEX('Реестр'!$C$4:$C$103,$K5)),IF(ROW()=$K$3+7,"________________",IF(ROW()=$K$3+8,"________________",""))) | D5: =IF(ISNUMBER($K5),IF(INDEX('Реестр'!$D$4:$D$103,$K5)="","",INDEX('Реестр'!$D$4:$D$103,$K5)),IF(ROW()=$K$3+8,"Дата:","")) | E5: =IF(ISNUMBER($K5),IF(INDEX('Реестр'!$E$4:$E$103,$K5)="","",INDEX('Реестр'!$E$4:$E$103,$K5)),IF(ROW()=$K$3+8,"____________","")) | F5: =IF(ISNUMBER($K5),IF(INDEX('Реестр'!$F$4:$F$103,$K5)="","",INDEX('Реестр'!$F$4:$F$103,$K5)),IF(ROW()=$K$3+5,'Реестр'!F104,"")) | G5: =IF(ISNUMBER($K5),IF(INDEX('Реестр'!$G$4:$G$103,$K5)="","",INDEX('Реестр'!$G$4:$G$103,$K5)),IF(ROW()=$K$3+6,"ЗАКАЗЧИК",IF(ROW()=$K$3+7,"Должн./ФИО:",IF(ROW()=$K$3+8,"Подпись:","")))) | H5: =IF(ISNUMBER($K5),IF(INDEX('Реестр'!$H$4:$H$103,$K5)="","",INDEX('Реестр'!$H$4:$H$103,$K5)),IF(ROW()=$K$3+7,"________________",IF(ROW()=$K$3+8,"________________",""))) | I5: =IF(ISNUMBER($K5),IF(INDEX('Реестр'!$I$4:$I$103,$K5)="","",INDEX('Реестр'!$I$4:$I$103,$K5)),IF(ROW()=$K$3+5,'Реестр'!I104,IF(ROW()=$K$3+8,"Дата:",""))) | J5: =IF(ISNUMBER($K5),IF(INDEX('Реестр'!$J$4:$J$103,$K5)="","",INDEX('Реестр'!$J$4:$J$103,$K5)),IF(ROW()=$K$3+8,"____________","")) | K5: =IFERROR(_xlfn.AGGREGATE(15,6,(ROW('Реестр'!$B$4:$B$103)-3)/((('Реестр'!$B$4:$B$103<>"")+('Реестр'!$C$4:$C$103<>"")+('Реестр'!$D$4:$D$103<>"")+('Реестр'!$E$4:$E$103<>"")+('Реестр'!$G$4:$G$103<>"")+('Реестр'!$H$4:$H$103<>"")+('Реестр'!$J$4:$J$103<>""))>0),ROWS($K$5:K5)),"")
A6: =IF(ISNUMBER($K6),$K6,"") | B6: =IF(ISNUMBER($K6),IF(INDEX('Реестр'!$B$4:$B$103,$K6)="","",INDEX('Реестр'!$B$4:$B$103,$K6)),IF(ROW()=$K$3+5,"ИТОГО",IF(ROW()=$K$3+6,"ПОДРЯДЧИК",IF(ROW()=$K$3+7,"Должн./ФИО:",IF(ROW()=$K$3+8,"Подпись:",""))))) | C6: =IF(ISNUMBER($K6),IF(INDEX('Реестр'!$C$4:$C$103,$K6)="","",INDEX('Реестр'!$C$4:$C$103,$K6)),IF(ROW()=$K$3+7,"________________",IF(ROW()=$K$3+8,"________________",""))) | D6: =IF(ISNUMBER($K6),IF(INDEX('Реестр'!$D$4:$D$103,$K6)="","",INDEX('Реестр'!$D$4:$D$103,$K6)),IF(ROW()=$K$3+8,"Дата:","")) | E6: =IF(ISNUMBER($K6),IF(INDEX('Реестр'!$E$4:$E$103,$K6)="","",INDEX('Реестр'!$E$4:$E$103,$K6)),IF(ROW()=$K$3+8,"____________","")) | F6: =IF(ISNUMBER($K6),IF(INDEX('Реестр'!$F$4:$F$103,$K6)="","",INDEX('Реестр'!$F$4:$F$103,$K6)),IF(ROW()=$K$3+5,'Реестр'!F104,"")) | G6: =IF(ISNUMBER($K6),IF(INDEX('Реестр'!$G$4:$G$103,$K6)="","",INDEX('Реестр'!$G$4:$G$103,$K6)),IF(ROW()=$K$3+6,"ЗАКАЗЧИК",IF(ROW()=$K$3+7,"Должн./ФИО:",IF(ROW()=$K$3+8,"Подпись:","")))) | H6: =IF(ISNUMBER($K6),IF(INDEX('Реестр'!$H$4:$H$103,$K6)="","",INDEX('Реестр'!$H$4:$H$103,$K6)),IF(ROW()=$K$3+7,"________________",IF(ROW()=$K$3+8,"________________",""))) | I6: =IF(ISNUMBER($K6),IF(INDEX('Реестр'!$I$4:$I$103,$K6)="","",INDEX('Реестр'!$I$4:$I$103,$K6)),IF(ROW()=$K$3+5,'Реестр'!I104,IF(ROW()=$K$3+8,"Дата:",""))) | J6: =IF(ISNUMBER($K6),IF(INDEX('Реестр'!$J$4:$J$103,$K6)="","",INDEX('Реестр'!$J$4:$J$103,$K6)),IF(ROW()=$K$3+8,"____________","")) | K6: =IFERROR(_xlfn.AGGREGATE(15,6,(ROW('Реестр'!$B$4:$B$103)-3)/((('Реестр'!$B$4:$B$103<>"")+('Реестр'!$C$4:$C$103<>"")+('Реестр'!$D$4:$D$103<>"")+('Реестр'!$E$4:$E$103<>"")+('Реестр'!$G$4:$G$103<>"")+('Реестр'!$H$4:$H$103<>"")+('Реестр'!$J$4:$J$103<>""))>0),ROWS($K$5:K6)),"")
A7: =IF(ISNUMBER($K7),$K7,"") | B7: =IF(ISNUMBER($K7),IF(INDEX('Реестр'!$B$4:$B$103,$K7)="","",INDEX('Реестр'!$B$4:$B$103,$K7)),IF(ROW()=$K$3+5,"ИТОГО",IF(ROW()=$K$3+6,"ПОДРЯДЧИК",IF(ROW()=$K$3+7,"Должн./ФИО:",IF(ROW()=$K$3+8,"Подпись:",""))))) | C7: =IF(ISNUMBER($K7),IF(INDEX('Реестр'!$C$4:$C$103,$K7)="","",INDEX('Реестр'!$C$4:$C$103,$K7)),IF(ROW()=$K$3+7,"________________",IF(ROW()=$K$3+8,"________________",""))) | D7: =IF(ISNUMBER($K7),IF(INDEX('Реестр'!$D$4:$D$103,$K7)="","",INDEX('Реестр'!$D$4:$D$103,$K7)),IF(ROW()=$K$3+8,"Дата:","")) | E7: =IF(ISNUMBER($K7),IF(INDEX('Реестр'!$E$4:$E$103,$K7)="","",INDEX('Реестр'!$E$4:$E$103,$K7)),IF(ROW()=$K$3+8,"____________","")) | F7: =IF(ISNUMBER($K7),IF(INDEX('Реестр'!$F$4:$F$103,$K7)="","",INDEX('Реестр'!$F$4:$F$103,$K7)),IF(ROW()=$K$3+5,'Реестр'!F104,"")) | G7: =IF(ISNUMBER($K7),IF(INDEX('Реестр'!$G$4:$G$103,$K7)="","",INDEX('Реестр'!$G$4:$G$103,$K7)),IF(ROW()=$K$3+6,"ЗАКАЗЧИК",IF(ROW()=$K$3+7,"Должн./ФИО:",IF(ROW()=$K$3+8,"Подпись:","")))) | H7: =IF(ISNUMBER($K7),IF(INDEX('Реестр'!$H$4:$H$103,$K7)="","",INDEX('Реестр'!$H$4:$H$103,$K7)),IF(ROW()=$K$3+7,"________________",IF(ROW()=$K$3+8,"________________",""))) | I7: =IF(ISNUMBER($K7),IF(INDEX('Реестр'!$I$4:$I$103,$K7)="","",INDEX('Реестр'!$I$4:$I$103,$K7)),IF(ROW()=$K$3+5,'Реестр'!I104,IF(ROW()=$K$3+8,"Дата:",""))) | J7: =IF(ISNUMBER($K7),IF(INDEX('Реестр'!$J$4:$J$103,$K7)="","",INDEX('Реестр'!$J$4:$J$103,$K7)),IF(ROW()=$K$3+8,"____________","")) | K7: =IFERROR(_xlfn.AGGREGATE(15,6,(ROW('Реестр'!$B$4:$B$103)-3)/((('Реестр'!$B$4:$B$103<>"")+('Реестр'!$C$4:$C$103<>"")+('Реестр'!$D$4:$D$103<>"")+('Реестр'!$E$4:$E$103<>"")+('Реестр'!$G$4:$G$103<>"")+('Реестр'!$H$4:$H$103<>"")+('Реестр'!$J$4:$J$103<>""))>0),ROWS($K$5:K7)),"")
A8: =IF(ISNUMBER($K8),$K8,"") | B8: =IF(ISNUMBER($K8),IF(INDEX('Реестр'!$B$4:$B$103,$K8)="","",INDEX('Реестр'!$B$4:$B$103,$K8)),IF(ROW()=$K$3+5,"ИТОГО",IF(ROW()=$K$3+6,"ПОДРЯДЧИК",IF(ROW()=$K$3+7,"Должн./ФИО:",IF(ROW()=$K$3+8,"Подпись:",""))))) | C8: =IF(ISNUMBER($K8),IF(INDEX('Реестр'!$C$4:$C$103,$K8)="","",INDEX('Реестр'!$C$4:$C$103,$K8)),IF(ROW()=$K$3+7,"________________",IF(ROW()=$K$3+8,"________________",""))) | D8: =IF(ISNUMBER($K8),IF(INDEX('Реестр'!$D$4:$D$103,$K8)="","",INDEX('Реестр'!$D$4:$D$103,$K8)),IF(ROW()=$K$3+8,"Дата:","")) | E8: =IF(ISNUMBER($K8),IF(INDEX('Реестр'!$E$4:$E$103,$K8)="","",INDEX('Реестр'!$E$4:$E$103,$K8)),IF(ROW()=$K$3+8,"____________","")) | F8: =IF(ISNUMBER($K8),IF(INDEX('Реестр'!$F$4:$F$103,$K8)="","",INDEX('Реестр'!$F$4:$F$103,$K8)),IF(ROW()=$K$3+5,'Реестр'!F104,"")) | G8: =IF(ISNUMBER($K8),IF(INDEX('Реестр'!$G$4:$G$103,$K8)="","",INDEX('Реестр'!$G$4:$G$103,$K8)),IF(ROW()=$K$3+6,"ЗАКАЗЧИК",IF(ROW()=$K$3+7,"Должн./ФИО:",IF(ROW()=$K$3+8,"Подпись:","")))) | H8: =IF(ISNUMBER($K8),IF(INDEX('Реестр'!$H$4:$H$103,$K8)="","",INDEX('Реестр'!$H$4:$H$103,$K8)),IF(ROW()=$K$3+7,"________________",IF(ROW()=$K$3+8,"________________",""))) | I8: =IF(ISNUMBER($K8),IF(INDEX('Реестр'!$I$4:$I$103,$K8)="","",INDEX('Реестр'!$I$4:$I$103,$K8)),IF(ROW()=$K$3+5,'Реестр'!I104,IF(ROW()=$K$3+8,"Дата:",""))) | J8: =IF(ISNUMBER($K8),IF(INDEX('Реестр'!$J$4:$J$103,$K8)="","",INDEX('Реестр'!$J$4:$J$103,$K8)),IF(ROW()=$K$3+8,"____________","")) | K8: =IFERROR(_xlfn.AGGREGATE(15,6,(ROW('Реестр'!$B$4:$B$103)-3)/((('Реестр'!$B$4:$B$103<>"")+('Реестр'!$C$4:$C$103<>"")+('Реестр'!$D$4:$D$103<>"")+('Реестр'!$E$4:$E$103<>"")+('Реестр'!$G$4:$G$103<>"")+('Реестр'!$H$4:$H$103<>"")+('Реестр'!$J$4:$J$103<>""))>0),ROWS($K$5:K8)),"")
A9: =IF(ISNUMBER($K9),$K9,"") | B9: =IF(ISNUMBER($K9),IF(INDEX('Реестр'!$B$4:$B$103,$K9)="","",INDEX('Реестр'!$B$4:$B$103,$K9)),IF(ROW()=$K$3+5,"ИТОГО",IF(ROW()=$K$3+6,"ПОДРЯДЧИК",IF(ROW()=$K$3+7,"Должн./ФИО:",IF(ROW()=$K$3+8,"Подпись:",""))))) | C9: =IF(ISNUMBER($K9),IF(INDEX('Реестр'!$C$4:$C$103,$K9)="","",INDEX('Реестр'!$C$4:$C$103,$K9)),IF(ROW()=$K$3+7,"________________",IF(ROW()=$K$3+8,"________________",""))) | D9: =IF(ISNUMBER($K9),IF(INDEX('Реестр'!$D$4:$D$103,$K9)="","",INDEX('Реестр'!$D$4:$D$103,$K9)),IF(ROW()=$K$3+8,"Дата:","")) | E9: =IF(ISNUMBER($K9),IF(INDEX('Реестр'!$E$4:$E$103,$K9)="","",INDEX('Реестр'!$E$4:$E$103,$K9)),IF(ROW()=$K$3+8,"____________","")) | F9: =IF(ISNUMBER($K9),IF(INDEX('Реестр'!$F$4:$F$103,$K9)="","",INDEX('Реестр'!$F$4:$F$103,$K9)),IF(ROW()=$K$3+5,'Реестр'!F104,"")) | G9: =IF(ISNUMBER($K9),IF(INDEX('Реестр'!$G$4:$G$103,$K9)="","",INDEX('Реестр'!$G$4:$G$103,$K9)),IF(ROW()=$K$3+6,"ЗАКАЗЧИК",IF(ROW()=$K$3+7,"Должн./ФИО:",IF(ROW()=$K$3+8,"Подпись:","")))) | H9: =IF(ISNUMBER($K9),IF(INDEX('Реестр'!$H$4:$H$103,$K9)="","",INDEX('Реестр'!$H$4:$H$103,$K9)),IF(ROW()=$K$3+7,"________________",IF(ROW()=$K$3+8,"________________",""))) | I9: =IF(ISNUMBER($K9),IF(INDEX('Реестр'!$I$4:$I$103,$K9)="","",INDEX('Реестр'!$I$4:$I$103,$K9)),IF(ROW()=$K$3+5,'Реестр'!I104,IF(ROW()=$K$3+8,"Дата:",""))) | J9: =IF(ISNUMBER($K9),IF(INDEX('Реестр'!$J$4:$J$103,$K9)="","",INDEX('Реестр'!$J$4:$J$103,$K9)),IF(ROW()=$K$3+8,"____________","")) | K9: =IFERROR(_xlfn.AGGREGATE(15,6,(ROW('Реестр'!$B$4:$B$103)-3)/((('Реестр'!$B$4:$B$103<>"")+('Реестр'!$C$4:$C$103<>"")+('Реестр'!$D$4:$D$103<>"")+('Реестр'!$E$4:$E$103<>"")+('Реестр'!$G$4:$G$103<>"")+('Реестр'!$H$4:$H$103<>"")+('Реестр'!$J$4:$J$103<>""))>0),ROWS($K$5:K9)),"")
A10: =IF(ISNUMBER($K10),$K10,"") | B10: =IF(ISNUMBER($K10),IF(INDEX('Реестр'!$B$4:$B$103,$K10)="","",INDEX('Реестр'!$B$4:$B$103,$K10)),IF(ROW()=$K$3+5,"ИТОГО",IF(ROW()=$K$3+6,"ПОДРЯДЧИК",IF(ROW()=$K$3+7,"Должн./ФИО:",IF(ROW()=$K$3+8,"Подпись:",""))))) | C10: =IF(ISNUMBER($K10),IF(INDEX('Реестр'!$C$4:$C$103,$K10)="","",INDEX('Реестр'!$C$4:$C$103,$K10)),IF(ROW()=$K$3+7,"________________",IF(ROW()=$K$3+8,"________________",""))) | D10: =IF(ISNUMBER($K10),IF(INDEX('Реестр'!$D$4:$D$103,$K10)="","",INDEX('Реестр'!$D$4:$D$103,$K10)),IF(ROW()=$K$3+8,"Дата:","")) | E10: =IF(ISNUMBER($K10),IF(INDEX('Реестр'!$E$4:$E$103,$K10)="","",INDEX('Реестр'!$E$4:$E$103,$K10)),IF(ROW()=$K$3+8,"____________","")) | F10: =IF(ISNUMBER($K10),IF(INDEX('Реестр'!$F$4:$F$103,$K10)="","",INDEX('Реестр'!$F$4:$F$103,$K10)),IF(ROW()=$K$3+5,'Реестр'!F104,"")) | G10: =IF(ISNUMBER($K10),IF(INDEX('Реестр'!$G$4:$G$103,$K10)="","",INDEX('Реестр'!$G$4:$G$103,$K10)),IF(ROW()=$K$3+6,"ЗАКАЗЧИК",IF(ROW()=$K$3+7,"Должн./ФИО:",IF(ROW()=$K$3+8,"Подпись:","")))) | H10: =IF(ISNUMBER($K10),IF(INDEX('Реестр'!$H$4:$H$103,$K10)="","",INDEX('Реестр'!$H$4:$H$103,$K10)),IF(ROW()=$K$3+7,"________________",IF(ROW()=$K$3+8,"________________",""))) | I10: =IF(ISNUMBER($K10),IF(INDEX('Реестр'!$I$4:$I$103,$K10)="","",INDEX('Реестр'!$I$4:$I$103,$K10)),IF(ROW()=$K$3+5,'Реестр'!I104,IF(ROW()=$K$3+8,"Дата:",""))) | J10: =IF(ISNUMBER($K10),IF(INDEX('Реестр'!$J$4:$J$103,$K10)="","",INDEX('Реестр'!$J$4:$J$103,$K10)),IF(ROW()=$K$3+8,"____________","")) | K10: =IFERROR(_xlfn.AGGREGATE(15,6,(ROW('Реестр'!$B$4:$B$103)-3)/((('Реестр'!$B$4:$B$103<>"")+('Реестр'!$C$4:$C$103<>"")+('Реестр'!$D$4:$D$103<>"")+('Реестр'!$E$4:$E$103<>"")+('Реестр'!$G$4:$G$103<>"")+('Реестр'!$H$4:$H$103<>"")+('Реестр'!$J$4:$J$103<>""))>0),ROWS($K$5:K10)),"")
A11: =IF(ISNUMBER($K11),$K11,"") | B11: =IF(ISNUMBER($K11),IF(INDEX('Реестр'!$B$4:$B$103,$K11)="","",INDEX('Реестр'!$B$4:$B$103,$K11)),IF(ROW()=$K$3+5,"ИТОГО",IF(ROW()=$K$3+6,"ПОДРЯДЧИК",IF(ROW()=$K$3+7,"Должн./ФИО:",IF(ROW()=$K$3+8,"Подпись:",""))))) | C11: =IF(ISNUMBER($K11),IF(INDEX('Реестр'!$C$4:$C$103,$K11)="","",INDEX('Реестр'!$C$4:$C$103,$K11)),IF(ROW()=$K$3+7,"________________",IF(ROW()=$K$3+8,"________________",""))) | D11: =IF(ISNUMBER($K11),IF(INDEX('Реестр'!$D$4:$D$103,$K11)="","",INDEX('Реестр'!$D$4:$D$103,$K11)),IF(ROW()=$K$3+8,"Дата:","")) | E11: =IF(ISNUMBER($K11),IF(INDEX('Реестр'!$E$4:$E$103,$K11)="","",INDEX('Реестр'!$E$4:$E$103,$K11)),IF(ROW()=$K$3+8,"____________","")) | F11: =IF(ISNUMBER($K11),IF(INDEX('Реестр'!$F$4:$F$103,$K11)="","",INDEX('Реестр'!$F$4:$F$103,$K11)),IF(ROW()=$K$3+5,'Реестр'!F104,"")) | G11: =IF(ISNUMBER($K11),IF(INDEX('Реестр'!$G$4:$G$103,$K11)="","",INDEX('Реестр'!$G$4:$G$103,$K11)),IF(ROW()=$K$3+6,"ЗАКАЗЧИК",IF(ROW()=$K$3+7,"Должн./ФИО:",IF(ROW()=$K$3+8,"Подпись:","")))) | H11: =IF(ISNUMBER($K11),IF(INDEX('Реестр'!$H$4:$H$103,$K11)="","",INDEX('Реестр'!$H$4:$H$103,$K11)),IF(ROW()=$K$3+7,"________________",IF(ROW()=$K$3+8,"________________",""))) | I11: =IF(ISNUMBER($K11),IF(INDEX('Реестр'!$I$4:$I$103,$K11)="","",INDEX('Реестр'!$I$4:$I$103,$K11)),IF(ROW()=$K$3+5,'Реестр'!I104,IF(ROW()=$K$3+8,"Дата:",""))) | J11: =IF(ISNUMBER($K11),IF(INDEX('Реестр'!$J$4:$J$103,$K11)="","",INDEX('Реестр'!$J$4:$J$103,$K11)),IF(ROW()=$K$3+8,"____________","")) | K11: =IFERROR(_xlfn.AGGREGATE(15,6,(ROW('Реестр'!$B$4:$B$103)-3)/((('Реестр'!$B$4:$B$103<>"")+('Реестр'!$C$4:$C$103<>"")+('Реестр'!$D$4:$D$103<>"")+('Реестр'!$E$4:$E$103<>"")+('Реестр'!$G$4:$G$103<>"")+('Реестр'!$H$4:$H$103<>"")+('Реестр'!$J$4:$J$103<>""))>0),ROWS($K$5:K11)),"")
A12: =IF(ISNUMBER($K12),$K12,"") | B12: =IF(ISNUMBER($K12),IF(INDEX('Реестр'!$B$4:$B$103,$K12)="","",INDEX('Реестр'!$B$4:$B$103,$K12)),IF(ROW()=$K$3+5,"ИТОГО",IF(ROW()=$K$3+6,"ПОДРЯДЧИК",IF(ROW()=$K$3+7,"Должн./ФИО:",IF(ROW()=$K$3+8,"Подпись:",""))))) | C12: =IF(ISNUMBER($K12),IF(INDEX('Реестр'!$C$4:$C$103,$K12)="","",INDEX('Реестр'!$C$4:$C$103,$K12)),IF(ROW()=$K$3+7,"________________",IF(ROW()=$K$3+8,"________________",""))) | D12: =IF(ISNUMBER($K12),IF(INDEX('Реестр'!$D$4:$D$103,$K12)="","",INDEX('Реестр'!$D$4:$D$103,$K12)),IF(ROW()=$K$3+8,"Дата:","")) | E12: =IF(ISNUMBER($K12),IF(INDEX('Реестр'!$E$4:$E$103,$K12)="","",INDEX('Реестр'!$E$4:$E$103,$K12)),IF(ROW()=$K$3+8,"____________","")) | F12: =IF(ISNUMBER($K12),IF(INDEX('Реестр'!$F$4:$F$103,$K12)="","",INDEX('Реестр'!$F$4:$F$103,$K12)),IF(ROW()=$K$3+5,'Реестр'!F104,"")) | G12: =IF(ISNUMBER($K12),IF(INDEX('Реестр'!$G$4:$G$103,$K12)="","",INDEX('Реестр'!$G$4:$G$103,$K12)),IF(ROW()=$K$3+6,"ЗАКАЗЧИК",IF(ROW()=$K$3+7,"Должн./ФИО:",IF(ROW()=$K$3+8,"Подпись:","")))) | H12: =IF(ISNUMBER($K12),IF(INDEX('Реестр'!$H$4:$H$103,$K12)="","",INDEX('Реестр'!$H$4:$H$103,$K12)),IF(ROW()=$K$3+7,"________________",IF(ROW()=$K$3+8,"________________",""))) | I12: =IF(ISNUMBER($K12),IF(INDEX('Реестр'!$I$4:$I$103,$K12)="","",INDEX('Реестр'!$I$4:$I$103,$K12)),IF(ROW()=$K$3+5,'Реестр'!I104,IF(ROW()=$K$3+8,"Дата:",""))) | J12: =IF(ISNUMBER($K12),IF(INDEX('Реестр'!$J$4:$J$103,$K12)="","",INDEX('Реестр'!$J$4:$J$103,$K12)),IF(ROW()=$K$3+8,"____________","")) | K12: =IFERROR(_xlfn.AGGREGATE(15,6,(ROW('Реестр'!$B$4:$B$103)-3)/((('Реестр'!$B$4:$B$103<>"")+('Реестр'!$C$4:$C$103<>"")+('Реестр'!$D$4:$D$103<>"")+('Реестр'!$E$4:$E$103<>"")+('Реестр'!$G$4:$G$103<>"")+('Реестр'!$H$4:$H$103<>"")+('Реестр'!$J$4:$J$103<>""))>0),ROWS($K$5:K12)),"")
A13: =IF(ISNUMBER($K13),$K13,"") | B13: =IF(ISNUMBER($K13),IF(INDEX('Реестр'!$B$4:$B$103,$K13)="","",INDEX('Реестр'!$B$4:$B$103,$K13)),IF(ROW()=$K$3+5,"ИТОГО",IF(ROW()=$K$3+6,"ПОДРЯДЧИК",IF(ROW()=$K$3+7,"Должн./ФИО:",IF(ROW()=$K$3+8,"Подпись:",""))))) | C13: =IF(ISNUMBER($K13),IF(INDEX('Реестр'!$C$4:$C$103,$K13)="","",INDEX('Реестр'!$C$4:$C$103,$K13)),IF(ROW()=$K$3+7,"________________",IF(ROW()=$K$3+8,"________________",""))) | D13: =IF(ISNUMBER($K13),IF(INDEX('Реестр'!$D$4:$D$103,$K13)="","",INDEX('Реестр'!$D$4:$D$103,$K13)),IF(ROW()=$K$3+8,"Дата:","")) | E13: =IF(ISNUMBER($K13),IF(INDEX('Реестр'!$E$4:$E$103,$K13)="","",INDEX('Реестр'!$E$4:$E$103,$K13)),IF(ROW()=$K$3+8,"____________","")) | F13: =IF(ISNUMBER($K13),IF(INDEX('Реестр'!$F$4:$F$103,$K13)="","",INDEX('Реестр'!$F$4:$F$103,$K13)),IF(ROW()=$K$3+5,'Реестр'!F104,"")) | G13: =IF(ISNUMBER($K13),IF(INDEX('Реестр'!$G$4:$G$103,$K13)="","",INDEX('Реестр'!$G$4:$G$103,$K13)),IF(ROW()=$K$3+6,"ЗАКАЗЧИК",IF(ROW()=$K$3+7,"Должн./ФИО:",IF(ROW()=$K$3+8,"Подпись:","")))) | H13: =IF(ISNUMBER($K13),IF(INDEX('Реестр'!$H$4:$H$103,$K13)="","",INDEX('Реестр'!$H$4:$H$103,$K13)),IF(ROW()=$K$3+7,"________________",IF(ROW()=$K$3+8,"________________",""))) | I13: =IF(ISNUMBER($K13),IF(INDEX('Реестр'!$I$4:$I$103,$K13)="","",INDEX('Реестр'!$I$4:$I$103,$K13)),IF(ROW()=$K$3+5,'Реестр'!I104,IF(ROW()=$K$3+8,"Дата:",""))) | J13: =IF(ISNUMBER($K13),IF(INDEX('Реестр'!$J$4:$J$103,$K13)="","",INDEX('Реестр'!$J$4:$J$103,$K13)),IF(ROW()=$K$3+8,"____________","")) | K13: =IFERROR(_xlfn.AGGREGATE(15,6,(ROW('Реестр'!$B$4:$B$103)-3)/((('Реестр'!$B$4:$B$103<>"")+('Реестр'!$C$4:$C$103<>"")+('Реестр'!$D$4:$D$103<>"")+('Реестр'!$E$4:$E$103<>"")+('Реестр'!$G$4:$G$103<>"")+('Реестр'!$H$4:$H$103<>"")+('Реестр'!$J$4:$J$103<>""))>0),ROWS($K$5:K13)),"")
A14: =IF(ISNUMBER($K14),$K14,"") | B14: =IF(ISNUMBER($K14),IF(INDEX('Реестр'!$B$4:$B$103,$K14)="","",INDEX('Реестр'!$B$4:$B$103,$K14)),IF(ROW()=$K$3+5,"ИТОГО",IF(ROW()=$K$3+6,"ПОДРЯДЧИК",IF(ROW()=$K$3+7,"Должн./ФИО:",IF(ROW()=$K$3+8,"Подпись:",""))))) | C14: =IF(ISNUMBER($K14),IF(INDEX('Реестр'!$C$4:$C$103,$K14)="","",INDEX('Реестр'!$C$4:$C$103,$K14)),IF(ROW()=$K$3+7,"________________",IF(ROW()=$K$3+8,"________________",""))) | D14: =IF(ISNUMBER($K14),IF(INDEX('Реестр'!$D$4:$D$103,$K14)="","",INDEX('Реестр'!$D$4:$D$103,$K14)),IF(ROW()=$K$3+8,"Дата:","")) | E14: =IF(ISNUMBER($K14),IF(INDEX('Реестр'!$E$4:$E$103,$K14)="","",INDEX('Реестр'!$E$4:$E$103,$K14)),IF(ROW()=$K$3+8,"____________","")) | F14: =IF(ISNUMBER($K14),IF(INDEX('Реестр'!$F$4:$F$103,$K14)="","",INDEX('Реестр'!$F$4:$F$103,$K14)),IF(ROW()=$K$3+5,'Реестр'!F104,"")) | G14: =IF(ISNUMBER($K14),IF(INDEX('Реестр'!$G$4:$G$103,$K14)="","",INDEX('Реестр'!$G$4:$G$103,$K14)),IF(ROW()=$K$3+6,"ЗАКАЗЧИК",IF(ROW()=$K$3+7,"Должн./ФИО:",IF(ROW()=$K$3+8,"Подпись:","")))) | H14: =IF(ISNUMBER($K14),IF(INDEX('Реестр'!$H$4:$H$103,$K14)="","",INDEX('Реестр'!$H$4:$H$103,$K14)),IF(ROW()=$K$3+7,"________________",IF(ROW()=$K$3+8,"________________",""))) | I14: =IF(ISNUMBER($K14),IF(INDEX('Реестр'!$I$4:$I$103,$K14)="","",INDEX('Реестр'!$I$4:$I$103,$K14)),IF(ROW()=$K$3+5,'Реестр'!I104,IF(ROW()=$K$3+8,"Дата:",""))) | J14: =IF(ISNUMBER($K14),IF(INDEX('Реестр'!$J$4:$J$103,$K14)="","",INDEX('Реестр'!$J$4:$J$103,$K14)),IF(ROW()=$K$3+8,"____________","")) | K14: =IFERROR(_xlfn.AGGREGATE(15,6,(ROW('Реестр'!$B$4:$B$103)-3)/((('Реестр'!$B$4:$B$103<>"")+('Реестр'!$C$4:$C$103<>"")+('Реестр'!$D$4:$D$103<>"")+('Реестр'!$E$4:$E$103<>"")+('Реестр'!$G$4:$G$103<>"")+('Реестр'!$H$4:$H$103<>"")+('Реестр'!$J$4:$J$103<>""))>0),ROWS($K$5:K14)),"")
A15: =IF(ISNUMBER($K15),$K15,"") | B15: =IF(ISNUMBER($K15),IF(INDEX('Реестр'!$B$4:$B$103,$K15)="","",INDEX('Реестр'!$B$4:$B$103,$K15)),IF(ROW()=$K$3+5,"ИТОГО",IF(ROW()=$K$3+6,"ПОДРЯДЧИК",IF(ROW()=$K$3+7,"Должн./ФИО:",IF(ROW()=$K$3+8,"Подпись:",""))))) | C15: =IF(ISNUMBER($K15),IF(INDEX('Реестр'!$C$4:$C$103,$K15)="","",INDEX('Реестр'!$C$4:$C$103,$K15)),IF(ROW()=$K$3+7,"________________",IF(ROW()=$K$3+8,"________________",""))) | D15: =IF(ISNUMBER($K15),IF(INDEX('Реестр'!$D$4:$D$103,$K15)="","",INDEX('Реестр'!$D$4:$D$103,$K15)),IF(ROW()=$K$3+8,"Дата:","")) | E15: =IF(ISNUMBER($K15),IF(INDEX('Реестр'!$E$4:$E$103,$K15)="","",INDEX('Реестр'!$E$4:$E$103,$K15)),IF(ROW()=$K$3+8,"____________","")) | F15: =IF(ISNUMBER($K15),IF(INDEX('Реестр'!$F$4:$F$103,$K15)="","",INDEX('Реестр'!$F$4:$F$103,$K15)),IF(ROW()=$K$3+5,'Реестр'!F104,"")) | G15: =IF(ISNUMBER($K15),IF(INDEX('Реестр'!$G$4:$G$103,$K15)="","",INDEX('Реестр'!$G$4:$G$103,$K15)),IF(ROW()=$K$3+6,"ЗАКАЗЧИК",IF(ROW()=$K$3+7,"Должн./ФИО:",IF(ROW()=$K$3+8,"Подпись:","")))) | H15: =IF(ISNUMBER($K15),IF(INDEX('Реестр'!$H$4:$H$103,$K15)="","",INDEX('Реестр'!$H$4:$H$103,$K15)),IF(ROW()=$K$3+7,"________________",IF(ROW()=$K$3+8,"________________",""))) | I15: =IF(ISNUMBER($K15),IF(INDEX('Реестр'!$I$4:$I$103,$K15)="","",INDEX('Реестр'!$I$4:$I$103,$K15)),IF(ROW()=$K$3+5,'Реестр'!I104,IF(ROW()=$K$3+8,"Дата:",""))) | J15: =IF(ISNUMBER($K15),IF(INDEX('Реестр'!$J$4:$J$103,$K15)="","",INDEX('Реестр'!$J$4:$J$103,$K15)),IF(ROW()=$K$3+8,"____________","")) | K15: =IFERROR(_xlfn.AGGREGATE(15,6,(ROW('Реестр'!$B$4:$B$103)-3)/((('Реестр'!$B$4:$B$103<>"")+('Реестр'!$C$4:$C$103<>"")+('Реестр'!$D$4:$D$103<>"")+('Реестр'!$E$4:$E$103<>"")+('Реестр'!$G$4:$G$103<>"")+('Реестр'!$H$4:$H$103<>"")+('Реестр'!$J$4:$J$103<>""))>0),ROWS($K$5:K15)),"")
A16: =IF(ISNUMBER($K16),$K16,"") | B16: =IF(ISNUMBER($K16),IF(INDEX('Реестр'!$B$4:$B$103,$K16)="","",INDEX('Реестр'!$B$4:$B$103,$K16)),IF(ROW()=$K$3+5,"ИТОГО",IF(ROW()=$K$3+6,"ПОДРЯДЧИК",IF(ROW()=$K$3+7,"Должн./ФИО:",IF(ROW()=$K$3+8,"Подпись:",""))))) | C16: =IF(ISNUMBER($K16),IF(INDEX('Реестр'!$C$4:$C$103,$K16)="","",INDEX('Реестр'!$C$4:$C$103,$K16)),IF(ROW()=$K$3+7,"________________",IF(ROW()=$K$3+8,"________________",""))) | D16: =IF(ISNUMBER($K16),IF(INDEX('Реестр'!$D$4:$D$103,$K16)="","",INDEX('Реестр'!$D$4:$D$103,$K16)),IF(ROW()=$K$3+8,"Дата:","")) | E16: =IF(ISNUMBER($K16),IF(INDEX('Реестр'!$E$4:$E$103,$K16)="","",INDEX('Реестр'!$E$4:$E$103,$K16)),IF(ROW()=$K$3+8,"____________","")) | F16: =IF(ISNUMBER($K16),IF(INDEX('Реестр'!$F$4:$F$103,$K16)="","",INDEX('Реестр'!$F$4:$F$103,$K16)),IF(ROW()=$K$3+5,'Реестр'!F104,"")) | G16: =IF(ISNUMBER($K16),IF(INDEX('Реестр'!$G$4:$G$103,$K16)="","",INDEX('Реестр'!$G$4:$G$103,$K16)),IF(ROW()=$K$3+6,"ЗАКАЗЧИК",IF(ROW()=$K$3+7,"Должн./ФИО:",IF(ROW()=$K$3+8,"Подпись:","")))) | H16: =IF(ISNUMBER($K16),IF(INDEX('Реестр'!$H$4:$H$103,$K16)="","",INDEX('Реестр'!$H$4:$H$103,$K16)),IF(ROW()=$K$3+7,"________________",IF(ROW()=$K$3+8,"________________",""))) | I16: =IF(ISNUMBER($K16),IF(INDEX('Реестр'!$I$4:$I$103,$K16)="","",INDEX('Реестр'!$I$4:$I$103,$K16)),IF(ROW()=$K$3+5,'Реестр'!I104,IF(ROW()=$K$3+8,"Дата:",""))) | J16: =IF(ISNUMBER($K16),IF(INDEX('Реестр'!$J$4:$J$103,$K16)="","",INDEX('Реестр'!$J$4:$J$103,$K16)),IF(ROW()=$K$3+8,"____________","")) | K16: =IFERROR(_xlfn.AGGREGATE(15,6,(ROW('Реестр'!$B$4:$B$103)-3)/((('Реестр'!$B$4:$B$103<>"")+('Реестр'!$C$4:$C$103<>"")+('Реестр'!$D$4:$D$103<>"")+('Реестр'!$E$4:$E$103<>"")+('Реестр'!$G$4:$G$103<>"")+('Реестр'!$H$4:$H$103<>"")+('Реестр'!$J$4:$J$103<>""))>0),ROWS($K$5:K16)),"")
A17: =IF(ISNUMBER($K17),$K17,"") | B17: =IF(ISNUMBER($K17),IF(INDEX('Реестр'!$B$4:$B$103,$K17)="","",INDEX('Реестр'!$B$4:$B$103,$K17)),IF(ROW()=$K$3+5,"ИТОГО",IF(ROW()=$K$3+6,"ПОДРЯДЧИК",IF(ROW()=$K$3+7,"Должн./ФИО:",IF(ROW()=$K$3+8,"Подпись:",""))))) | C17: =IF(ISNUMBER($K17),IF(INDEX('Реестр'!$C$4:$C$103,$K17)="","",INDEX('Реестр'!$C$4:$C$103,$K17)),IF(ROW()=$K$3+7,"________________",IF(ROW()=$K$3+8,"________________",""))) | D17: =IF(ISNUMBER($K17),IF(INDEX('Реестр'!$D$4:$D$103,$K17)="","",INDEX('Реестр'!$D$4:$D$103,$K17)),IF(ROW()=$K$3+8,"Дата:","")) | E17: =IF(ISNUMBER($K17),IF(INDEX('Реестр'!$E$4:$E$103,$K17)="","",INDEX('Реестр'!$E$4:$E$103,$K17)),IF(ROW()=$K$3+8,"____________","")) | F17: =IF(ISNUMBER($K17),IF(INDEX('Реестр'!$F$4:$F$103,$K17)="","",INDEX('Реестр'!$F$4:$F$103,$K17)),IF(ROW()=$K$3+5,'Реестр'!F104,"")) | G17: =IF(ISNUMBER($K17),IF(INDEX('Реестр'!$G$4:$G$103,$K17)="","",INDEX('Реестр'!$G$4:$G$103,$K17)),IF(ROW()=$K$3+6,"ЗАКАЗЧИК",IF(ROW()=$K$3+7,"Должн./ФИО:",IF(ROW()=$K$3+8,"Подпись:","")))) | H17: =IF(ISNUMBER($K17),IF(INDEX('Реестр'!$H$4:$H$103,$K17)="","",INDEX('Реестр'!$H$4:$H$103,$K17)),IF(ROW()=$K$3+7,"________________",IF(ROW()=$K$3+8,"________________",""))) | I17: =IF(ISNUMBER($K17),IF(INDEX('Реестр'!$I$4:$I$103,$K17)="","",INDEX('Реестр'!$I$4:$I$103,$K17)),IF(ROW()=$K$3+5,'Реестр'!I104,IF(ROW()=$K$3+8,"Дата:",""))) | J17: =IF(ISNUMBER($K17),IF(INDEX('Реестр'!$J$4:$J$103,$K17)="","",INDEX('Реестр'!$J$4:$J$103,$K17)),IF(ROW()=$K$3+8,"____________","")) | K17: =IFERROR(_xlfn.AGGREGATE(15,6,(ROW('Реестр'!$B$4:$B$103)-3)/((('Реестр'!$B$4:$B$103<>"")+('Реестр'!$C$4:$C$103<>"")+('Реестр'!$D$4:$D$103<>"")+('Реестр'!$E$4:$E$103<>"")+('Реестр'!$G$4:$G$103<>"")+('Реестр'!$H$4:$H$103<>"")+('Реестр'!$J$4:$J$103<>""))>0),ROWS($K$5:K17)),"")
A18: =IF(ISNUMBER($K18),$K18,"") | B18: =IF(ISNUMBER($K18),IF(INDEX('Реестр'!$B$4:$B$103,$K18)="","",INDEX('Реестр'!$B$4:$B$103,$K18)),IF(ROW()=$K$3+5,"ИТОГО",IF(ROW()=$K$3+6,"ПОДРЯДЧИК",IF(ROW()=$K$3+7,"Должн./ФИО:",IF(ROW()=$K$3+8,"Подпись:",""))))) | C18: =IF(ISNUMBER($K18),IF(INDEX('Реестр'!$C$4:$C$103,$K18)="","",INDEX('Реестр'!$C$4:$C$103,$K18)),IF(ROW()=$K$3+7,"________________",IF(ROW()=$K$3+8,"________________",""))) | D18: =IF(ISNUMBER($K18),IF(INDEX('Реестр'!$D$4:$D$103,$K18)="","",INDEX('Реестр'!$D$4:$D$103,$K18)),IF(ROW()=$K$3+8,"Дата:","")) | E18: =IF(ISNUMBER($K18),IF(INDEX('Реестр'!$E$4:$E$103,$K18)="","",INDEX('Реестр'!$E$4:$E$103,$K18)),IF(ROW()=$K$3+8,"____________","")) | F18: =IF(ISNUMBER($K18),IF(INDEX('Реестр'!$F$4:$F$103,$K18)="","",INDEX('Реестр'!$F$4:$F$103,$K18)),IF(ROW()=$K$3+5,'Реестр'!F104,"")) | G18: =IF(ISNUMBER($K18),IF(INDEX('Реестр'!$G$4:$G$103,$K18)="","",INDEX('Реестр'!$G$4:$G$103,$K18)),IF(ROW()=$K$3+6,"ЗАКАЗЧИК",IF(ROW()=$K$3+7,"Должн./ФИО:",IF(ROW()=$K$3+8,"Подпись:","")))) | H18: =IF(ISNUMBER($K18),IF(INDEX('Реестр'!$H$4:$H$103,$K18)="","",INDEX('Реестр'!$H$4:$H$103,$K18)),IF(ROW()=$K$3+7,"________________",IF(ROW()=$K$3+8,"________________",""))) | I18: =IF(ISNUMBER($K18),IF(INDEX('Реестр'!$I$4:$I$103,$K18)="","",INDEX('Реестр'!$I$4:$I$103,$K18)),IF(ROW()=$K$3+5,'Реестр'!I104,IF(ROW()=$K$3+8,"Дата:",""))) | J18: =IF(ISNUMBER($K18),IF(INDEX('Реестр'!$J$4:$J$103,$K18)="","",INDEX('Реестр'!$J$4:$J$103,$K18)),IF(ROW()=$K$3+8,"____________","")) | K18: =IFERROR(_xlfn.AGGREGATE(15,6,(ROW('Реестр'!$B$4:$B$103)-3)/((('Реестр'!$B$4:$B$103<>"")+('Реестр'!$C$4:$C$103<>"")+('Реестр'!$D$4:$D$103<>"")+('Реестр'!$E$4:$E$103<>"")+('Реестр'!$G$4:$G$103<>"")+('Реестр'!$H$4:$H$103<>"")+('Реестр'!$J$4:$J$103<>""))>0),ROWS($K$5:K18)),"")
A19: =IF(ISNUMBER($K19),$K19,"") | B19: =IF(ISNUMBER($K19),IF(INDEX('Реестр'!$B$4:$B$103,$K19)="","",INDEX('Реестр'!$B$4:$B$103,$K19)),IF(ROW()=$K$3+5,"ИТОГО",IF(ROW()=$K$3+6,"ПОДРЯДЧИК",IF(ROW()=$K$3+7,"Должн./ФИО:",IF(ROW()=$K$3+8,"Подпись:",""))))) | C19: =IF(ISNUMBER($K19),IF(INDEX('Реестр'!$C$4:$C$103,$K19)="","",INDEX('Реестр'!$C$4:$C$103,$K19)),IF(ROW()=$K$3+7,"________________",IF(ROW()=$K$3+8,"________________",""))) | D19: =IF(ISNUMBER($K19),IF(INDEX('Реестр'!$D$4:$D$103,$K19)="","",INDEX('Реестр'!$D$4:$D$103,$K19)),IF(ROW()=$K$3+8,"Дата:","")) | E19: =IF(ISNUMBER($K19),IF(INDEX('Реестр'!$E$4:$E$103,$K19)="","",INDEX('Реестр'!$E$4:$E$103,$K19)),IF(ROW()=$K$3+8,"____________","")) | F19: =IF(ISNUMBER($K19),IF(INDEX('Реестр'!$F$4:$F$103,$K19)="","",INDEX('Реестр'!$F$4:$F$103,$K19)),IF(ROW()=$K$3+5,'Реестр'!F104,"")) | G19: =IF(ISNUMBER($K19),IF(INDEX('Реестр'!$G$4:$G$103,$K19)="","",INDEX('Реестр'!$G$4:$G$103,$K19)),IF(ROW()=$K$3+6,"ЗАКАЗЧИК",IF(ROW()=$K$3+7,"Должн./ФИО:",IF(ROW()=$K$3+8,"Подпись:","")))) | H19: =IF(ISNUMBER($K19),IF(INDEX('Реестр'!$H$4:$H$103,$K19)="","",INDEX('Реестр'!$H$4:$H$103,$K19)),IF(ROW()=$K$3+7,"________________",IF(ROW()=$K$3+8,"________________",""))) | I19: =IF(ISNUMBER($K19),IF(INDEX('Реестр'!$I$4:$I$103,$K19)="","",INDEX('Реестр'!$I$4:$I$103,$K19)),IF(ROW()=$K$3+5,'Реестр'!I104,IF(ROW()=$K$3+8,"Дата:",""))) | J19: =IF(ISNUMBER($K19),IF(INDEX('Реестр'!$J$4:$J$103,$K19)="","",INDEX('Реестр'!$J$4:$J$103,$K19)),IF(ROW()=$K$3+8,"____________","")) | K19: =IFERROR(_xlfn.AGGREGATE(15,6,(ROW('Реестр'!$B$4:$B$103)-3)/((('Реестр'!$B$4:$B$103<>"")+('Реестр'!$C$4:$C$103<>"")+('Реестр'!$D$4:$D$103<>"")+('Реестр'!$E$4:$E$103<>"")+('Реестр'!$G$4:$G$103<>"")+('Реестр'!$H$4:$H$103<>"")+('Реестр'!$J$4:$J$103<>""))>0),ROWS($K$5:K19)),"")
A20: =IF(ISNUMBER($K20),$K20,"") | B20: =IF(ISNUMBER($K20),IF(INDEX('Реестр'!$B$4:$B$103,$K20)="","",INDEX('Реестр'!$B$4:$B$103,$K20)),IF(ROW()=$K$3+5,"ИТОГО",IF(ROW()=$K$3+6,"ПОДРЯДЧИК",IF(ROW()=$K$3+7,"Должн./ФИО:",IF(ROW()=$K$3+8,"Подпись:",""))))) | C20: =IF(ISNUMBER($K20),IF(INDEX('Реестр'!$C$4:$C$103,$K20)="","",INDEX('Реестр'!$C$4:$C$103,$K20)),IF(ROW()=$K$3+7,"________________",IF(ROW()=$K$3+8,"________________",""))) | D20: =IF(ISNUMBER($K20),IF(INDEX('Реестр'!$D$4:$D$103,$K20)="","",INDEX('Реестр'!$D$4:$D$103,$K20)),IF(ROW()=$K$3+8,"Дата:","")) | E20: =IF(ISNUMBER($K20),IF(INDEX('Реестр'!$E$4:$E$103,$K20)="","",INDEX('Реестр'!$E$4:$E$103,$K20)),IF(ROW()=$K$3+8,"____________","")) | F20: =IF(ISNUMBER($K20),IF(INDEX('Реестр'!$F$4:$F$103,$K20)="","",INDEX('Реестр'!$F$4:$F$103,$K20)),IF(ROW()=$K$3+5,'Реестр'!F104,"")) | G20: =IF(ISNUMBER($K20),IF(INDEX('Реестр'!$G$4:$G$103,$K20)="","",INDEX('Реестр'!$G$4:$G$103,$K20)),IF(ROW()=$K$3+6,"ЗАКАЗЧИК",IF(ROW()=$K$3+7,"Должн./ФИО:",IF(ROW()=$K$3+8,"Подпись:","")))) | H20: =IF(ISNUMBER($K20),IF(INDEX('Реестр'!$H$4:$H$103,$K20)="","",INDEX('Реестр'!$H$4:$H$103,$K20)),IF(ROW()=$K$3+7,"________________",IF(ROW()=$K$3+8,"________________",""))) | I20: =IF(ISNUMBER($K20),IF(INDEX('Реестр'!$I$4:$I$103,$K20)="","",INDEX('Реестр'!$I$4:$I$103,$K20)),IF(ROW()=$K$3+5,'Реестр'!I104,IF(ROW()=$K$3+8,"Дата:",""))) | J20: =IF(ISNUMBER($K20),IF(INDEX('Реестр'!$J$4:$J$103,$K20)="","",INDEX('Реестр'!$J$4:$J$103,$K20)),IF(ROW()=$K$3+8,"____________","")) | K20: =IFERROR(_xlfn.AGGREGATE(15,6,(ROW('Реестр'!$B$4:$B$103)-3)/((('Реестр'!$B$4:$B$103<>"")+('Реестр'!$C$4:$C$103<>"")+('Реестр'!$D$4:$D$103<>"")+('Реестр'!$E$4:$E$103<>"")+('Реестр'!$G$4:$G$103<>"")+('Реестр'!$H$4:$H$103<>"")+('Реестр'!$J$4:$J$103<>""))>0),ROWS($K$5:K20)),"")
A21: =IF(ISNUMBER($K21),$K21,"") | B21: =IF(ISNUMBER($K21),IF(INDEX('Реестр'!$B$4:$B$103,$K21)="","",INDEX('Реестр'!$B$4:$B$103,$K21)),IF(ROW()=$K$3+5,"ИТОГО",IF(ROW()=$K$3+6,"ПОДРЯДЧИК",IF(ROW()=$K$3+7,"Должн./ФИО:",IF(ROW()=$K$3+8,"Подпись:",""))))) | C21: =IF(ISNUMBER($K21),IF(INDEX('Реестр'!$C$4:$C$103,$K21)="","",INDEX('Реестр'!$C$4:$C$103,$K21)),IF(ROW()=$K$3+7,"________________",IF(ROW()=$K$3+8,"________________",""))) | D21: =IF(ISNUMBER($K21),IF(INDEX('Реестр'!$D$4:$D$103,$K21)="","",INDEX('Реестр'!$D$4:$D$103,$K21)),IF(ROW()=$K$3+8,"Дата:","")) | E21: =IF(ISNUMBER($K21),IF(INDEX('Реестр'!$E$4:$E$103,$K21)="","",INDEX('Реестр'!$E$4:$E$103,$K21)),IF(ROW()=$K$3+8,"____________","")) | F21: =IF(ISNUMBER($K21),IF(INDEX('Реестр'!$F$4:$F$103,$K21)="","",INDEX('Реестр'!$F$4:$F$103,$K21)),IF(ROW()=$K$3+5,'Реестр'!F104,"")) | G21: =IF(ISNUMBER($K21),IF(INDEX('Реестр'!$G$4:$G$103,$K21)="","",INDEX('Реестр'!$G$4:$G$103,$K21)),IF(ROW()=$K$3+6,"ЗАКАЗЧИК",IF(ROW()=$K$3+7,"Должн./ФИО:",IF(ROW()=$K$3+8,"Подпись:","")))) | H21: =IF(ISNUMBER($K21),IF(INDEX('Реестр'!$H$4:$H$103,$K21)="","",INDEX('Реестр'!$H$4:$H$103,$K21)),IF(ROW()=$K$3+7,"________________",IF(ROW()=$K$3+8,"________________",""))) | I21: =IF(ISNUMBER($K21),IF(INDEX('Реестр'!$I$4:$I$103,$K21)="","",INDEX('Реестр'!$I$4:$I$103,$K21)),IF(ROW()=$K$3+5,'Реестр'!I104,IF(ROW()=$K$3+8,"Дата:",""))) | J21: =IF(ISNUMBER($K21),IF(INDEX('Реестр'!$J$4:$J$103,$K21)="","",INDEX('Реестр'!$J$4:$J$103,$K21)),IF(ROW()=$K$3+8,"____________","")) | K21: =IFERROR(_xlfn.AGGREGATE(15,6,(ROW('Реестр'!$B$4:$B$103)-3)/((('Реестр'!$B$4:$B$103<>"")+('Реестр'!$C$4:$C$103<>"")+('Реестр'!$D$4:$D$103<>"")+('Реестр'!$E$4:$E$103<>"")+('Реестр'!$G$4:$G$103<>"")+('Реестр'!$H$4:$H$103<>"")+('Реестр'!$J$4:$J$103<>""))>0),ROWS($K$5:K21)),"")
A22: =IF(ISNUMBER($K22),$K22,"") | B22: =IF(ISNUMBER($K22),IF(INDEX('Реестр'!$B$4:$B$103,$K22)="","",INDEX('Реестр'!$B$4:$B$103,$K22)),IF(ROW()=$K$3+5,"ИТОГО",IF(ROW()=$K$3+6,"ПОДРЯДЧИК",IF(ROW()=$K$3+7,"Должн./ФИО:",IF(ROW()=$K$3+8,"Подпись:",""))))) | C22: =IF(ISNUMBER($K22),IF(INDEX('Реестр'!$C$4:$C$103,$K22)="","",INDEX('Реестр'!$C$4:$C$103,$K22)),IF(ROW()=$K$3+7,"________________",IF(ROW()=$K$3+8,"________________",""))) | D22: =IF(ISNUMBER($K22),IF(INDEX('Реестр'!$D$4:$D$103,$K22)="","",INDEX('Реестр'!$D$4:$D$103,$K22)),IF(ROW()=$K$3+8,"Дата:","")) | E22: =IF(ISNUMBER($K22),IF(INDEX('Реестр'!$E$4:$E$103,$K22)="","",INDEX('Реестр'!$E$4:$E$103,$K22)),IF(ROW()=$K$3+8,"____________","")) | F22: =IF(ISNUMBER($K22),IF(INDEX('Реестр'!$F$4:$F$103,$K22)="","",INDEX('Реестр'!$F$4:$F$103,$K22)),IF(ROW()=$K$3+5,'Реестр'!F104,"")) | G22: =IF(ISNUMBER($K22),IF(INDEX('Реестр'!$G$4:$G$103,$K22)="","",INDEX('Реестр'!$G$4:$G$103,$K22)),IF(ROW()=$K$3+6,"ЗАКАЗЧИК",IF(ROW()=$K$3+7,"Должн./ФИО:",IF(ROW()=$K$3+8,"Подпись:","")))) | H22: =IF(ISNUMBER($K22),IF(INDEX('Реестр'!$H$4:$H$103,$K22)="","",INDEX('Реестр'!$H$4:$H$103,$K22)),IF(ROW()=$K$3+7,"________________",IF(ROW()=$K$3+8,"________________",""))) | I22: =IF(ISNUMBER($K22),IF(INDEX('Реестр'!$I$4:$I$103,$K22)="","",INDEX('Реестр'!$I$4:$I$103,$K22)),IF(ROW()=$K$3+5,'Реестр'!I104,IF(ROW()=$K$3+8,"Дата:",""))) | J22: =IF(ISNUMBER($K22),IF(INDEX('Реестр'!$J$4:$J$103,$K22)="","",INDEX('Реестр'!$J$4:$J$103,$K22)),IF(ROW()=$K$3+8,"____________","")) | K22: =IFERROR(_xlfn.AGGREGATE(15,6,(ROW('Реестр'!$B$4:$B$103)-3)/((('Реестр'!$B$4:$B$103<>"")+('Реестр'!$C$4:$C$103<>"")+('Реестр'!$D$4:$D$103<>"")+('Реестр'!$E$4:$E$103<>"")+('Реестр'!$G$4:$G$103<>"")+('Реестр'!$H$4:$H$103<>"")+('Реестр'!$J$4:$J$103<>""))>0),ROWS($K$5:K22)),"")
A23: =IF(ISNUMBER($K23),$K23,"") | B23: =IF(ISNUMBER($K23),IF(INDEX('Реестр'!$B$4:$B$103,$K23)="","",INDEX('Реестр'!$B$4:$B$103,$K23)),IF(ROW()=$K$3+5,"ИТОГО",IF(ROW()=$K$3+6,"ПОДРЯДЧИК",IF(ROW()=$K$3+7,"Должн./ФИО:",IF(ROW()=$K$3+8,"Подпись:",""))))) | C23: =IF(ISNUMBER($K23),IF(INDEX('Реестр'!$C$4:$C$103,$K23)="","",INDEX('Реестр'!$C$4:$C$103,$K23)),IF(ROW()=$K$3+7,"________________",IF(ROW()=$K$3+8,"________________",""))) | D23: =IF(ISNUMBER($K23),IF(INDEX('Реестр'!$D$4:$D$103,$K23)="","",INDEX('Реестр'!$D$4:$D$103,$K23)),IF(ROW()=$K$3+8,"Дата:","")) | E23: =IF(ISNUMBER($K23),IF(INDEX('Реестр'!$E$4:$E$103,$K23)="","",INDEX('Реестр'!$E$4:$E$103,$K23)),IF(ROW()=$K$3+8,"____________","")) | F23: =IF(ISNUMBER($K23),IF(INDEX('Реестр'!$F$4:$F$103,$K23)="","",INDEX('Реестр'!$F$4:$F$103,$K23)),IF(ROW()=$K$3+5,'Реестр'!F104,"")) | G23: =IF(ISNUMBER($K23),IF(INDEX('Реестр'!$G$4:$G$103,$K23)="","",INDEX('Реестр'!$G$4:$G$103,$K23)),IF(ROW()=$K$3+6,"ЗАКАЗЧИК",IF(ROW()=$K$3+7,"Должн./ФИО:",IF(ROW()=$K$3+8,"Подпись:","")))) | H23: =IF(ISNUMBER($K23),IF(INDEX('Реестр'!$H$4:$H$103,$K23)="","",INDEX('Реестр'!$H$4:$H$103,$K23)),IF(ROW()=$K$3+7,"________________",IF(ROW()=$K$3+8,"________________",""))) | I23: =IF(ISNUMBER($K23),IF(INDEX('Реестр'!$I$4:$I$103,$K23)="","",INDEX('Реестр'!$I$4:$I$103,$K23)),IF(ROW()=$K$3+5,'Реестр'!I104,IF(ROW()=$K$3+8,"Дата:",""))) | J23: =IF(ISNUMBER($K23),IF(INDEX('Реестр'!$J$4:$J$103,$K23)="","",INDEX('Реестр'!$J$4:$J$103,$K23)),IF(ROW()=$K$3+8,"____________","")) | K23: =IFERROR(_xlfn.AGGREGATE(15,6,(ROW('Реестр'!$B$4:$B$103)-3)/((('Реестр'!$B$4:$B$103<>"")+('Реестр'!$C$4:$C$103<>"")+('Реестр'!$D$4:$D$103<>"")+('Реестр'!$E$4:$E$103<>"")+('Реестр'!$G$4:$G$103<>"")+('Реестр'!$H$4:$H$103<>"")+('Реестр'!$J$4:$J$103<>""))>0),ROWS($K$5:K23)),"")
A24: =IF(ISNUMBER($K24),$K24,"") | B24: =IF(ISNUMBER($K24),IF(INDEX('Реестр'!$B$4:$B$103,$K24)="","",INDEX('Реестр'!$B$4:$B$103,$K24)),IF(ROW()=$K$3+5,"ИТОГО",IF(ROW()=$K$3+6,"ПОДРЯДЧИК",IF(ROW()=$K$3+7,"Должн./ФИО:",IF(ROW()=$K$3+8,"Подпись:",""))))) | C24: =IF(ISNUMBER($K24),IF(INDEX('Реестр'!$C$4:$C$103,$K24)="","",INDEX('Реестр'!$C$4:$C$103,$K24)),IF(ROW()=$K$3+7,"________________",IF(ROW()=$K$3+8,"________________",""))) | D24: =IF(ISNUMBER($K24),IF(INDEX('Реестр'!$D$4:$D$103,$K24)="","",INDEX('Реестр'!$D$4:$D$103,$K24)),IF(ROW()=$K$3+8,"Дата:","")) | E24: =IF(ISNUMBER($K24),IF(INDEX('Реестр'!$E$4:$E$103,$K24)="","",INDEX('Реестр'!$E$4:$E$103,$K24)),IF(ROW()=$K$3+8,"____________","")) | F24: =IF(ISNUMBER($K24),IF(INDEX('Реестр'!$F$4:$F$103,$K24)="","",INDEX('Реестр'!$F$4:$F$103,$K24)),IF(ROW()=$K$3+5,'Реестр'!F104,"")) | G24: =IF(ISNUMBER($K24),IF(INDEX('Реестр'!$G$4:$G$103,$K24)="","",INDEX('Реестр'!$G$4:$G$103,$K24)),IF(ROW()=$K$3+6,"ЗАКАЗЧИК",IF(ROW()=$K$3+7,"Должн./ФИО:",IF(ROW()=$K$3+8,"Подпись:","")))) | H24: =IF(ISNUMBER($K24),IF(INDEX('Реестр'!$H$4:$H$103,$K24)="","",INDEX('Реестр'!$H$4:$H$103,$K24)),IF(ROW()=$K$3+7,"________________",IF(ROW()=$K$3+8,"________________",""))) | I24: =IF(ISNUMBER($K24),IF(INDEX('Реестр'!$I$4:$I$103,$K24)="","",INDEX('Реестр'!$I$4:$I$103,$K24)),IF(ROW()=$K$3+5,'Реестр'!I104,IF(ROW()=$K$3+8,"Дата:",""))) | J24: =IF(ISNUMBER($K24),IF(INDEX('Реестр'!$J$4:$J$103,$K24)="","",INDEX('Реестр'!$J$4:$J$103,$K24)),IF(ROW()=$K$3+8,"____________","")) | K24: =IFERROR(_xlfn.AGGREGATE(15,6,(ROW('Реестр'!$B$4:$B$103)-3)/((('Реестр'!$B$4:$B$103<>"")+('Реестр'!$C$4:$C$103<>"")+('Реестр'!$D$4:$D$103<>"")+('Реестр'!$E$4:$E$103<>"")+('Реестр'!$G$4:$G$103<>"")+('Реестр'!$H$4:$H$103<>"")+('Реестр'!$J$4:$J$103<>""))>0),ROWS($K$5:K24)),"")
A25: =IF(ISNUMBER($K25),$K25,"") | B25: =IF(ISNUMBER($K25),IF(INDEX('Реестр'!$B$4:$B$103,$K25)="","",INDEX('Реестр'!$B$4:$B$103,$K25)),IF(ROW()=$K$3+5,"ИТОГО",IF(ROW()=$K$3+6,"ПОДРЯДЧИК",IF(ROW()=$K$3+7,"Должн./ФИО:",IF(ROW()=$K$3+8,"Подпись:",""))))) | C25: =IF(ISNUMBER($K25),IF(INDEX('Реестр'!$C$4:$C$103,$K25)="","",INDEX('Реестр'!$C$4:$C$103,$K25)),IF(ROW()=$K$3+7,"________________",IF(ROW()=$K$3+8,"________________",""))) | D25: =IF(ISNUMBER($K25),IF(INDEX('Реестр'!$D$4:$D$103,$K25)="","",INDEX('Реестр'!$D$4:$D$103,$K25)),IF(ROW()=$K$3+8,"Дата:","")) | E25: =IF(ISNUMBER($K25),IF(INDEX('Реестр'!$E$4:$E$103,$K25)="","",INDEX('Реестр'!$E$4:$E$103,$K25)),IF(ROW()=$K$3+8,"____________","")) | F25: =IF(ISNUMBER($K25),IF(INDEX('Реестр'!$F$4:$F$103,$K25)="","",INDEX('Реестр'!$F$4:$F$103,$K25)),IF(ROW()=$K$3+5,'Реестр'!F104,"")) | G25: =IF(ISNUMBER($K25),IF(INDEX('Реестр'!$G$4:$G$103,$K25)="","",INDEX('Реестр'!$G$4:$G$103,$K25)),IF(ROW()=$K$3+6,"ЗАКАЗЧИК",IF(ROW()=$K$3+7,"Должн./ФИО:",IF(ROW()=$K$3+8,"Подпись:","")))) | H25: =IF(ISNUMBER($K25),IF(INDEX('Реестр'!$H$4:$H$103,$K25)="","",INDEX('Реестр'!$H$4:$H$103,$K25)),IF(ROW()=$K$3+7,"________________",IF(ROW()=$K$3+8,"________________",""))) | I25: =IF(ISNUMBER($K25),IF(INDEX('Реестр'!$I$4:$I$103,$K25)="","",INDEX('Реестр'!$I$4:$I$103,$K25)),IF(ROW()=$K$3+5,'Реестр'!I104,IF(ROW()=$K$3+8,"Дата:",""))) | J25: =IF(ISNUMBER($K25),IF(INDEX('Реестр'!$J$4:$J$103,$K25)="","",INDEX('Реестр'!$J$4:$J$103,$K25)),IF(ROW()=$K$3+8,"____________","")) | K25: =IFERROR(_xlfn.AGGREGATE(15,6,(ROW('Реестр'!$B$4:$B$103)-3)/((('Реестр'!$B$4:$B$103<>"")+('Реестр'!$C$4:$C$103<>"")+('Реестр'!$D$4:$D$103<>"")+('Реестр'!$E$4:$E$103<>"")+('Реестр'!$G$4:$G$103<>"")+('Реестр'!$H$4:$H$103<>"")+('Реестр'!$J$4:$J$103<>""))>0),ROWS($K$5:K25)),"")
A26: =IF(ISNUMBER($K26),$K26,"") | B26: =IF(ISNUMBER($K26),IF(INDEX('Реестр'!$B$4:$B$103,$K26)="","",INDEX('Реестр'!$B$4:$B$103,$K26)),IF(ROW()=$K$3+5,"ИТОГО",IF(ROW()=$K$3+6,"ПОДРЯДЧИК",IF(ROW()=$K$3+7,"Должн./ФИО:",IF(ROW()=$K$3+8,"Подпись:",""))))) | C26: =IF(ISNUMBER($K26),IF(INDEX('Реестр'!$C$4:$C$103,$K26)="","",INDEX('Реестр'!$C$4:$C$103,$K26)),IF(ROW()=$K$3+7,"________________",IF(ROW()=$K$3+8,"________________",""))) | D26: =IF(ISNUMBER($K26),IF(INDEX('Реестр'!$D$4:$D$103,$K26)="","",INDEX('Реестр'!$D$4:$D$103,$K26)),IF(ROW()=$K$3+8,"Дата:","")) | E26: =IF(ISNUMBER($K26),IF(INDEX('Реестр'!$E$4:$E$103,$K26)="","",INDEX('Реестр'!$E$4:$E$103,$K26)),IF(ROW()=$K$3+8,"____________","")) | F26: =IF(ISNUMBER($K26),IF(INDEX('Реестр'!$F$4:$F$103,$K26)="","",INDEX('Реестр'!$F$4:$F$103,$K26)),IF(ROW()=$K$3+5,'Реестр'!F104,"")) | G26: =IF(ISNUMBER($K26),IF(INDEX('Реестр'!$G$4:$G$103,$K26)="","",INDEX('Реестр'!$G$4:$G$103,$K26)),IF(ROW()=$K$3+6,"ЗАКАЗЧИК",IF(ROW()=$K$3+7,"Должн./ФИО:",IF(ROW()=$K$3+8,"Подпись:","")))) | H26: =IF(ISNUMBER($K26),IF(INDEX('Реестр'!$H$4:$H$103,$K26)="","",INDEX('Реестр'!$H$4:$H$103,$K26)),IF(ROW()=$K$3+7,"________________",IF(ROW()=$K$3+8,"________________",""))) | I26: =IF(ISNUMBER($K26),IF(INDEX('Реестр'!$I$4:$I$103,$K26)="","",INDEX('Реестр'!$I$4:$I$103,$K26)),IF(ROW()=$K$3+5,'Реестр'!I104,IF(ROW()=$K$3+8,"Дата:",""))) | J26: =IF(ISNUMBER($K26),IF(INDEX('Реестр'!$J$4:$J$103,$K26)="","",INDEX('Реестр'!$J$4:$J$103,$K26)),IF(ROW()=$K$3+8,"____________","")) | K26: =IFERROR(_xlfn.AGGREGATE(15,6,(ROW('Реестр'!$B$4:$B$103)-3)/((('Реестр'!$B$4:$B$103<>"")+('Реестр'!$C$4:$C$103<>"")+('Реестр'!$D$4:$D$103<>"")+('Реестр'!$E$4:$E$103<>"")+('Реестр'!$G$4:$G$103<>"")+('Реестр'!$H$4:$H$103<>"")+('Реестр'!$J$4:$J$103<>""))>0),ROWS($K$5:K26)),"")
A27: =IF(ISNUMBER($K27),$K27,"") | B27: =IF(ISNUMBER($K27),IF(INDEX('Реестр'!$B$4:$B$103,$K27)="","",INDEX('Реестр'!$B$4:$B$103,$K27)),IF(ROW()=$K$3+5,"ИТОГО",IF(ROW()=$K$3+6,"ПОДРЯДЧИК",IF(ROW()=$K$3+7,"Должн./ФИО:",IF(ROW()=$K$3+8,"Подпись:",""))))) | C27: =IF(ISNUMBER($K27),IF(INDEX('Реестр'!$C$4:$C$103,$K27)="","",INDEX('Реестр'!$C$4:$C$103,$K27)),IF(ROW()=$K$3+7,"________________",IF(ROW()=$K$3+8,"________________",""))) | D27: =IF(ISNUMBER($K27),IF(INDEX('Реестр'!$D$4:$D$103,$K27)="","",INDEX('Реестр'!$D$4:$D$103,$K27)),IF(ROW()=$K$3+8,"Дата:","")) | E27: =IF(ISNUMBER($K27),IF(INDEX('Реестр'!$E$4:$E$103,$K27)="","",INDEX('Реестр'!$E$4:$E$103,$K27)),IF(ROW()=$K$3+8,"____________","")) | F27: =IF(ISNUMBER($K27),IF(INDEX('Реестр'!$F$4:$F$103,$K27)="","",INDEX('Реестр'!$F$4:$F$103,$K27)),IF(ROW()=$K$3+5,'Реестр'!F104,"")) | G27: =IF(ISNUMBER($K27),IF(INDEX('Реестр'!$G$4:$G$103,$K27)="","",INDEX('Реестр'!$G$4:$G$103,$K27)),IF(ROW()=$K$3+6,"ЗАКАЗЧИК",IF(ROW()=$K$3+7,"Должн./ФИО:",IF(ROW()=$K$3+8,"Подпись:","")))) | H27: =IF(ISNUMBER($K27),IF(INDEX('Реестр'!$H$4:$H$103,$K27)="","",INDEX('Реестр'!$H$4:$H$103,$K27)),IF(ROW()=$K$3+7,"________________",IF(ROW()=$K$3+8,"________________",""))) | I27: =IF(ISNUMBER($K27),IF(INDEX('Реестр'!$I$4:$I$103,$K27)="","",INDEX('Реестр'!$I$4:$I$103,$K27)),IF(ROW()=$K$3+5,'Реестр'!I104,IF(ROW()=$K$3+8,"Дата:",""))) | J27: =IF(ISNUMBER($K27),IF(INDEX('Реестр'!$J$4:$J$103,$K27)="","",INDEX('Реестр'!$J$4:$J$103,$K27)),IF(ROW()=$K$3+8,"____________","")) | K27: =IFERROR(_xlfn.AGGREGATE(15,6,(ROW('Реестр'!$B$4:$B$103)-3)/((('Реестр'!$B$4:$B$103<>"")+('Реестр'!$C$4:$C$103<>"")+('Реестр'!$D$4:$D$103<>"")+('Реестр'!$E$4:$E$103<>"")+('Реестр'!$G$4:$G$103<>"")+('Реестр'!$H$4:$H$103<>"")+('Реестр'!$J$4:$J$103<>""))>0),ROWS($K$5:K27)),"")
A28: =IF(ISNUMBER($K28),$K28,"") | B28: =IF(ISNUMBER($K28),IF(INDEX('Реестр'!$B$4:$B$103,$K28)="","",INDEX('Реестр'!$B$4:$B$103,$K28)),IF(ROW()=$K$3+5,"ИТОГО",IF(ROW()=$K$3+6,"ПОДРЯДЧИК",IF(ROW()=$K$3+7,"Должн./ФИО:",IF(ROW()=$K$3+8,"Подпись:",""))))) | C28: =IF(ISNUMBER($K28),IF(INDEX('Реестр'!$C$4:$C$103,$K28)="","",INDEX('Реестр'!$C$4:$C$103,$K28)),IF(ROW()=$K$3+7,"________________",IF(ROW()=$K$3+8,"________________",""))) | D28: =IF(ISNUMBER($K28),IF(INDEX('Реестр'!$D$4:$D$103,$K28)="","",INDEX('Реестр'!$D$4:$D$103,$K28)),IF(ROW()=$K$3+8,"Дата:","")) | E28: =IF(ISNUMBER($K28),IF(INDEX('Реестр'!$E$4:$E$103,$K28)="","",INDEX('Реестр'!$E$4:$E$103,$K28)),IF(ROW()=$K$3+8,"____________","")) | F28: =IF(ISNUMBER($K28),IF(INDEX('Реестр'!$F$4:$F$103,$K28)="","",INDEX('Реестр'!$F$4:$F$103,$K28)),IF(ROW()=$K$3+5,'Реестр'!F104,"")) | G28: =IF(ISNUMBER($K28),IF(INDEX('Реестр'!$G$4:$G$103,$K28)="","",INDEX('Реестр'!$G$4:$G$103,$K28)),IF(ROW()=$K$3+6,"ЗАКАЗЧИК",IF(ROW()=$K$3+7,"Должн./ФИО:",IF(ROW()=$K$3+8,"Подпись:","")))) | H28: =IF(ISNUMBER($K28),IF(INDEX('Реестр'!$H$4:$H$103,$K28)="","",INDEX('Реестр'!$H$4:$H$103,$K28)),IF(ROW()=$K$3+7,"________________",IF(ROW()=$K$3+8,"________________",""))) | I28: =IF(ISNUMBER($K28),IF(INDEX('Реестр'!$I$4:$I$103,$K28)="","",INDEX('Реестр'!$I$4:$I$103,$K28)),IF(ROW()=$K$3+5,'Реестр'!I104,IF(ROW()=$K$3+8,"Дата:",""))) | J28: =IF(ISNUMBER($K28),IF(INDEX('Реестр'!$J$4:$J$103,$K28)="","",INDEX('Реестр'!$J$4:$J$103,$K28)),IF(ROW()=$K$3+8,"____________","")) | K28: =IFERROR(_xlfn.AGGREGATE(15,6,(ROW('Реестр'!$B$4:$B$103)-3)/((('Реестр'!$B$4:$B$103<>"")+('Реестр'!$C$4:$C$103<>"")+('Реестр'!$D$4:$D$103<>"")+('Реестр'!$E$4:$E$103<>"")+('Реестр'!$G$4:$G$103<>"")+('Реестр'!$H$4:$H$103<>"")+('Реестр'!$J$4:$J$103<>""))>0),ROWS($K$5:K28)),"")
A29: =IF(ISNUMBER($K29),$K29,"") | B29: =IF(ISNUMBER($K29),IF(INDEX('Реестр'!$B$4:$B$103,$K29)="","",INDEX('Реестр'!$B$4:$B$103,$K29)),IF(ROW()=$K$3+5,"ИТОГО",IF(ROW()=$K$3+6,"ПОДРЯДЧИК",IF(ROW()=$K$3+7,"Должн./ФИО:",IF(ROW()=$K$3+8,"Подпись:",""))))) | C29: =IF(ISNUMBER($K29),IF(INDEX('Реестр'!$C$4:$C$103,$K29)="","",INDEX('Реестр'!$C$4:$C$103,$K29)),IF(ROW()=$K$3+7,"________________",IF(ROW()=$K$3+8,"________________",""))) | D29: =IF(ISNUMBER($K29),IF(INDEX('Реестр'!$D$4:$D$103,$K29)="","",INDEX('Реестр'!$D$4:$D$103,$K29)),IF(ROW()=$K$3+8,"Дата:","")) | E29: =IF(ISNUMBER($K29),IF(INDEX('Реестр'!$E$4:$E$103,$K29)="","",INDEX('Реестр'!$E$4:$E$103,$K29)),IF(ROW()=$K$3+8,"____________","")) | F29: =IF(ISNUMBER($K29),IF(INDEX('Реестр'!$F$4:$F$103,$K29)="","",INDEX('Реестр'!$F$4:$F$103,$K29)),IF(ROW()=$K$3+5,'Реестр'!F104,"")) | G29: =IF(ISNUMBER($K29),IF(INDEX('Реестр'!$G$4:$G$103,$K29)="","",INDEX('Реестр'!$G$4:$G$103,$K29)),IF(ROW()=$K$3+6,"ЗАКАЗЧИК",IF(ROW()=$K$3+7,"Должн./ФИО:",IF(ROW()=$K$3+8,"Подпись:","")))) | H29: =IF(ISNUMBER($K29),IF(INDEX('Реестр'!$H$4:$H$103,$K29)="","",INDEX('Реестр'!$H$4:$H$103,$K29)),IF(ROW()=$K$3+7,"________________",IF(ROW()=$K$3+8,"________________",""))) | I29: =IF(ISNUMBER($K29),IF(INDEX('Реестр'!$I$4:$I$103,$K29)="","",INDEX('Реестр'!$I$4:$I$103,$K29)),IF(ROW()=$K$3+5,'Реестр'!I104,IF(ROW()=$K$3+8,"Дата:",""))) | J29: =IF(ISNUMBER($K29),IF(INDEX('Реестр'!$J$4:$J$103,$K29)="","",INDEX('Реестр'!$J$4:$J$103,$K29)),IF(ROW()=$K$3+8,"____________","")) | K29: =IFERROR(_xlfn.AGGREGATE(15,6,(ROW('Реестр'!$B$4:$B$103)-3)/((('Реестр'!$B$4:$B$103<>"")+('Реестр'!$C$4:$C$103<>"")+('Реестр'!$D$4:$D$103<>"")+('Реестр'!$E$4:$E$103<>"")+('Реестр'!$G$4:$G$103<>"")+('Реестр'!$H$4:$H$103<>"")+('Реестр'!$J$4:$J$103<>""))>0),ROWS($K$5:K29)),"")
A30: =IF(ISNUMBER($K30),$K30,"") | B30: =IF(ISNUMBER($K30),IF(INDEX('Реестр'!$B$4:$B$103,$K30)="","",INDEX('Реестр'!$B$4:$B$103,$K30)),IF(ROW()=$K$3+5,"ИТОГО",IF(ROW()=$K$3+6,"ПОДРЯДЧИК",IF(ROW()=$K$3+7,"Должн./ФИО:",IF(ROW()=$K$3+8,"Подпись:",""))))) | C30: =IF(ISNUMBER($K30),IF(INDEX('Реестр'!$C$4:$C$103,$K30)="","",INDEX('Реестр'!$C$4:$C$103,$K30)),IF(ROW()=$K$3+7,"________________",IF(ROW()=$K$3+8,"________________",""))) | D30: =IF(ISNUMBER($K30),IF(INDEX('Реестр'!$D$4:$D$103,$K30)="","",INDEX('Реестр'!$D$4:$D$103,$K30)),IF(ROW()=$K$3+8,"Дата:","")) | E30: =IF(ISNUMBER($K30),IF(INDEX('Реестр'!$E$4:$E$103,$K30)="","",INDEX('Реестр'!$E$4:$E$103,$K30)),IF(ROW()=$K$3+8,"____________","")) | F30: =IF(ISNUMBER($K30),IF(INDEX('Реестр'!$F$4:$F$103,$K30)="","",INDEX('Реестр'!$F$4:$F$103,$K30)),IF(ROW()=$K$3+5,'Реестр'!F104,"")) | G30: =IF(ISNUMBER($K30),IF(INDEX('Реестр'!$G$4:$G$103,$K30)="","",INDEX('Реестр'!$G$4:$G$103,$K30)),IF(ROW()=$K$3+6,"ЗАКАЗЧИК",IF(ROW()=$K$3+7,"Должн./ФИО:",IF(ROW()=$K$3+8,"Подпись:","")))) | H30: =IF(ISNUMBER($K30),IF(INDEX('Реестр'!$H$4:$H$103,$K30)="","",INDEX('Реестр'!$H$4:$H$103,$K30)),IF(ROW()=$K$3+7,"________________",IF(ROW()=$K$3+8,"________________",""))) | I30: =IF(ISNUMBER($K30),IF(INDEX('Реестр'!$I$4:$I$103,$K30)="","",INDEX('Реестр'!$I$4:$I$103,$K30)),IF(ROW()=$K$3+5,'Реестр'!I104,IF(ROW()=$K$3+8,"Дата:",""))) | J30: =IF(ISNUMBER($K30),IF(INDEX('Реестр'!$J$4:$J$103,$K30)="","",INDEX('Реестр'!$J$4:$J$103,$K30)),IF(ROW()=$K$3+8,"____________","")) | K30: =IFERROR(_xlfn.AGGREGATE(15,6,(ROW('Реестр'!$B$4:$B$103)-3)/((('Реестр'!$B$4:$B$103<>"")+('Реестр'!$C$4:$C$103<>"")+('Реестр'!$D$4:$D$103<>"")+('Реестр'!$E$4:$E$103<>"")+('Реестр'!$G$4:$G$103<>"")+('Реестр'!$H$4:$H$103<>"")+('Реестр'!$J$4:$J$103<>""))>0),ROWS($K$5:K30)),"")
A31: =IF(ISNUMBER($K31),$K31,"") | B31: =IF(ISNUMBER($K31),IF(INDEX('Реестр'!$B$4:$B$103,$K31)="","",INDEX('Реестр'!$B$4:$B$103,$K31)),IF(ROW()=$K$3+5,"ИТОГО",IF(ROW()=$K$3+6,"ПОДРЯДЧИК",IF(ROW()=$K$3+7,"Должн./ФИО:",IF(ROW()=$K$3+8,"Подпись:",""))))) | C31: =IF(ISNUMBER($K31),IF(INDEX('Реестр'!$C$4:$C$103,$K31)="","",INDEX('Реестр'!$C$4:$C$103,$K31)),IF(ROW()=$K$3+7,"________________",IF(ROW()=$K$3+8,"________________",""))) | D31: =IF(ISNUMBER($K31),IF(INDEX('Реестр'!$D$4:$D$103,$K31)="","",INDEX('Реестр'!$D$4:$D$103,$K31)),IF(ROW()=$K$3+8,"Дата:","")) | E31: =IF(ISNUMBER($K31),IF(INDEX('Реестр'!$E$4:$E$103,$K31)="","",INDEX('Реестр'!$E$4:$E$103,$K31)),IF(ROW()=$K$3+8,"____________","")) | F31: =IF(ISNUMBER($K31),IF(INDEX('Реестр'!$F$4:$F$103,$K31)="","",INDEX('Реестр'!$F$4:$F$103,$K31)),IF(ROW()=$K$3+5,'Реестр'!F104,"")) | G31: =IF(ISNUMBER($K31),IF(INDEX('Реестр'!$G$4:$G$103,$K31)="","",INDEX('Реестр'!$G$4:$G$103,$K31)),IF(ROW()=$K$3+6,"ЗАКАЗЧИК",IF(ROW()=$K$3+7,"Должн./ФИО:",IF(ROW()=$K$3+8,"Подпись:","")))) | H31: =IF(ISNUMBER($K31),IF(INDEX('Реестр'!$H$4:$H$103,$K31)="","",INDEX('Реестр'!$H$4:$H$103,$K31)),IF(ROW()=$K$3+7,"________________",IF(ROW()=$K$3+8,"________________",""))) | I31: =IF(ISNUMBER($K31),IF(INDEX('Реестр'!$I$4:$I$103,$K31)="","",INDEX('Реестр'!$I$4:$I$103,$K31)),IF(ROW()=$K$3+5,'Реестр'!I104,IF(ROW()=$K$3+8,"Дата:",""))) | J31: =IF(ISNUMBER($K31),IF(INDEX('Реестр'!$J$4:$J$103,$K31)="","",INDEX('Реестр'!$J$4:$J$103,$K31)),IF(ROW()=$K$3+8,"____________","")) | K31: =IFERROR(_xlfn.AGGREGATE(15,6,(ROW('Реестр'!$B$4:$B$103)-3)/((('Реестр'!$B$4:$B$103<>"")+('Реестр'!$C$4:$C$103<>"")+('Реестр'!$D$4:$D$103<>"")+('Реестр'!$E$4:$E$103<>"")+('Реестр'!$G$4:$G$103<>"")+('Реестр'!$H$4:$H$103<>"")+('Реестр'!$J$4:$J$103<>""))>0),ROWS($K$5:K31)),"")
A32: =IF(ISNUMBER($K32),$K32,"") | B32: =IF(ISNUMBER($K32),IF(INDEX('Реестр'!$B$4:$B$103,$K32)="","",INDEX('Реестр'!$B$4:$B$103,$K32)),IF(ROW()=$K$3+5,"ИТОГО",IF(ROW()=$K$3+6,"ПОДРЯДЧИК",IF(ROW()=$K$3+7,"Должн./ФИО:",IF(ROW()=$K$3+8,"Подпись:",""))))) | C32: =IF(ISNUMBER($K32),IF(INDEX('Реестр'!$C$4:$C$103,$K32)="","",INDEX('Реестр'!$C$4:$C$103,$K32)),IF(ROW()=$K$3+7,"________________",IF(ROW()=$K$3+8,"________________",""))) | D32: =IF(ISNUMBER($K32),IF(INDEX('Реестр'!$D$4:$D$103,$K32)="","",INDEX('Реестр'!$D$4:$D$103,$K32)),IF(ROW()=$K$3+8,"Дата:","")) | E32: =IF(ISNUMBER($K32),IF(INDEX('Реестр'!$E$4:$E$103,$K32)="","",INDEX('Реестр'!$E$4:$E$103,$K32)),IF(ROW()=$K$3+8,"____________","")) | F32: =IF(ISNUMBER($K32),IF(INDEX('Реестр'!$F$4:$F$103,$K32)="","",INDEX('Реестр'!$F$4:$F$103,$K32)),IF(ROW()=$K$3+5,'Реестр'!F104,"")) | G32: =IF(ISNUMBER($K32),IF(INDEX('Реестр'!$G$4:$G$103,$K32)="","",INDEX('Реестр'!$G$4:$G$103,$K32)),IF(ROW()=$K$3+6,"ЗАКАЗЧИК",IF(ROW()=$K$3+7,"Должн./ФИО:",IF(ROW()=$K$3+8,"Подпись:","")))) | H32: =IF(ISNUMBER($K32),IF(INDEX('Реестр'!$H$4:$H$103,$K32)="","",INDEX('Реестр'!$H$4:$H$103,$K32)),IF(ROW()=$K$3+7,"________________",IF(ROW()=$K$3+8,"________________",""))) | I32: =IF(ISNUMBER($K32),IF(INDEX('Реестр'!$I$4:$I$103,$K32)="","",INDEX('Реестр'!$I$4:$I$103,$K32)),IF(ROW()=$K$3+5,'Реестр'!I104,IF(ROW()=$K$3+8,"Дата:",""))) | J32: =IF(ISNUMBER($K32),IF(INDEX('Реестр'!$J$4:$J$103,$K32)="","",INDEX('Реестр'!$J$4:$J$103,$K32)),IF(ROW()=$K$3+8,"____________","")) | K32: =IFERROR(_xlfn.AGGREGATE(15,6,(ROW('Реестр'!$B$4:$B$103)-3)/((('Реестр'!$B$4:$B$103<>"")+('Реестр'!$C$4:$C$103<>"")+('Реестр'!$D$4:$D$103<>"")+('Реестр'!$E$4:$E$103<>"")+('Реестр'!$G$4:$G$103<>"")+('Реестр'!$H$4:$H$103<>"")+('Реестр'!$J$4:$J$103<>""))>0),ROWS($K$5:K32)),"")
A33: =IF(ISNUMBER($K33),$K33,"") | B33: =IF(ISNUMBER($K33),IF(INDEX('Реестр'!$B$4:$B$103,$K33)="","",INDEX('Реестр'!$B$4:$B$103,$K33)),IF(ROW()=$K$3+5,"ИТОГО",IF(ROW()=$K$3+6,"ПОДРЯДЧИК",IF(ROW()=$K$3+7,"Должн./ФИО:",IF(ROW()=$K$3+8,"Подпись:",""))))) | C33: =IF(ISNUMBER($K33),IF(INDEX('Реестр'!$C$4:$C$103,$K33)="","",INDEX('Реестр'!$C$4:$C$103,$K33)),IF(ROW()=$K$3+7,"________________",IF(ROW()=$K$3+8,"________________",""))) | D33: =IF(ISNUMBER($K33),IF(INDEX('Реестр'!$D$4:$D$103,$K33)="","",INDEX('Реестр'!$D$4:$D$103,$K33)),IF(ROW()=$K$3+8,"Дата:","")) | E33: =IF(ISNUMBER($K33),IF(INDEX('Реестр'!$E$4:$E$103,$K33)="","",INDEX('Реестр'!$E$4:$E$103,$K33)),IF(ROW()=$K$3+8,"____________","")) | F33: =IF(ISNUMBER($K33),IF(INDEX('Реестр'!$F$4:$F$103,$K33)="","",INDEX('Реестр'!$F$4:$F$103,$K33)),IF(ROW()=$K$3+5,'Реестр'!F104,"")) | G33: =IF(ISNUMBER($K33),IF(INDEX('Реестр'!$G$4:$G$103,$K33)="","",INDEX('Реестр'!$G$4:$G$103,$K33)),IF(ROW()=$K$3+6,"ЗАКАЗЧИК",IF(ROW()=$K$3+7,"Должн./ФИО:",IF(ROW()=$K$3+8,"Подпись:","")))) | H33: =IF(ISNUMBER($K33),IF(INDEX('Реестр'!$H$4:$H$103,$K33)="","",INDEX('Реестр'!$H$4:$H$103,$K33)),IF(ROW()=$K$3+7,"________________",IF(ROW()=$K$3+8,"________________",""))) | I33: =IF(ISNUMBER($K33),IF(INDEX('Реестр'!$I$4:$I$103,$K33)="","",INDEX('Реестр'!$I$4:$I$103,$K33)),IF(ROW()=$K$3+5,'Реестр'!I104,IF(ROW()=$K$3+8,"Дата:",""))) | J33: =IF(ISNUMBER($K33),IF(INDEX('Реестр'!$J$4:$J$103,$K33)="","",INDEX('Реестр'!$J$4:$J$103,$K33)),IF(ROW()=$K$3+8,"____________","")) | K33: =IFERROR(_xlfn.AGGREGATE(15,6,(ROW('Реестр'!$B$4:$B$103)-3)/((('Реестр'!$B$4:$B$103<>"")+('Реестр'!$C$4:$C$103<>"")+('Реестр'!$D$4:$D$103<>"")+('Реестр'!$E$4:$E$103<>"")+('Реестр'!$G$4:$G$103<>"")+('Реестр'!$H$4:$H$103<>"")+('Реестр'!$J$4:$J$103<>""))>0),ROWS($K$5:K33)),"")
A34: =IF(ISNUMBER($K34),$K34,"") | B34: =IF(ISNUMBER($K34),IF(INDEX('Реестр'!$B$4:$B$103,$K34)="","",INDEX('Реестр'!$B$4:$B$103,$K34)),IF(ROW()=$K$3+5,"ИТОГО",IF(ROW()=$K$3+6,"ПОДРЯДЧИК",IF(ROW()=$K$3+7,"Должн./ФИО:",IF(ROW()=$K$3+8,"Подпись:",""))))) | C34: =IF(ISNUMBER($K34),IF(INDEX('Реестр'!$C$4:$C$103,$K34)="","",INDEX('Реестр'!$C$4:$C$103,$K34)),IF(ROW()=$K$3+7,"________________",IF(ROW()=$K$3+8,"________________",""))) | D34: =IF(ISNUMBER($K34),IF(INDEX('Реестр'!$D$4:$D$103,$K34)="","",INDEX('Реестр'!$D$4:$D$103,$K34)),IF(ROW()=$K$3+8,"Дата:","")) | E34: =IF(ISNUMBER($K34),IF(INDEX('Реестр'!$E$4:$E$103,$K34)="","",INDEX('Реестр'!$E$4:$E$103,$K34)),IF(ROW()=$K$3+8,"____________","")) | F34: =IF(ISNUMBER($K34),IF(INDEX('Реестр'!$F$4:$F$103,$K34)="","",INDEX('Реестр'!$F$4:$F$103,$K34)),IF(ROW()=$K$3+5,'Реестр'!F104,"")) | G34: =IF(ISNUMBER($K34),IF(INDEX('Реестр'!$G$4:$G$103,$K34)="","",INDEX('Реестр'!$G$4:$G$103,$K34)),IF(ROW()=$K$3+6,"ЗАКАЗЧИК",IF(ROW()=$K$3+7,"Должн./ФИО:",IF(ROW()=$K$3+8,"Подпись:","")))) | H34: =IF(ISNUMBER($K34),IF(INDEX('Реестр'!$H$4:$H$103,$K34)="","",INDEX('Реестр'!$H$4:$H$103,$K34)),IF(ROW()=$K$3+7,"________________",IF(ROW()=$K$3+8,"________________",""))) | I34: =IF(ISNUMBER($K34),IF(INDEX('Реестр'!$I$4:$I$103,$K34)="","",INDEX('Реестр'!$I$4:$I$103,$K34)),IF(ROW()=$K$3+5,'Реестр'!I104,IF(ROW()=$K$3+8,"Дата:",""))) | J34: =IF(ISNUMBER($K34),IF(INDEX('Реестр'!$J$4:$J$103,$K34)="","",INDEX('Реестр'!$J$4:$J$103,$K34)),IF(ROW()=$K$3+8,"____________","")) | K34: =IFERROR(_xlfn.AGGREGATE(15,6,(ROW('Реестр'!$B$4:$B$103)-3)/((('Реестр'!$B$4:$B$103<>"")+('Реестр'!$C$4:$C$103<>"")+('Реестр'!$D$4:$D$103<>"")+('Реестр'!$E$4:$E$103<>"")+('Реестр'!$G$4:$G$103<>"")+('Реестр'!$H$4:$H$103<>"")+('Реестр'!$J$4:$J$103<>""))>0),ROWS($K$5:K34)),"")
