Workbook

Sheet Как пользоваться
A1: Расчёт процентов по ст. 395 ГК РФ
A2: 1. Лист «Акты»: одна строка — один акт (или часть долга) со своей датой начала просрочки. По каждому акту из файла 04, лист «Долг по актам», переносится только бесспорная часть: в колонку «Бесспорный на первый день просрочки» — колонка J того листа, в колонку «Первый день просрочки» — колонка E, в колонку сверки — колонка M («Текущий бесспорный остаток»). Спорная часть (удержание, зачёт встречного требования, неустойка, допработы без соглашения) сюда не вносится: проценты на неё книга не считает ни за какой период, её оценка — у специалиста. Сверка нужна, чтобы оплаты не учлись дважды: если в колонку долга попадёт сумма, из которой оплаты уже вычтены, сверка не сойдётся и книга заблокирует расчёт.
A3: 2. Лист «Ввод»: последний день расчёта и обязательная сверка с файлом 04 — бесспорная часть долга из листа «Взаиморасчёты», строка «БЕССПОРНАЯ ЧАСТЬ» (ячейка M12). Сумма колонки F листа «Акты» должна с ней совпасть (за вычетом актов файла 04, которые не входят в этот расчёт). Если на лист «Акты» перенесён общий долг вместе со спорной частью, сверка не сойдётся и расчёт будет заблокирован. Без этой суммы расчёт тоже заблокирован.
A4: 3. Лист «Ввод»: ключевая ставка Банка России (cbr.ru, раздел «Ключевая ставка Банка России»): ставка, действовавшая в первый день просрочки самого раннего акта, и все её изменения до конца расчёта — по возрастанию дат, без пропусков строк. Ставка вводится в процентах годовых: 21 означает 21 %. Долю (0,21) книга не принимает.
A5: 4. Лист «Ввод»: периоды, за которые проценты не начисляются (например, мораторий), если они применимы к вашему должнику. Применимость проверьте у специалиста.
A6: 5. Лист «Оплаты»: каждая оплата, поступившая в первый день просрочки по своему акту или позже, — дата, сумма и акт, к которому она отнесена. Оплата, поступившая в день D, уменьшает долг по своему акту со следующего дня. Книга сама делит расчёт каждого акта на периоды по датам его оплат и смене ставки.
A7: 6. Платёж без указания акта расчёт блокирует. Система не распределяет платежи между актами сама и не назначает очередность зачёта: это правовой вопрос, который решается назначением платежа, договором или соглашением сторон. Распределите платёж документально и укажите акт.
A8: 7. Лист «Проверки»: все строки должны быть «ок». Любая строка «БЛОК» останавливает итог: книга не выдаёт сумму, которая может быть завышена или занижена.
A9: 8. Лист «Расчёт»: строки расчёта по каждому акту для приложения к претензии и иску. Строка — отрезок, на котором долг акта не меняется; её проценты — сумма по периодам ставки, каждый округлён до копейки. Проценты по акту — сумма его строк; «Проценты итого» — сумма итогов по актам.
A10: Каждый акт считается отдельно: своя дата начала просрочки, свой долг, свои оплаты, свои периоды и своё округление. Акты не объединяются в один долг — ни с одной датой, ни по дням: это занизило бы или завысило проценты. Лист «По дням» — общий календарь (одна строка на день): из него берутся ставка, число дней в году и исключения.
A11: Ограничения: до 12 актов в одном расчёте, до 500 оплат, 60 изменений ставки, 20 исключаемых периодов, 3999 дней от первого дня просрочки самого раннего акта до последнего дня расчёта и 150 периодов ставки. Данные за пределами таблиц не отбрасываются молча, а блокируют итог.
A12: Оплаты уменьшают основной долг. Если договор устанавливает неустойку за просрочку оплаты, проценты по ст. 395 ГК РФ по общему правилу не взыскиваются (п. 4 ст. 395 ГК РФ) — выбор к специалисту.
... A14: Редакция-кандидат. Правовые ссылки этой редакции не прошли юридическую приёмку; перед применением сверьте их с действующей редакцией закона.

Sheet Акты
A1: Акты и суммы долга на первый день просрочки
A2: Одна строка — один акт (или часть долга) со своей датой начала просрочки. Акт входит в долг со своего первого дня просрочки; до этой даты проценты по нему не начисляются. Колонки D, E и F заполняются из файла 04, лист «Долг по актам», только бесспорной частью: D — «Бесспорный на первый день просрочки» (колонка J), E — «Первый день просрочки» (колонка E), F — «Текущий бесспорный остаток» (колонка M). Спорную часть акта сюда не вносите. По F книга проверяет, что оплаты не учтены дважды: если в D попала сумма, из которой оплаты уже вычтены, сверка не сойдётся и расчёт будет заблокирован. Сумма колонки F сверяется с бесспорной частью файла 04 на листе «Ввод»: общий долг вместе со спорной частью сверку не пройдёт.
A4: № | B4: Акт (идентификатор, как в файле 04) | C4: Документ (КС-2 / акт: №, дата) | D4: Бесспорный на первый день просрочки, руб. (файл 04, «Долг по актам», колонка J) | E4: Первый день просрочки | F4: Сверка: текущий бесспорный остаток по акту из файла 04 (колонка M), руб. | G4: Остаток по расчёту на последний день, руб. | H4: Проверка
A5: 1 | G5: =IF(OR(B5="",NOT(ISNUMBER(D5))),"",D5-SUMIF(Оплаты!$D$6:$D$505,B5,Оплаты!$B$6:$B$505)) | H5: =IF(AND(B5="",C5="",D5="",E5="",F5=""),"",IF(B5="","БЛОК: нужен идентификатор акта — по нему распределяются оплаты",IF(COUNTIF($B$5:$B$16,B5)>1,"БЛОК: идентификатор акта повторяется — оплату нельзя отнести однозначно",IF(OR(NOT(ISNUMBER(D5)),D5<=0),"БЛОК: нужен бесспорный долг на первый день просрочки, больше нуля (файл 04, лист «Долг по актам», колонка J)",IF(NOT(ISNUMBER(E5)),"БЛОК: нужен первый день просрочки по этому акту",IF(NOT(ISNUMBER(Ввод!$B$4)),"БЛОК: на листе «Ввод» не введён последний день расчёта",IF(E5>Ввод!$B$4,"БЛОК: первый день просрочки позже последнего дня расчёта",IF(Ввод!$B$4-E5+1>3999,"БЛОК: от первого дня просрочки до последнего дня расчёта более 3999 дней — разбейте расчёт на части",IF(COUNT(Ввод!$A$12:$A$71)=0,"БЛОК: на листе «Ввод» не введена ставка",IF(MIN(Ввод!$D$12:$D$71)>E5,"БЛОК: нет ставки, действовавшей в первый день просрочки по этому акту",IF(N(G5)<0,"БЛОК: оплаты по этому акту больше долга на первый день просрочки",IF(NOT(ISNUMBER(F5)),"БЛОК: нужна сверочная сумма по этому акту из файла 04 (лист «Долг по актам», колонка M — текущий бесспорный остаток)",IF(ROUND(N(G5)-F5,2)<>0,"БЛОК: сверка не сходится. Долг на первый день просрочки минус оплаты по этому акту = "&FIXED(N(G5),2)&" руб., а по файлу 04 = "&FIXED(F5,2)&" руб. Похоже, в колонку D внесён текущий остаток, из которого оплаты уже вычтены: тогда те же оплаты учтутся дважды. В колонке D нужен бесспорный долг НА ПЕРВЫЙ ДЕНЬ ПРОСРОЧКИ (файл 04, колонка J)","ок")))))))))))))
A6: 2 | G6: =IF(OR(B6="",NOT(ISNUMBER(D6))),"",D6-SUMIF(Оплаты!$D$6:$D$505,B6,Оплаты!$B$6:$B$505)) | H6: =IF(AND(B6="",C6="",D6="",E6="",F6=""),"",IF(B6="","БЛОК: нужен идентификатор акта — по нему распределяются оплаты",IF(COUNTIF($B$5:$B$16,B6)>1,"БЛОК: идентификатор акта повторяется — оплату нельзя отнести однозначно",IF(OR(NOT(ISNUMBER(D6)),D6<=0),"БЛОК: нужен бесспорный долг на первый день просрочки, больше нуля (файл 04, лист «Долг по актам», колонка J)",IF(NOT(ISNUMBER(E6)),"БЛОК: нужен первый день просрочки по этому акту",IF(NOT(ISNUMBER(Ввод!$B$4)),"БЛОК: на листе «Ввод» не введён последний день расчёта",IF(E6>Ввод!$B$4,"БЛОК: первый день просрочки позже последнего дня расчёта",IF(Ввод!$B$4-E6+1>3999,"БЛОК: от первого дня просрочки до последнего дня расчёта более 3999 дней — разбейте расчёт на части",IF(COUNT(Ввод!$A$12:$A$71)=0,"БЛОК: на листе «Ввод» не введена ставка",IF(MIN(Ввод!$D$12:$D$71)>E6,"БЛОК: нет ставки, действовавшей в первый день просрочки по этому акту",IF(N(G6)<0,"БЛОК: оплаты по этому акту больше долга на первый день просрочки",IF(NOT(ISNUMBER(F6)),"БЛОК: нужна сверочная сумма по этому акту из файла 04 (лист «Долг по актам», колонка M — текущий бесспорный остаток)",IF(ROUND(N(G6)-F6,2)<>0,"БЛОК: сверка не сходится. Долг на первый день просрочки минус оплаты по этому акту = "&FIXED(N(G6),2)&" руб., а по файлу 04 = "&FIXED(F6,2)&" руб. Похоже, в колонку D внесён текущий остаток, из которого оплаты уже вычтены: тогда те же оплаты учтутся дважды. В колонке D нужен бесспорный долг НА ПЕРВЫЙ ДЕНЬ ПРОСРОЧКИ (файл 04, колонка J)","ок")))))))))))))
A7: 3 | G7: =IF(OR(B7="",NOT(ISNUMBER(D7))),"",D7-SUMIF(Оплаты!$D$6:$D$505,B7,Оплаты!$B$6:$B$505)) | H7: =IF(AND(B7="",C7="",D7="",E7="",F7=""),"",IF(B7="","БЛОК: нужен идентификатор акта — по нему распределяются оплаты",IF(COUNTIF($B$5:$B$16,B7)>1,"БЛОК: идентификатор акта повторяется — оплату нельзя отнести однозначно",IF(OR(NOT(ISNUMBER(D7)),D7<=0),"БЛОК: нужен бесспорный долг на первый день просрочки, больше нуля (файл 04, лист «Долг по актам», колонка J)",IF(NOT(ISNUMBER(E7)),"БЛОК: нужен первый день просрочки по этому акту",IF(NOT(ISNUMBER(Ввод!$B$4)),"БЛОК: на листе «Ввод» не введён последний день расчёта",IF(E7>Ввод!$B$4,"БЛОК: первый день просрочки позже последнего дня расчёта",IF(Ввод!$B$4-E7+1>3999,"БЛОК: от первого дня просрочки до последнего дня расчёта более 3999 дней — разбейте расчёт на части",IF(COUNT(Ввод!$A$12:$A$71)=0,"БЛОК: на листе «Ввод» не введена ставка",IF(MIN(Ввод!$D$12:$D$71)>E7,"БЛОК: нет ставки, действовавшей в первый день просрочки по этому акту",IF(N(G7)<0,"БЛОК: оплаты по этому акту больше долга на первый день просрочки",IF(NOT(ISNUMBER(F7)),"БЛОК: нужна сверочная сумма по этому акту из файла 04 (лист «Долг по актам», колонка M — текущий бесспорный остаток)",IF(ROUND(N(G7)-F7,2)<>0,"БЛОК: сверка не сходится. Долг на первый день просрочки минус оплаты по этому акту = "&FIXED(N(G7),2)&" руб., а по файлу 04 = "&FIXED(F7,2)&" руб. Похоже, в колонку D внесён текущий остаток, из которого оплаты уже вычтены: тогда те же оплаты учтутся дважды. В колонке D нужен бесспорный долг НА ПЕРВЫЙ ДЕНЬ ПРОСРОЧКИ (файл 04, колонка J)","ок")))))))))))))
A8: 4 | G8: =IF(OR(B8="",NOT(ISNUMBER(D8))),"",D8-SUMIF(Оплаты!$D$6:$D$505,B8,Оплаты!$B$6:$B$505)) | H8: =IF(AND(B8="",C8="",D8="",E8="",F8=""),"",IF(B8="","БЛОК: нужен идентификатор акта — по нему распределяются оплаты",IF(COUNTIF($B$5:$B$16,B8)>1,"БЛОК: идентификатор акта повторяется — оплату нельзя отнести однозначно",IF(OR(NOT(ISNUMBER(D8)),D8<=0),"БЛОК: нужен бесспорный долг на первый день просрочки, больше нуля (файл 04, лист «Долг по актам», колонка J)",IF(NOT(ISNUMBER(E8)),"БЛОК: нужен первый день просрочки по этому акту",IF(NOT(ISNUMBER(Ввод!$B$4)),"БЛОК: на листе «Ввод» не введён последний день расчёта",IF(E8>Ввод!$B$4,"БЛОК: первый день просрочки позже последнего дня расчёта",IF(Ввод!$B$4-E8+1>3999,"БЛОК: от первого дня просрочки до последнего дня расчёта более 3999 дней — разбейте расчёт на части",IF(COUNT(Ввод!$A$12:$A$71)=0,"БЛОК: на листе «Ввод» не введена ставка",IF(MIN(Ввод!$D$12:$D$71)>E8,"БЛОК: нет ставки, действовавшей в первый день просрочки по этому акту",IF(N(G8)<0,"БЛОК: оплаты по этому акту больше долга на первый день просрочки",IF(NOT(ISNUMBER(F8)),"БЛОК: нужна сверочная сумма по этому акту из файла 04 (лист «Долг по актам», колонка M — текущий бесспорный остаток)",IF(ROUND(N(G8)-F8,2)<>0,"БЛОК: сверка не сходится. Долг на первый день просрочки минус оплаты по этому акту = "&FIXED(N(G8),2)&" руб., а по файлу 04 = "&FIXED(F8,2)&" руб. Похоже, в колонку D внесён текущий остаток, из которого оплаты уже вычтены: тогда те же оплаты учтутся дважды. В колонке D нужен бесспорный долг НА ПЕРВЫЙ ДЕНЬ ПРОСРОЧКИ (файл 04, колонка J)","ок")))))))))))))
A9: 5 | G9: =IF(OR(B9="",NOT(ISNUMBER(D9))),"",D9-SUMIF(Оплаты!$D$6:$D$505,B9,Оплаты!$B$6:$B$505)) | H9: =IF(AND(B9="",C9="",D9="",E9="",F9=""),"",IF(B9="","БЛОК: нужен идентификатор акта — по нему распределяются оплаты",IF(COUNTIF($B$5:$B$16,B9)>1,"БЛОК: идентификатор акта повторяется — оплату нельзя отнести однозначно",IF(OR(NOT(ISNUMBER(D9)),D9<=0),"БЛОК: нужен бесспорный долг на первый день просрочки, больше нуля (файл 04, лист «Долг по актам», колонка J)",IF(NOT(ISNUMBER(E9)),"БЛОК: нужен первый день просрочки по этому акту",IF(NOT(ISNUMBER(Ввод!$B$4)),"БЛОК: на листе «Ввод» не введён последний день расчёта",IF(E9>Ввод!$B$4,"БЛОК: первый день просрочки позже последнего дня расчёта",IF(Ввод!$B$4-E9+1>3999,"БЛОК: от первого дня просрочки до последнего дня расчёта более 3999 дней — разбейте расчёт на части",IF(COUNT(Ввод!$A$12:$A$71)=0,"БЛОК: на листе «Ввод» не введена ставка",IF(MIN(Ввод!$D$12:$D$71)>E9,"БЛОК: нет ставки, действовавшей в первый день просрочки по этому акту",IF(N(G9)<0,"БЛОК: оплаты по этому акту больше долга на первый день просрочки",IF(NOT(ISNUMBER(F9)),"БЛОК: нужна сверочная сумма по этому акту из файла 04 (лист «Долг по актам», колонка M — текущий бесспорный остаток)",IF(ROUND(N(G9)-F9,2)<>0,"БЛОК: сверка не сходится. Долг на первый день просрочки минус оплаты по этому акту = "&FIXED(N(G9),2)&" руб., а по файлу 04 = "&FIXED(F9,2)&" руб. Похоже, в колонку D внесён текущий остаток, из которого оплаты уже вычтены: тогда те же оплаты учтутся дважды. В колонке D нужен бесспорный долг НА ПЕРВЫЙ ДЕНЬ ПРОСРОЧКИ (файл 04, колонка J)","ок")))))))))))))
A10: 6 | G10: =IF(OR(B10="",NOT(ISNUMBER(D10))),"",D10-SUMIF(Оплаты!$D$6:$D$505,B10,Оплаты!$B$6:$B$505)) | H10: =IF(AND(B10="",C10="",D10="",E10="",F10=""),"",IF(B10="","БЛОК: нужен идентификатор акта — по нему распределяются оплаты",IF(COUNTIF($B$5:$B$16,B10)>1,"БЛОК: идентификатор акта повторяется — оплату нельзя отнести однозначно",IF(OR(NOT(ISNUMBER(D10)),D10<=0),"БЛОК: нужен бесспорный долг на первый день просрочки, больше нуля (файл 04, лист «Долг по актам», колонка J)",IF(NOT(ISNUMBER(E10)),"БЛОК: нужен первый день просрочки по этому акту",IF(NOT(ISNUMBER(Ввод!$B$4)),"БЛОК: на листе «Ввод» не введён последний день расчёта",IF(E10>Ввод!$B$4,"БЛОК: первый день просрочки позже последнего дня расчёта",IF(Ввод!$B$4-E10+1>3999,"БЛОК: от первого дня просрочки до последнего дня расчёта более 3999 дней — разбейте расчёт на части",IF(COUNT(Ввод!$A$12:$A$71)=0,"БЛОК: на листе «Ввод» не введена ставка",IF(MIN(Ввод!$D$12:$D$71)>E10,"БЛОК: нет ставки, действовавшей в первый день просрочки по этому акту",IF(N(G10)<0,"БЛОК: оплаты по этому акту больше долга на первый день просрочки",IF(NOT(ISNUMBER(F10)),"БЛОК: нужна сверочная сумма по этому акту из файла 04 (лист «Долг по актам», колонка M — текущий бесспорный остаток)",IF(ROUND(N(G10)-F10,2)<>0,"БЛОК: сверка не сходится. Долг на первый день просрочки минус оплаты по этому акту = "&FIXED(N(G10),2)&" руб., а по файлу 04 = "&FIXED(F10,2)&" руб. Похоже, в колонку D внесён текущий остаток, из которого оплаты уже вычтены: тогда те же оплаты учтутся дважды. В колонке D нужен бесспорный долг НА ПЕРВЫЙ ДЕНЬ ПРОСРОЧКИ (файл 04, колонка J)","ок")))))))))))))
A11: 7 | G11: =IF(OR(B11="",NOT(ISNUMBER(D11))),"",D11-SUMIF(Оплаты!$D$6:$D$505,B11,Оплаты!$B$6:$B$505)) | H11: =IF(AND(B11="",C11="",D11="",E11="",F11=""),"",IF(B11="","БЛОК: нужен идентификатор акта — по нему распределяются оплаты",IF(COUNTIF($B$5:$B$16,B11)>1,"БЛОК: идентификатор акта повторяется — оплату нельзя отнести однозначно",IF(OR(NOT(ISNUMBER(D11)),D11<=0),"БЛОК: нужен бесспорный долг на первый день просрочки, больше нуля (файл 04, лист «Долг по актам», колонка J)",IF(NOT(ISNUMBER(E11)),"БЛОК: нужен первый день просрочки по этому акту",IF(NOT(ISNUMBER(Ввод!$B$4)),"БЛОК: на листе «Ввод» не введён последний день расчёта",IF(E11>Ввод!$B$4,"БЛОК: первый день просрочки позже последнего дня расчёта",IF(Ввод!$B$4-E11+1>3999,"БЛОК: от первого дня просрочки до последнего дня расчёта более 3999 дней — разбейте расчёт на части",IF(COUNT(Ввод!$A$12:$A$71)=0,"БЛОК: на листе «Ввод» не введена ставка",IF(MIN(Ввод!$D$12:$D$71)>E11,"БЛОК: нет ставки, действовавшей в первый день просрочки по этому акту",IF(N(G11)<0,"БЛОК: оплаты по этому акту больше долга на первый день просрочки",IF(NOT(ISNUMBER(F11)),"БЛОК: нужна сверочная сумма по этому акту из файла 04 (лист «Долг по актам», колонка M — текущий бесспорный остаток)",IF(ROUND(N(G11)-F11,2)<>0,"БЛОК: сверка не сходится. Долг на первый день просрочки минус оплаты по этому акту = "&FIXED(N(G11),2)&" руб., а по файлу 04 = "&FIXED(F11,2)&" руб. Похоже, в колонку D внесён текущий остаток, из которого оплаты уже вычтены: тогда те же оплаты учтутся дважды. В колонке D нужен бесспорный долг НА ПЕРВЫЙ ДЕНЬ ПРОСРОЧКИ (файл 04, колонка J)","ок")))))))))))))
A12: 8 | G12: =IF(OR(B12="",NOT(ISNUMBER(D12))),"",D12-SUMIF(Оплаты!$D$6:$D$505,B12,Оплаты!$B$6:$B$505)) | H12: =IF(AND(B12="",C12="",D12="",E12="",F12=""),"",IF(B12="","БЛОК: нужен идентификатор акта — по нему распределяются оплаты",IF(COUNTIF($B$5:$B$16,B12)>1,"БЛОК: идентификатор акта повторяется — оплату нельзя отнести однозначно",IF(OR(NOT(ISNUMBER(D12)),D12<=0),"БЛОК: нужен бесспорный долг на первый день просрочки, больше нуля (файл 04, лист «Долг по актам», колонка J)",IF(NOT(ISNUMBER(E12)),"БЛОК: нужен первый день просрочки по этому акту",IF(NOT(ISNUMBER(Ввод!$B$4)),"БЛОК: на листе «Ввод» не введён последний день расчёта",IF(E12>Ввод!$B$4,"БЛОК: первый день просрочки позже последнего дня расчёта",IF(Ввод!$B$4-E12+1>3999,"БЛОК: от первого дня просрочки до последнего дня расчёта более 3999 дней — разбейте расчёт на части",IF(COUNT(Ввод!$A$12:$A$71)=0,"БЛОК: на листе «Ввод» не введена ставка",IF(MIN(Ввод!$D$12:$D$71)>E12,"БЛОК: нет ставки, действовавшей в первый день просрочки по этому акту",IF(N(G12)<0,"БЛОК: оплаты по этому акту больше долга на первый день просрочки",IF(NOT(ISNUMBER(F12)),"БЛОК: нужна сверочная сумма по этому акту из файла 04 (лист «Долг по актам», колонка M — текущий бесспорный остаток)",IF(ROUND(N(G12)-F12,2)<>0,"БЛОК: сверка не сходится. Долг на первый день просрочки минус оплаты по этому акту = "&FIXED(N(G12),2)&" руб., а по файлу 04 = "&FIXED(F12,2)&" руб. Похоже, в колонку D внесён текущий остаток, из которого оплаты уже вычтены: тогда те же оплаты учтутся дважды. В колонке D нужен бесспорный долг НА ПЕРВЫЙ ДЕНЬ ПРОСРОЧКИ (файл 04, колонка J)","ок")))))))))))))
A13: 9 | G13: =IF(OR(B13="",NOT(ISNUMBER(D13))),"",D13-SUMIF(Оплаты!$D$6:$D$505,B13,Оплаты!$B$6:$B$505)) | H13: =IF(AND(B13="",C13="",D13="",E13="",F13=""),"",IF(B13="","БЛОК: нужен идентификатор акта — по нему распределяются оплаты",IF(COUNTIF($B$5:$B$16,B13)>1,"БЛОК: идентификатор акта повторяется — оплату нельзя отнести однозначно",IF(OR(NOT(ISNUMBER(D13)),D13<=0),"БЛОК: нужен бесспорный долг на первый день просрочки, больше нуля (файл 04, лист «Долг по актам», колонка J)",IF(NOT(ISNUMBER(E13)),"БЛОК: нужен первый день просрочки по этому акту",IF(NOT(ISNUMBER(Ввод!$B$4)),"БЛОК: на листе «Ввод» не введён последний день расчёта",IF(E13>Ввод!$B$4,"БЛОК: первый день просрочки позже последнего дня расчёта",IF(Ввод!$B$4-E13+1>3999,"БЛОК: от первого дня просрочки до последнего дня расчёта более 3999 дней — разбейте расчёт на части",IF(COUNT(Ввод!$A$12:$A$71)=0,"БЛОК: на листе «Ввод» не введена ставка",IF(MIN(Ввод!$D$12:$D$71)>E13,"БЛОК: нет ставки, действовавшей в первый день просрочки по этому акту",IF(N(G13)<0,"БЛОК: оплаты по этому акту больше долга на первый день просрочки",IF(NOT(ISNUMBER(F13)),"БЛОК: нужна сверочная сумма по этому акту из файла 04 (лист «Долг по актам», колонка M — текущий бесспорный остаток)",IF(ROUND(N(G13)-F13,2)<>0,"БЛОК: сверка не сходится. Долг на первый день просрочки минус оплаты по этому акту = "&FIXED(N(G13),2)&" руб., а по файлу 04 = "&FIXED(F13,2)&" руб. Похоже, в колонку D внесён текущий остаток, из которого оплаты уже вычтены: тогда те же оплаты учтутся дважды. В колонке D нужен бесспорный долг НА ПЕРВЫЙ ДЕНЬ ПРОСРОЧКИ (файл 04, колонка J)","ок")))))))))))))
A14: 10 | G14: =IF(OR(B14="",NOT(ISNUMBER(D14))),"",D14-SUMIF(Оплаты!$D$6:$D$505,B14,Оплаты!$B$6:$B$505)) | H14: =IF(AND(B14="",C14="",D14="",E14="",F14=""),"",IF(B14="","БЛОК: нужен идентификатор акта — по нему распределяются оплаты",IF(COUNTIF($B$5:$B$16,B14)>1,"БЛОК: идентификатор акта повторяется — оплату нельзя отнести однозначно",IF(OR(NOT(ISNUMBER(D14)),D14<=0),"БЛОК: нужен бесспорный долг на первый день просрочки, больше нуля (файл 04, лист «Долг по актам», колонка J)",IF(NOT(ISNUMBER(E14)),"БЛОК: нужен первый день просрочки по этому акту",IF(NOT(ISNUMBER(Ввод!$B$4)),"БЛОК: на листе «Ввод» не введён последний день расчёта",IF(E14>Ввод!$B$4,"БЛОК: первый день просрочки позже последнего дня расчёта",IF(Ввод!$B$4-E14+1>3999,"БЛОК: от первого дня просрочки до последнего дня расчёта более 3999 дней — разбейте расчёт на части",IF(COUNT(Ввод!$A$12:$A$71)=0,"БЛОК: на листе «Ввод» не введена ставка",IF(MIN(Ввод!$D$12:$D$71)>E14,"БЛОК: нет ставки, действовавшей в первый день просрочки по этому акту",IF(N(G14)<0,"БЛОК: оплаты по этому акту больше долга на первый день просрочки",IF(NOT(ISNUMBER(F14)),"БЛОК: нужна сверочная сумма по этому акту из файла 04 (лист «Долг по актам», колонка M — текущий бесспорный остаток)",IF(ROUND(N(G14)-F14,2)<>0,"БЛОК: сверка не сходится. Долг на первый день просрочки минус оплаты по этому акту = "&FIXED(N(G14),2)&" руб., а по файлу 04 = "&FIXED(F14,2)&" руб. Похоже, в колонку D внесён текущий остаток, из которого оплаты уже вычтены: тогда те же оплаты учтутся дважды. В колонке D нужен бесспорный долг НА ПЕРВЫЙ ДЕНЬ ПРОСРОЧКИ (файл 04, колонка J)","ок")))))))))))))
A15: 11 | G15: =IF(OR(B15="",NOT(ISNUMBER(D15))),"",D15-SUMIF(Оплаты!$D$6:$D$505,B15,Оплаты!$B$6:$B$505)) | H15: =IF(AND(B15="",C15="",D15="",E15="",F15=""),"",IF(B15="","БЛОК: нужен идентификатор акта — по нему распределяются оплаты",IF(COUNTIF($B$5:$B$16,B15)>1,"БЛОК: идентификатор акта повторяется — оплату нельзя отнести однозначно",IF(OR(NOT(ISNUMBER(D15)),D15<=0),"БЛОК: нужен бесспорный долг на первый день просрочки, больше нуля (файл 04, лист «Долг по актам», колонка J)",IF(NOT(ISNUMBER(E15)),"БЛОК: нужен первый день просрочки по этому акту",IF(NOT(ISNUMBER(Ввод!$B$4)),"БЛОК: на листе «Ввод» не введён последний день расчёта",IF(E15>Ввод!$B$4,"БЛОК: первый день просрочки позже последнего дня расчёта",IF(Ввод!$B$4-E15+1>3999,"БЛОК: от первого дня просрочки до последнего дня расчёта более 3999 дней — разбейте расчёт на части",IF(COUNT(Ввод!$A$12:$A$71)=0,"БЛОК: на листе «Ввод» не введена ставка",IF(MIN(Ввод!$D$12:$D$71)>E15,"БЛОК: нет ставки, действовавшей в первый день просрочки по этому акту",IF(N(G15)<0,"БЛОК: оплаты по этому акту больше долга на первый день просрочки",IF(NOT(ISNUMBER(F15)),"БЛОК: нужна сверочная сумма по этому акту из файла 04 (лист «Долг по актам», колонка M — текущий бесспорный остаток)",IF(ROUND(N(G15)-F15,2)<>0,"БЛОК: сверка не сходится. Долг на первый день просрочки минус оплаты по этому акту = "&FIXED(N(G15),2)&" руб., а по файлу 04 = "&FIXED(F15,2)&" руб. Похоже, в колонку D внесён текущий остаток, из которого оплаты уже вычтены: тогда те же оплаты учтутся дважды. В колонке D нужен бесспорный долг НА ПЕРВЫЙ ДЕНЬ ПРОСРОЧКИ (файл 04, колонка J)","ок")))))))))))))
A16: 12 | G16: =IF(OR(B16="",NOT(ISNUMBER(D16))),"",D16-SUMIF(Оплаты!$D$6:$D$505,B16,Оплаты!$B$6:$B$505)) | H16: =IF(AND(B16="",C16="",D16="",E16="",F16=""),"",IF(B16="","БЛОК: нужен идентификатор акта — по нему распределяются оплаты",IF(COUNTIF($B$5:$B$16,B16)>1,"БЛОК: идентификатор акта повторяется — оплату нельзя отнести однозначно",IF(OR(NOT(ISNUMBER(D16)),D16<=0),"БЛОК: нужен бесспорный долг на первый день просрочки, больше нуля (файл 04, лист «Долг по актам», колонка J)",IF(NOT(ISNUMBER(E16)),"БЛОК: нужен первый день просрочки по этому акту",IF(NOT(ISNUMBER(Ввод!$B$4)),"БЛОК: на листе «Ввод» не введён последний день расчёта",IF(E16>Ввод!$B$4,"БЛОК: первый день просрочки позже последнего дня расчёта",IF(Ввод!$B$4-E16+1>3999,"БЛОК: от первого дня просрочки до последнего дня расчёта более 3999 дней — разбейте расчёт на части",IF(COUNT(Ввод!$A$12:$A$71)=0,"БЛОК: на листе «Ввод» не введена ставка",IF(MIN(Ввод!$D$12:$D$71)>E16,"БЛОК: нет ставки, действовавшей в первый день просрочки по этому акту",IF(N(G16)<0,"БЛОК: оплаты по этому акту больше долга на первый день просрочки",IF(NOT(ISNUMBER(F16)),"БЛОК: нужна сверочная сумма по этому акту из файла 04 (лист «Долг по актам», колонка M — текущий бесспорный остаток)",IF(ROUND(N(G16)-F16,2)<>0,"БЛОК: сверка не сходится. Долг на первый день просрочки минус оплаты по этому акту = "&FIXED(N(G16),2)&" руб., а по файлу 04 = "&FIXED(F16,2)&" руб. Похоже, в колонку D внесён текущий остаток, из которого оплаты уже вычтены: тогда те же оплаты учтутся дважды. В колонке D нужен бесспорный долг НА ПЕРВЫЙ ДЕНЬ ПРОСРОЧКИ (файл 04, колонка J)","ок")))))))))))))

Sheet Ввод
A1: Исходные данные
A4: Последний день расчёта (включительно) | C4: Дата претензии или иска. Общая для всех актов.
A5: Бесспорная часть долга по файлу 04, руб. (обязательно) | C5: Файл 04, лист «Взаиморасчёты», строка «БЕССПОРНАЯ ЧАСТЬ» (ячейка M12). Не общий долг и не спорная часть. Без этой суммы расчёт заблокирован.
A6: Из неё не входит в этот расчёт, руб. (если есть) | C6: Текущий бесспорный остаток актов файла 04, которых нет на листе «Акты»: срок оплаты ещё не истёк или акт оспорен заказчиком (граница B4). Таких актов нет — оставьте пустым.
A7: Суммы долга и даты начала просрочки — на листе «Акты»: у каждого акта они свои.
A8: Ставка — в процентах годовых: 21 означает 21 %. Не вводите долю (0,21).
F10: Периоды без начисления (если применимо)
A11: Ставка действует с | B11: Ставка, % годовых | C11: Проверка | D11: служ. | F11: С | G11: По (включительно) | H11: Проверка
C12: =IF(AND(A12="",B12=""),"",IF(OR(A12="",B12=""),"БЛОК: нужны и дата, и ставка",IF(OR(B12<=0,B12>100),"БЛОК: ставка вне 0–100",IF(B12<1,"БЛОК: похоже на долю — введите проценты","ок")))) | D12: =IF(A12="",2958465,A12) -> 2958465 | H12: =IF(AND(F12="",G12=""),"",IF(OR(F12="",G12=""),"БЛОК: нужны обе даты",IF(G12<F12,"БЛОК: конец раньше начала","ок")))
C13: =IF(AND(A13="",B13=""),"",IF(OR(A13="",B13=""),"БЛОК: нужны и дата, и ставка",IF(OR(B13<=0,B13>100),"БЛОК: ставка вне 0–100",IF(B13<1,"БЛОК: похоже на долю — введите проценты",IF(OR(A12="",A13<=A12),"БЛОК: даты по возрастанию, без пустых строк","ок"))))) | D13: =IF(A13="",2958465,A13) -> 2958465 | H13: =IF(AND(F13="",G13=""),"",IF(OR(F13="",G13=""),"БЛОК: нужны обе даты",IF(G13<F13,"БЛОК: конец раньше начала","ок")))
C14: =IF(AND(A14="",B14=""),"",IF(OR(A14="",B14=""),"БЛОК: нужны и дата, и ставка",IF(OR(B14<=0,B14>100),"БЛОК: ставка вне 0–100",IF(B14<1,"БЛОК: похоже на долю — введите проценты",IF(OR(A13="",A14<=A13),"БЛОК: даты по возрастанию, без пустых строк","ок"))))) | D14: =IF(A14="",2958465,A14) -> 2958465 | H14: =IF(AND(F14="",G14=""),"",IF(OR(F14="",G14=""),"БЛОК: нужны обе даты",IF(G14<F14,"БЛОК: конец раньше начала","ок")))
C15: =IF(AND(A15="",B15=""),"",IF(OR(A15="",B15=""),"БЛОК: нужны и дата, и ставка",IF(OR(B15<=0,B15>100),"БЛОК: ставка вне 0–100",IF(B15<1,"БЛОК: похоже на долю — введите проценты",IF(OR(A14="",A15<=A14),"БЛОК: даты по возрастанию, без пустых строк","ок"))))) | D15: =IF(A15="",2958465,A15) -> 2958465 | H15: =IF(AND(F15="",G15=""),"",IF(OR(F15="",G15=""),"БЛОК: нужны обе даты",IF(G15<F15,"БЛОК: конец раньше начала","ок")))
C16: =IF(AND(A16="",B16=""),"",IF(OR(A16="",B16=""),"БЛОК: нужны и дата, и ставка",IF(OR(B16<=0,B16>100),"БЛОК: ставка вне 0–100",IF(B16<1,"БЛОК: похоже на долю — введите проценты",IF(OR(A15="",A16<=A15),"БЛОК: даты по возрастанию, без пустых строк","ок"))))) | D16: =IF(A16="",2958465,A16) -> 2958465 | H16: =IF(AND(F16="",G16=""),"",IF(OR(F16="",G16=""),"БЛОК: нужны обе даты",IF(G16<F16,"БЛОК: конец раньше начала","ок")))
C17: =IF(AND(A17="",B17=""),"",IF(OR(A17="",B17=""),"БЛОК: нужны и дата, и ставка",IF(OR(B17<=0,B17>100),"БЛОК: ставка вне 0–100",IF(B17<1,"БЛОК: похоже на долю — введите проценты",IF(OR(A16="",A17<=A16),"БЛОК: даты по возрастанию, без пустых строк","ок"))))) | D17: =IF(A17="",2958465,A17) -> 2958465 | H17: =IF(AND(F17="",G17=""),"",IF(OR(F17="",G17=""),"БЛОК: нужны обе даты",IF(G17<F17,"БЛОК: конец раньше начала","ок")))
C18: =IF(AND(A18="",B18=""),"",IF(OR(A18="",B18=""),"БЛОК: нужны и дата, и ставка",IF(OR(B18<=0,B18>100),"БЛОК: ставка вне 0–100",IF(B18<1,"БЛОК: похоже на долю — введите проценты",IF(OR(A17="",A18<=A17),"БЛОК: даты по возрастанию, без пустых строк","ок"))))) | D18: =IF(A18="",2958465,A18) -> 2958465 | H18: =IF(AND(F18="",G18=""),"",IF(OR(F18="",G18=""),"БЛОК: нужны обе даты",IF(G18<F18,"БЛОК: конец раньше начала","ок")))
C19: =IF(AND(A19="",B19=""),"",IF(OR(A19="",B19=""),"БЛОК: нужны и дата, и ставка",IF(OR(B19<=0,B19>100),"БЛОК: ставка вне 0–100",IF(B19<1,"БЛОК: похоже на долю — введите проценты",IF(OR(A18="",A19<=A18),"БЛОК: даты по возрастанию, без пустых строк","ок"))))) | D19: =IF(A19="",2958465,A19) -> 2958465 | H19: =IF(AND(F19="",G19=""),"",IF(OR(F19="",G19=""),"БЛОК: нужны обе даты",IF(G19<F19,"БЛОК: конец раньше начала","ок")))
C20: =IF(AND(A20="",B20=""),"",IF(OR(A20="",B20=""),"БЛОК: нужны и дата, и ставка",IF(OR(B20<=0,B20>100),"БЛОК: ставка вне 0–100",IF(B20<1,"БЛОК: похоже на долю — введите проценты",IF(OR(A19="",A20<=A19),"БЛОК: даты по возрастанию, без пустых строк","ок"))))) | D20: =IF(A20="",2958465,A20) -> 2958465 | H20: =IF(AND(F20="",G20=""),"",IF(OR(F20="",G20=""),"БЛОК: нужны обе даты",IF(G20<F20,"БЛОК: конец раньше начала","ок")))
C21: =IF(AND(A21="",B21=""),"",IF(OR(A21="",B21=""),"БЛОК: нужны и дата, и ставка",IF(OR(B21<=0,B21>100),"БЛОК: ставка вне 0–100",IF(B21<1,"БЛОК: похоже на долю — введите проценты",IF(OR(A20="",A21<=A20),"БЛОК: даты по возрастанию, без пустых строк","ок"))))) | D21: =IF(A21="",2958465,A21) -> 2958465 | H21: =IF(AND(F21="",G21=""),"",IF(OR(F21="",G21=""),"БЛОК: нужны обе даты",IF(G21<F21,"БЛОК: конец раньше начала","ок")))
C22: =IF(AND(A22="",B22=""),"",IF(OR(A22="",B22=""),"БЛОК: нужны и дата, и ставка",IF(OR(B22<=0,B22>100),"БЛОК: ставка вне 0–100",IF(B22<1,"БЛОК: похоже на долю — введите проценты",IF(OR(A21="",A22<=A21),"БЛОК: даты по возрастанию, без пустых строк","ок"))))) | D22: =IF(A22="",2958465,A22) -> 2958465 | H22: =IF(AND(F22="",G22=""),"",IF(OR(F22="",G22=""),"БЛОК: нужны обе даты",IF(G22<F22,"БЛОК: конец раньше начала","ок")))
C23: =IF(AND(A23="",B23=""),"",IF(OR(A23="",B23=""),"БЛОК: нужны и дата, и ставка",IF(OR(B23<=0,B23>100),"БЛОК: ставка вне 0–100",IF(B23<1,"БЛОК: похоже на долю — введите проценты",IF(OR(A22="",A23<=A22),"БЛОК: даты по возрастанию, без пустых строк","ок"))))) | D23: =IF(A23="",2958465,A23) -> 2958465 | H23: =IF(AND(F23="",G23=""),"",IF(OR(F23="",G23=""),"БЛОК: нужны обе даты",IF(G23<F23,"БЛОК: конец раньше начала","ок")))
C24: =IF(AND(A24="",B24=""),"",IF(OR(A24="",B24=""),"БЛОК: нужны и дата, и ставка",IF(OR(B24<=0,B24>100),"БЛОК: ставка вне 0–100",IF(B24<1,"БЛОК: похоже на долю — введите проценты",IF(OR(A23="",A24<=A23),"БЛОК: даты по возрастанию, без пустых строк","ок"))))) | D24: =IF(A24="",2958465,A24) -> 2958465 | H24: =IF(AND(F24="",G24=""),"",IF(OR(F24="",G24=""),"БЛОК: нужны обе даты",IF(G24<F24,"БЛОК: конец раньше начала","ок")))
... C31: =IF(AND(A31="",B31=""),"",IF(OR(A31="",B31=""),"БЛОК: нужны и дата, и ставка",IF(OR(B31<=0,B31>100),"БЛОК: ставка вне 0–100",IF(B31<1,"БЛОК: похоже на долю — введите проценты",IF(OR(A30="",A31<=A30),"БЛОК: даты по возрастанию, без пустых строк","ок"))))) | D31: =IF(A31="",2958465,A31) -> 2958465 | H31: =IF(AND(F31="",G31=""),"",IF(OR(F31="",G31=""),"БЛОК: нужны обе даты",IF(G31<F31,"БЛОК: конец раньше начала","ок")))
C32: =IF(AND(A32="",B32=""),"",IF(OR(A32="",B32=""),"БЛОК: нужны и дата, и ставка",IF(OR(B32<=0,B32>100),"БЛОК: ставка вне 0–100",IF(B32<1,"БЛОК: похоже на долю — введите проценты",IF(OR(A31="",A32<=A31),"БЛОК: даты по возрастанию, без пустых строк","ок"))))) | D32: =IF(A32="",2958465,A32) -> 2958465
C33: =IF(AND(A33="",B33=""),"",IF(OR(A33="",B33=""),"БЛОК: нужны и дата, и ставка",IF(OR(B33<=0,B33>100),"БЛОК: ставка вне 0–100",IF(B33<1,"БЛОК: похоже на долю — введите проценты",IF(OR(A32="",A33<=A32),"БЛОК: даты по возрастанию, без пустых строк","ок"))))) | D33: =IF(A33="",2958465,A33) -> 2958465
C34: =IF(AND(A34="",B34=""),"",IF(OR(A34="",B34=""),"БЛОК: нужны и дата, и ставка",IF(OR(B34<=0,B34>100),"БЛОК: ставка вне 0–100",IF(B34<1,"БЛОК: похоже на долю — введите проценты",IF(OR(A33="",A34<=A33),"БЛОК: даты по возрастанию, без пустых строк","ок"))))) | D34: =IF(A34="",2958465,A34) -> 2958465
C35: =IF(AND(A35="",B35=""),"",IF(OR(A35="",B35=""),"БЛОК: нужны и дата, и ставка",IF(OR(B35<=0,B35>100),"БЛОК: ставка вне 0–100",IF(B35<1,"БЛОК: похоже на долю — введите проценты",IF(OR(A34="",A35<=A34),"БЛОК: даты по возрастанию, без пустых строк","ок"))))) | D35: =IF(A35="",2958465,A35) -> 2958465
C36: =IF(AND(A36="",B36=""),"",IF(OR(A36="",B36=""),"БЛОК: нужны и дата, и ставка",IF(OR(B36<=0,B36>100),"БЛОК: ставка вне 0–100",IF(B36<1,"БЛОК: похоже на долю — введите проценты",IF(OR(A35="",A36<=A35),"БЛОК: даты по возрастанию, без пустых строк","ок"))))) | D36: =IF(A36="",2958465,A36) -> 2958465
C37: =IF(AND(A37="",B37=""),"",IF(OR(A37="",B37=""),"БЛОК: нужны и дата, и ставка",IF(OR(B37<=0,B37>100),"БЛОК: ставка вне 0–100",IF(B37<1,"БЛОК: похоже на долю — введите проценты",IF(OR(A36="",A37<=A36),"БЛОК: даты по возрастанию, без пустых строк","ок"))))) | D37: =IF(A37="",2958465,A37) -> 2958465
C38: =IF(AND(A38="",B38=""),"",IF(OR(A38="",B38=""),"БЛОК: нужны и дата, и ставка",IF(OR(B38<=0,B38>100),"БЛОК: ставка вне 0–100",IF(B38<1,"БЛОК: похоже на долю — введите проценты",IF(OR(A37="",A38<=A37),"БЛОК: даты по возрастанию, без пустых строк","ок"))))) | D38: =IF(A38="",2958465,A38) -> 2958465
C39: =IF(AND(A39="",B39=""),"",IF(OR(A39="",B39=""),"БЛОК: нужны и дата, и ставка",IF(OR(B39<=0,B39>100),"БЛОК: ставка вне 0–100",IF(B39<1,"БЛОК: похоже на долю — введите проценты",IF(OR(A38="",A39<=A38),"БЛОК: даты по возрастанию, без пустых строк","ок"))))) | D39: =IF(A39="",2958465,A39) -> 2958465
C40: =IF(AND(A40="",B40=""),"",IF(OR(A40="",B40=""),"БЛОК: нужны и дата, и ставка",IF(OR(B40<=0,B40>100),"БЛОК: ставка вне 0–100",IF(B40<1,"БЛОК: похоже на долю — введите проценты",IF(OR(A39="",A40<=A39),"БЛОК: даты по возрастанию, без пустых строк","ок"))))) | D40: =IF(A40="",2958465,A40) -> 2958465
C41: =IF(AND(A41="",B41=""),"",IF(OR(A41="",B41=""),"БЛОК: нужны и дата, и ставка",IF(OR(B41<=0,B41>100),"БЛОК: ставка вне 0–100",IF(B41<1,"БЛОК: похоже на долю — введите проценты",IF(OR(A40="",A41<=A40),"БЛОК: даты по возрастанию, без пустых строк","ок"))))) | D41: =IF(A41="",2958465,A41) -> 2958465
C42: =IF(AND(A42="",B42=""),"",IF(OR(A42="",B42=""),"БЛОК: нужны и дата, и ставка",IF(OR(B42<=0,B42>100),"БЛОК: ставка вне 0–100",IF(B42<1,"БЛОК: похоже на долю — введите проценты",IF(OR(A41="",A42<=A41),"БЛОК: даты по возрастанию, без пустых строк","ок"))))) | D42: =IF(A42="",2958465,A42) -> 2958465
C43: =IF(AND(A43="",B43=""),"",IF(OR(A43="",B43=""),"БЛОК: нужны и дата, и ставка",IF(OR(B43<=0,B43>100),"БЛОК: ставка вне 0–100",IF(B43<1,"БЛОК: похоже на долю — введите проценты",IF(OR(A42="",A43<=A42),"БЛОК: даты по возрастанию, без пустых строк","ок"))))) | D43: =IF(A43="",2958465,A43) -> 2958465
... C71: =IF(AND(A71="",B71=""),"",IF(OR(A71="",B71=""),"БЛОК: нужны и дата, и ставка",IF(OR(B71<=0,B71>100),"БЛОК: ставка вне 0–100",IF(B71<1,"БЛОК: похоже на долю — введите проценты",IF(OR(A70="",A71<=A70),"БЛОК: даты по возрастанию, без пустых строк","ок"))))) | D71: =IF(A71="",2958465,A71) -> 2958465

Sheet Оплаты
A1: Оплаты, поступившие в первый день просрочки или позже
A2: Оплата, поступившая в день D, уменьшает долг по своему акту со следующего дня. Каждая оплата относится к одному акту с листа «Акты»: платёж без акта блокирует расчёт — распределите его документально. Оплаты, поступившие до первого дня просрочки по акту, сюда не вносятся: они уже вычтены в долге на первый день просрочки (файл 04, лист «Долг по актам»). Порядок строк любой. Вместимость — 500 оплат; строка ниже таблицы блокирует итог.
A3: Сумма оплат | B3: =SUM(B6:B505) -> 0
A5: Дата оплаты | B5: Сумма, руб. | C5: Документ (п/п №, дата) | D5: Акт (идентификатор, как на листе «Акты») | E5: Проверка
E6: =IF(AND(A6="",B6="",C6="",D6=""),"",IF(OR(A6="",B6=""),"БЛОК: нужны и дата, и сумма",IF(B6<=0,"БЛОК: сумма должна быть больше нуля",IF(D6="","БЛОК: не указан акт — платёж не отнесён к конкретному акту. Требуется распределить платёж документально (назначение платежа, соглашение, письмо) и указать акт: система не назначает очередность зачёта за вас",IF(COUNTIF(Акты!$B$5:$B$16,D6)=0,"БЛОК: такого акта нет на листе «Акты» — добавьте акт или исправьте идентификатор",IF(NOT(ISNUMBER(INDEX(Акты!$E$5:$E$16,MATCH(D6,Акты!$B$5:$B$16,0)))),"БЛОК: у этого акта на листе «Акты» не указан первый день просрочки",IF(A6<INDEX(Акты!$E$5:$E$16,MATCH(D6,Акты!$B$5:$B$16,0)),"БЛОК: оплата раньше первого дня просрочки по этому акту — она должна быть уже вычтена в долге на первый день просрочки (файл 04), а не внесена сюда",IF(A6>Ввод!$B$4,"БЛОК: оплата после последнего дня расчёта — продлите расчёт или уберите строку","ок"))))))))
E7: =IF(AND(A7="",B7="",C7="",D7=""),"",IF(OR(A7="",B7=""),"БЛОК: нужны и дата, и сумма",IF(B7<=0,"БЛОК: сумма должна быть больше нуля",IF(D7="","БЛОК: не указан акт — платёж не отнесён к конкретному акту. Требуется распределить платёж документально (назначение платежа, соглашение, письмо) и указать акт: система не назначает очередность зачёта за вас",IF(COUNTIF(Акты!$B$5:$B$16,D7)=0,"БЛОК: такого акта нет на листе «Акты» — добавьте акт или исправьте идентификатор",IF(NOT(ISNUMBER(INDEX(Акты!$E$5:$E$16,MATCH(D7,Акты!$B$5:$B$16,0)))),"БЛОК: у этого акта на листе «Акты» не указан первый день просрочки",IF(A7<INDEX(Акты!$E$5:$E$16,MATCH(D7,Акты!$B$5:$B$16,0)),"БЛОК: оплата раньше первого дня просрочки по этому акту — она должна быть уже вычтена в долге на первый день просрочки (файл 04), а не внесена сюда",IF(A7>Ввод!$B$4,"БЛОК: оплата после последнего дня расчёта — продлите расчёт или уберите строку","ок"))))))))
E8: =IF(AND(A8="",B8="",C8="",D8=""),"",IF(OR(A8="",B8=""),"БЛОК: нужны и дата, и сумма",IF(B8<=0,"БЛОК: сумма должна быть больше нуля",IF(D8="","БЛОК: не указан акт — платёж не отнесён к конкретному акту. Требуется распределить платёж документально (назначение платежа, соглашение, письмо) и указать акт: система не назначает очередность зачёта за вас",IF(COUNTIF(Акты!$B$5:$B$16,D8)=0,"БЛОК: такого акта нет на листе «Акты» — добавьте акт или исправьте идентификатор",IF(NOT(ISNUMBER(INDEX(Акты!$E$5:$E$16,MATCH(D8,Акты!$B$5:$B$16,0)))),"БЛОК: у этого акта на листе «Акты» не указан первый день просрочки",IF(A8<INDEX(Акты!$E$5:$E$16,MATCH(D8,Акты!$B$5:$B$16,0)),"БЛОК: оплата раньше первого дня просрочки по этому акту — она должна быть уже вычтена в долге на первый день просрочки (файл 04), а не внесена сюда",IF(A8>Ввод!$B$4,"БЛОК: оплата после последнего дня расчёта — продлите расчёт или уберите строку","ок"))))))))
E9: =IF(AND(A9="",B9="",C9="",D9=""),"",IF(OR(A9="",B9=""),"БЛОК: нужны и дата, и сумма",IF(B9<=0,"БЛОК: сумма должна быть больше нуля",IF(D9="","БЛОК: не указан акт — платёж не отнесён к конкретному акту. Требуется распределить платёж документально (назначение платежа, соглашение, письмо) и указать акт: система не назначает очередность зачёта за вас",IF(COUNTIF(Акты!$B$5:$B$16,D9)=0,"БЛОК: такого акта нет на листе «Акты» — добавьте акт или исправьте идентификатор",IF(NOT(ISNUMBER(INDEX(Акты!$E$5:$E$16,MATCH(D9,Акты!$B$5:$B$16,0)))),"БЛОК: у этого акта на листе «Акты» не указан первый день просрочки",IF(A9<INDEX(Акты!$E$5:$E$16,MATCH(D9,Акты!$B$5:$B$16,0)),"БЛОК: оплата раньше первого дня просрочки по этому акту — она должна быть уже вычтена в долге на первый день просрочки (файл 04), а не внесена сюда",IF(A9>Ввод!$B$4,"БЛОК: оплата после последнего дня расчёта — продлите расчёт или уберите строку","ок"))))))))
E10: =IF(AND(A10="",B10="",C10="",D10=""),"",IF(OR(A10="",B10=""),"БЛОК: нужны и дата, и сумма",IF(B10<=0,"БЛОК: сумма должна быть больше нуля",IF(D10="","БЛОК: не указан акт — платёж не отнесён к конкретному акту. Требуется распределить платёж документально (назначение платежа, соглашение, письмо) и указать акт: система не назначает очередность зачёта за вас",IF(COUNTIF(Акты!$B$5:$B$16,D10)=0,"БЛОК: такого акта нет на листе «Акты» — добавьте акт или исправьте идентификатор",IF(NOT(ISNUMBER(INDEX(Акты!$E$5:$E$16,MATCH(D10,Акты!$B$5:$B$16,0)))),"БЛОК: у этого акта на листе «Акты» не указан первый день просрочки",IF(A10<INDEX(Акты!$E$5:$E$16,MATCH(D10,Акты!$B$5:$B$16,0)),"БЛОК: оплата раньше первого дня просрочки по этому акту — она должна быть уже вычтена в долге на первый день просрочки (файл 04), а не внесена сюда",IF(A10>Ввод!$B$4,"БЛОК: оплата после последнего дня расчёта — продлите расчёт или уберите строку","ок"))))))))
E11: =IF(AND(A11="",B11="",C11="",D11=""),"",IF(OR(A11="",B11=""),"БЛОК: нужны и дата, и сумма",IF(B11<=0,"БЛОК: сумма должна быть больше нуля",IF(D11="","БЛОК: не указан акт — платёж не отнесён к конкретному акту. Требуется распределить платёж документально (назначение платежа, соглашение, письмо) и указать акт: система не назначает очередность зачёта за вас",IF(COUNTIF(Акты!$B$5:$B$16,D11)=0,"БЛОК: такого акта нет на листе «Акты» — добавьте акт или исправьте идентификатор",IF(NOT(ISNUMBER(INDEX(Акты!$E$5:$E$16,MATCH(D11,Акты!$B$5:$B$16,0)))),"БЛОК: у этого акта на листе «Акты» не указан первый день просрочки",IF(A11<INDEX(Акты!$E$5:$E$16,MATCH(D11,Акты!$B$5:$B$16,0)),"БЛОК: оплата раньше первого дня просрочки по этому акту — она должна быть уже вычтена в долге на первый день просрочки (файл 04), а не внесена сюда",IF(A11>Ввод!$B$4,"БЛОК: оплата после последнего дня расчёта — продлите расчёт или уберите строку","ок"))))))))
E12: =IF(AND(A12="",B12="",C12="",D12=""),"",IF(OR(A12="",B12=""),"БЛОК: нужны и дата, и сумма",IF(B12<=0,"БЛОК: сумма должна быть больше нуля",IF(D12="","БЛОК: не указан акт — платёж не отнесён к конкретному акту. Требуется распределить платёж документально (назначение платежа, соглашение, письмо) и указать акт: система не назначает очередность зачёта за вас",IF(COUNTIF(Акты!$B$5:$B$16,D12)=0,"БЛОК: такого акта нет на листе «Акты» — добавьте акт или исправьте идентификатор",IF(NOT(ISNUMBER(INDEX(Акты!$E$5:$E$16,MATCH(D12,Акты!$B$5:$B$16,0)))),"БЛОК: у этого акта на листе «Акты» не указан первый день просрочки",IF(A12<INDEX(Акты!$E$5:$E$16,MATCH(D12,Акты!$B$5:$B$16,0)),"БЛОК: оплата раньше первого дня просрочки по этому акту — она должна быть уже вычтена в долге на первый день просрочки (файл 04), а не внесена сюда",IF(A12>Ввод!$B$4,"БЛОК: оплата после последнего дня расчёта — продлите расчёт или уберите строку","ок"))))))))
E13: =IF(AND(A13="",B13="",C13="",D13=""),"",IF(OR(A13="",B13=""),"БЛОК: нужны и дата, и сумма",IF(B13<=0,"БЛОК: сумма должна быть больше нуля",IF(D13="","БЛОК: не указан акт — платёж не отнесён к конкретному акту. Требуется распределить платёж документально (назначение платежа, соглашение, письмо) и указать акт: система не назначает очередность зачёта за вас",IF(COUNTIF(Акты!$B$5:$B$16,D13)=0,"БЛОК: такого акта нет на листе «Акты» — добавьте акт или исправьте идентификатор",IF(NOT(ISNUMBER(INDEX(Акты!$E$5:$E$16,MATCH(D13,Акты!$B$5:$B$16,0)))),"БЛОК: у этого акта на листе «Акты» не указан первый день просрочки",IF(A13<INDEX(Акты!$E$5:$E$16,MATCH(D13,Акты!$B$5:$B$16,0)),"БЛОК: оплата раньше первого дня просрочки по этому акту — она должна быть уже вычтена в долге на первый день просрочки (файл 04), а не внесена сюда",IF(A13>Ввод!$B$4,"БЛОК: оплата после последнего дня расчёта — продлите расчёт или уберите строку","ок"))))))))
E14: =IF(AND(A14="",B14="",C14="",D14=""),"",IF(OR(A14="",B14=""),"БЛОК: нужны и дата, и сумма",IF(B14<=0,"БЛОК: сумма должна быть больше нуля",IF(D14="","БЛОК: не указан акт — платёж не отнесён к конкретному акту. Требуется распределить платёж документально (назначение платежа, соглашение, письмо) и указать акт: система не назначает очередность зачёта за вас",IF(COUNTIF(Акты!$B$5:$B$16,D14)=0,"БЛОК: такого акта нет на листе «Акты» — добавьте акт или исправьте идентификатор",IF(NOT(ISNUMBER(INDEX(Акты!$E$5:$E$16,MATCH(D14,Акты!$B$5:$B$16,0)))),"БЛОК: у этого акта на листе «Акты» не указан первый день просрочки",IF(A14<INDEX(Акты!$E$5:$E$16,MATCH(D14,Акты!$B$5:$B$16,0)),"БЛОК: оплата раньше первого дня просрочки по этому акту — она должна быть уже вычтена в долге на первый день просрочки (файл 04), а не внесена сюда",IF(A14>Ввод!$B$4,"БЛОК: оплата после последнего дня расчёта — продлите расчёт или уберите строку","ок"))))))))
E15: =IF(AND(A15="",B15="",C15="",D15=""),"",IF(OR(A15="",B15=""),"БЛОК: нужны и дата, и сумма",IF(B15<=0,"БЛОК: сумма должна быть больше нуля",IF(D15="","БЛОК: не указан акт — платёж не отнесён к конкретному акту. Требуется распределить платёж документально (назначение платежа, соглашение, письмо) и указать акт: система не назначает очередность зачёта за вас",IF(COUNTIF(Акты!$B$5:$B$16,D15)=0,"БЛОК: такого акта нет на листе «Акты» — добавьте акт или исправьте идентификатор",IF(NOT(ISNUMBER(INDEX(Акты!$E$5:$E$16,MATCH(D15,Акты!$B$5:$B$16,0)))),"БЛОК: у этого акта на листе «Акты» не указан первый день просрочки",IF(A15<INDEX(Акты!$E$5:$E$16,MATCH(D15,Акты!$B$5:$B$16,0)),"БЛОК: оплата раньше первого дня просрочки по этому акту — она должна быть уже вычтена в долге на первый день просрочки (файл 04), а не внесена сюда",IF(A15>Ввод!$B$4,"БЛОК: оплата после последнего дня расчёта — продлите расчёт или уберите строку","ок"))))))))
E16: =IF(AND(A16="",B16="",C16="",D16=""),"",IF(OR(A16="",B16=""),"БЛОК: нужны и дата, и сумма",IF(B16<=0,"БЛОК: сумма должна быть больше нуля",IF(D16="","БЛОК: не указан акт — платёж не отнесён к конкретному акту. Требуется распределить платёж документально (назначение платежа, соглашение, письмо) и указать акт: система не назначает очередность зачёта за вас",IF(COUNTIF(Акты!$B$5:$B$16,D16)=0,"БЛОК: такого акта нет на листе «Акты» — добавьте акт или исправьте идентификатор",IF(NOT(ISNUMBER(INDEX(Акты!$E$5:$E$16,MATCH(D16,Акты!$B$5:$B$16,0)))),"БЛОК: у этого акта на листе «Акты» не указан первый день просрочки",IF(A16<INDEX(Акты!$E$5:$E$16,MATCH(D16,Акты!$B$5:$B$16,0)),"БЛОК: оплата раньше первого дня просрочки по этому акту — она должна быть уже вычтена в долге на первый день просрочки (файл 04), а не внесена сюда",IF(A16>Ввод!$B$4,"БЛОК: оплата после последнего дня расчёта — продлите расчёт или уберите строку","ок"))))))))
E17: =IF(AND(A17="",B17="",C17="",D17=""),"",IF(OR(A17="",B17=""),"БЛОК: нужны и дата, и сумма",IF(B17<=0,"БЛОК: сумма должна быть больше нуля",IF(D17="","БЛОК: не указан акт — платёж не отнесён к конкретному акту. Требуется распределить платёж документально (назначение платежа, соглашение, письмо) и указать акт: система не назначает очередность зачёта за вас",IF(COUNTIF(Акты!$B$5:$B$16,D17)=0,"БЛОК: такого акта нет на листе «Акты» — добавьте акт или исправьте идентификатор",IF(NOT(ISNUMBER(INDEX(Акты!$E$5:$E$16,MATCH(D17,Акты!$B$5:$B$16,0)))),"БЛОК: у этого акта на листе «Акты» не указан первый день просрочки",IF(A17<INDEX(Акты!$E$5:$E$16,MATCH(D17,Акты!$B$5:$B$16,0)),"БЛОК: оплата раньше первого дня просрочки по этому акту — она должна быть уже вычтена в долге на первый день просрочки (файл 04), а не внесена сюда",IF(A17>Ввод!$B$4,"БЛОК: оплата после последнего дня расчёта — продлите расчёт или уберите строку","ок"))))))))
... E505: =IF(AND(A505="",B505="",C505="",D505=""),"",IF(OR(A505="",B505=""),"БЛОК: нужны и дата, и сумма",IF(B505<=0,"БЛОК: сумма должна быть больше нуля",IF(D505="","БЛОК: не указан акт — платёж не отнесён к конкретному акту. Требуется распределить платёж документально (назначение платежа, соглашение, письмо) и указать акт: система не назначает очередность зачёта за вас",IF(COUNTIF(Акты!$B$5:$B$16,D505)=0,"БЛОК: такого акта нет на листе «Акты» — добавьте акт или исправьте идентификатор",IF(NOT(ISNUMBER(INDEX(Акты!$E$5:$E$16,MATCH(D505,Акты!$B$5:$B$16,0)))),"БЛОК: у этого акта на листе «Акты» не указан первый день просрочки",IF(A505<INDEX(Акты!$E$5:$E$16,MATCH(D505,Акты!$B$5:$B$16,0)),"БЛОК: оплата раньше первого дня просрочки по этому акту — она должна быть уже вычтена в долге на первый день просрочки (файл 04), а не внесена сюда",IF(A505>Ввод!$B$4,"БЛОК: оплата после последнего дня расчёта — продлите расчёт или уберите строку","ок"))))))))

Sheet Расчёт
A1: Расчёт процентов по ст. 395 ГК РФ
A2: Статус | D2: =Проверки!C20 -> ЗАБЛОКИРОВАН
A3: Проценты итого, руб. | D3: =IF(D2="ГОТОВ",SUM(P7:P18),"РАСЧЁТ НЕ ВЫПОЛНЕН — см. лист «Проверки»") -> РАСЧЁТ НЕ ВЫПОЛНЕН — см. лист «Проверки»
A4: Долг на последний день расчёта, руб. | D4: =IF(D2="ГОТОВ",SUM(Акты!G5:G16),"")
A5: Каждый акт считается отдельно. Строка — отрезок, на котором долг акта не меняется; её проценты — сумма по периодам ставки, каждый округлён до копейки. Итог по акту — сумма его строк, «Проценты итого» — сумма итогов по актам (свод справа). | M5: Свод по актам: итог — сумма строк
A6: № | B6: Акт | C6: С | D6: По | E6: Дней | F6: Долг акта, руб. | G6: Ставка, % | H6: Периодов ставки | I6: Проценты, руб. | J6: Оплата по акту в последний день, руб. | K6: служ. | L6: служ. | M6: Акт | N6: Первый день просрочки | O6: Бесспорный долг на первый день просрочки, руб. | P6: Проценты по акту, руб. | Q6: Остаток на последний день, руб.
A7: =IF(K7="","",1) | B7: =IF(K7="","",INDEX(Интервалы!$A$2:$A$513,MATCH(K7,Интервалы!$G$2:$G$513,0))) | C7: =IF(K7="","",INDEX(Интервалы!$C$2:$C$513,MATCH(K7,Интервалы!$G$2:$G$513,0))) | D7: =IF(K7="","",INDEX(Интервалы!$D$2:$D$513,MATCH(K7,Интервалы!$G$2:$G$513,0))) | E7: =IF(K7="","",D7-C7+1) | F7: =IF(K7="","",INDEX(Интервалы!$E$2:$E$513,MATCH(K7,Интервалы!$G$2:$G$513,0))) | G7: =IF(K7="","",IF(H7=1,INDEX('По дням'!$B$2:$B$4000,MATCH(C7,'По дням'!$A$2:$A$4000,0)),"по периодам ставки")) | H7: =IF(K7="","",INDEX(Интервалы!$I$2:$I$513,MATCH(K7,Интервалы!$G$2:$G$513,0))) | I7: =IF(K7="","",INDEX(Интервалы!$F$2:$F$513,MATCH(K7,Интервалы!$G$2:$G$513,0))) | J7: =IF(K7="","",INDEX(Интервалы!$H$2:$H$513,MATCH(K7,Интервалы!$G$2:$G$513,0))) | K7: =IFERROR(SMALL(Интервалы!$G$2:$G$513,1),"") | L7: =IF(K7="","",INDEX(Интервалы!$B$2:$B$513,MATCH(K7,Интервалы!$G$2:$G$513,0))) | M7: =IF(Акты!$B$5="","",Акты!$B$5) | N7: =IF(M7="","",Акты!$E$5) | O7: =IF(M7="","",Акты!$D$5) | P7: =IF(M7="","",SUMIF($L$7:$L$518,1,$I$7:$I$518)) | Q7: =IF(M7="","",Акты!$G$5)
A8: =IF(K8="","",2) | B8: =IF(K8="","",INDEX(Интервалы!$A$2:$A$513,MATCH(K8,Интервалы!$G$2:$G$513,0))) | C8: =IF(K8="","",INDEX(Интервалы!$C$2:$C$513,MATCH(K8,Интервалы!$G$2:$G$513,0))) | D8: =IF(K8="","",INDEX(Интервалы!$D$2:$D$513,MATCH(K8,Интервалы!$G$2:$G$513,0))) | E8: =IF(K8="","",D8-C8+1) | F8: =IF(K8="","",INDEX(Интервалы!$E$2:$E$513,MATCH(K8,Интервалы!$G$2:$G$513,0))) | G8: =IF(K8="","",IF(H8=1,INDEX('По дням'!$B$2:$B$4000,MATCH(C8,'По дням'!$A$2:$A$4000,0)),"по периодам ставки")) | H8: =IF(K8="","",INDEX(Интервалы!$I$2:$I$513,MATCH(K8,Интервалы!$G$2:$G$513,0))) | I8: =IF(K8="","",INDEX(Интервалы!$F$2:$F$513,MATCH(K8,Интервалы!$G$2:$G$513,0))) | J8: =IF(K8="","",INDEX(Интервалы!$H$2:$H$513,MATCH(K8,Интервалы!$G$2:$G$513,0))) | K8: =IFERROR(SMALL(Интервалы!$G$2:$G$513,2),"") | L8: =IF(K8="","",INDEX(Интервалы!$B$2:$B$513,MATCH(K8,Интервалы!$G$2:$G$513,0))) | M8: =IF(Акты!$B$6="","",Акты!$B$6) | N8: =IF(M8="","",Акты!$E$6) | O8: =IF(M8="","",Акты!$D$6) | P8: =IF(M8="","",SUMIF($L$7:$L$518,2,$I$7:$I$518)) | Q8: =IF(M8="","",Акты!$G$6)
A9: =IF(K9="","",3) | B9: =IF(K9="","",INDEX(Интервалы!$A$2:$A$513,MATCH(K9,Интервалы!$G$2:$G$513,0))) | C9: =IF(K9="","",INDEX(Интервалы!$C$2:$C$513,MATCH(K9,Интервалы!$G$2:$G$513,0))) | D9: =IF(K9="","",INDEX(Интервалы!$D$2:$D$513,MATCH(K9,Интервалы!$G$2:$G$513,0))) | E9: =IF(K9="","",D9-C9+1) | F9: =IF(K9="","",INDEX(Интервалы!$E$2:$E$513,MATCH(K9,Интервалы!$G$2:$G$513,0))) | G9: =IF(K9="","",IF(H9=1,INDEX('По дням'!$B$2:$B$4000,MATCH(C9,'По дням'!$A$2:$A$4000,0)),"по периодам ставки")) | H9: =IF(K9="","",INDEX(Интервалы!$I$2:$I$513,MATCH(K9,Интервалы!$G$2:$G$513,0))) | I9: =IF(K9="","",INDEX(Интервалы!$F$2:$F$513,MATCH(K9,Интервалы!$G$2:$G$513,0))) | J9: =IF(K9="","",INDEX(Интервалы!$H$2:$H$513,MATCH(K9,Интервалы!$G$2:$G$513,0))) | K9: =IFERROR(SMALL(Интервалы!$G$2:$G$513,3),"") | L9: =IF(K9="","",INDEX(Интервалы!$B$2:$B$513,MATCH(K9,Интервалы!$G$2:$G$513,0))) | M9: =IF(Акты!$B$7="","",Акты!$B$7) | N9: =IF(M9="","",Акты!$E$7) | O9: =IF(M9="","",Акты!$D$7) | P9: =IF(M9="","",SUMIF($L$7:$L$518,3,$I$7:$I$518)) | Q9: =IF(M9="","",Акты!$G$7)
A10: =IF(K10="","",4) | B10: =IF(K10="","",INDEX(Интервалы!$A$2:$A$513,MATCH(K10,Интервалы!$G$2:$G$513,0))) | C10: =IF(K10="","",INDEX(Интервалы!$C$2:$C$513,MATCH(K10,Интервалы!$G$2:$G$513,0))) | D10: =IF(K10="","",INDEX(Интервалы!$D$2:$D$513,MATCH(K10,Интервалы!$G$2:$G$513,0))) | E10: =IF(K10="","",D10-C10+1) | F10: =IF(K10="","",INDEX(Интервалы!$E$2:$E$513,MATCH(K10,Интервалы!$G$2:$G$513,0))) | G10: =IF(K10="","",IF(H10=1,INDEX('По дням'!$B$2:$B$4000,MATCH(C10,'По дням'!$A$2:$A$4000,0)),"по периодам ставки")) | H10: =IF(K10="","",INDEX(Интервалы!$I$2:$I$513,MATCH(K10,Интервалы!$G$2:$G$513,0))) | I10: =IF(K10="","",INDEX(Интервалы!$F$2:$F$513,MATCH(K10,Интервалы!$G$2:$G$513,0))) | J10: =IF(K10="","",INDEX(Интервалы!$H$2:$H$513,MATCH(K10,Интервалы!$G$2:$G$513,0))) | K10: =IFERROR(SMALL(Интервалы!$G$2:$G$513,4),"") | L10: =IF(K10="","",INDEX(Интервалы!$B$2:$B$513,MATCH(K10,Интервалы!$G$2:$G$513,0))) | M10: =IF(Акты!$B$8="","",Акты!$B$8) | N10: =IF(M10="","",Акты!$E$8) | O10: =IF(M10="","",Акты!$D$8) | P10: =IF(M10="","",SUMIF($L$7:$L$518,4,$I$7:$I$518)) | Q10: =IF(M10="","",Акты!$G$8)
A11: =IF(K11="","",5) | B11: =IF(K11="","",INDEX(Интервалы!$A$2:$A$513,MATCH(K11,Интервалы!$G$2:$G$513,0))) | C11: =IF(K11="","",INDEX(Интервалы!$C$2:$C$513,MATCH(K11,Интервалы!$G$2:$G$513,0))) | D11: =IF(K11="","",INDEX(Интервалы!$D$2:$D$513,MATCH(K11,Интервалы!$G$2:$G$513,0))) | E11: =IF(K11="","",D11-C11+1) | F11: =IF(K11="","",INDEX(Интервалы!$E$2:$E$513,MATCH(K11,Интервалы!$G$2:$G$513,0))) | G11: =IF(K11="","",IF(H11=1,INDEX('По дням'!$B$2:$B$4000,MATCH(C11,'По дням'!$A$2:$A$4000,0)),"по периодам ставки")) | H11: =IF(K11="","",INDEX(Интервалы!$I$2:$I$513,MATCH(K11,Интервалы!$G$2:$G$513,0))) | I11: =IF(K11="","",INDEX(Интервалы!$F$2:$F$513,MATCH(K11,Интервалы!$G$2:$G$513,0))) | J11: =IF(K11="","",INDEX(Интервалы!$H$2:$H$513,MATCH(K11,Интервалы!$G$2:$G$513,0))) | K11: =IFERROR(SMALL(Интервалы!$G$2:$G$513,5),"") | L11: =IF(K11="","",INDEX(Интервалы!$B$2:$B$513,MATCH(K11,Интервалы!$G$2:$G$513,0))) | M11: =IF(Акты!$B$9="","",Акты!$B$9) | N11: =IF(M11="","",Акты!$E$9) | O11: =IF(M11="","",Акты!$D$9) | P11: =IF(M11="","",SUMIF($L$7:$L$518,5,$I$7:$I$518)) | Q11: =IF(M11="","",Акты!$G$9)
A12: =IF(K12="","",6) | B12: =IF(K12="","",INDEX(Интервалы!$A$2:$A$513,MATCH(K12,Интервалы!$G$2:$G$513,0))) | C12: =IF(K12="","",INDEX(Интервалы!$C$2:$C$513,MATCH(K12,Интервалы!$G$2:$G$513,0))) | D12: =IF(K12="","",INDEX(Интервалы!$D$2:$D$513,MATCH(K12,Интервалы!$G$2:$G$513,0))) | E12: =IF(K12="","",D12-C12+1) | F12: =IF(K12="","",INDEX(Интервалы!$E$2:$E$513,MATCH(K12,Интервалы!$G$2:$G$513,0))) | G12: =IF(K12="","",IF(H12=1,INDEX('По дням'!$B$2:$B$4000,MATCH(C12,'По дням'!$A$2:$A$4000,0)),"по периодам ставки")) | H12: =IF(K12="","",INDEX(Интервалы!$I$2:$I$513,MATCH(K12,Интервалы!$G$2:$G$513,0))) | I12: =IF(K12="","",INDEX(Интервалы!$F$2:$F$513,MATCH(K12,Интервалы!$G$2:$G$513,0))) | J12: =IF(K12="","",INDEX(Интервалы!$H$2:$H$513,MATCH(K12,Интервалы!$G$2:$G$513,0))) | K12: =IFERROR(SMALL(Интервалы!$G$2:$G$513,6),"") | L12: =IF(K12="","",INDEX(Интервалы!$B$2:$B$513,MATCH(K12,Интервалы!$G$2:$G$513,0))) | M12: =IF(Акты!$B$10="","",Акты!$B$10) | N12: =IF(M12="","",Акты!$E$10) | O12: =IF(M12="","",Акты!$D$10) | P12: =IF(M12="","",SUMIF($L$7:$L$518,6,$I$7:$I$518)) | Q12: =IF(M12="","",Акты!$G$10)
A13: =IF(K13="","",7) | B13: =IF(K13="","",INDEX(Интервалы!$A$2:$A$513,MATCH(K13,Интервалы!$G$2:$G$513,0))) | C13: =IF(K13="","",INDEX(Интервалы!$C$2:$C$513,MATCH(K13,Интервалы!$G$2:$G$513,0))) | D13: =IF(K13="","",INDEX(Интервалы!$D$2:$D$513,MATCH(K13,Интервалы!$G$2:$G$513,0))) | E13: =IF(K13="","",D13-C13+1) | F13: =IF(K13="","",INDEX(Интервалы!$E$2:$E$513,MATCH(K13,Интервалы!$G$2:$G$513,0))) | G13: =IF(K13="","",IF(H13=1,INDEX('По дням'!$B$2:$B$4000,MATCH(C13,'По дням'!$A$2:$A$4000,0)),"по периодам ставки")) | H13: =IF(K13="","",INDEX(Интервалы!$I$2:$I$513,MATCH(K13,Интервалы!$G$2:$G$513,0))) | I13: =IF(K13="","",INDEX(Интервалы!$F$2:$F$513,MATCH(K13,Интервалы!$G$2:$G$513,0))) | J13: =IF(K13="","",INDEX(Интервалы!$H$2:$H$513,MATCH(K13,Интервалы!$G$2:$G$513,0))) | K13: =IFERROR(SMALL(Интервалы!$G$2:$G$513,7),"") | L13: =IF(K13="","",INDEX(Интервалы!$B$2:$B$513,MATCH(K13,Интервалы!$G$2:$G$513,0))) | M13: =IF(Акты!$B$11="","",Акты!$B$11) | N13: =IF(M13="","",Акты!$E$11) | O13: =IF(M13="","",Акты!$D$11) | P13: =IF(M13="","",SUMIF($L$7:$L$518,7,$I$7:$I$518)) | Q13: =IF(M13="","",Акты!$G$11)
A14: =IF(K14="","",8) | B14: =IF(K14="","",INDEX(Интервалы!$A$2:$A$513,MATCH(K14,Интервалы!$G$2:$G$513,0))) | C14: =IF(K14="","",INDEX(Интервалы!$C$2:$C$513,MATCH(K14,Интервалы!$G$2:$G$513,0))) | D14: =IF(K14="","",INDEX(Интервалы!$D$2:$D$513,MATCH(K14,Интервалы!$G$2:$G$513,0))) | E14: =IF(K14="","",D14-C14+1) | F14: =IF(K14="","",INDEX(Интервалы!$E$2:$E$513,MATCH(K14,Интервалы!$G$2:$G$513,0))) | G14: =IF(K14="","",IF(H14=1,INDEX('По дням'!$B$2:$B$4000,MATCH(C14,'По дням'!$A$2:$A$4000,0)),"по периодам ставки")) | H14: =IF(K14="","",INDEX(Интервалы!$I$2:$I$513,MATCH(K14,Интервалы!$G$2:$G$513,0))) | I14: =IF(K14="","",INDEX(Интервалы!$F$2:$F$513,MATCH(K14,Интервалы!$G$2:$G$513,0))) | J14: =IF(K14="","",INDEX(Интервалы!$H$2:$H$513,MATCH(K14,Интервалы!$G$2:$G$513,0))) | K14: =IFERROR(SMALL(Интервалы!$G$2:$G$513,8),"") | L14: =IF(K14="","",INDEX(Интервалы!$B$2:$B$513,MATCH(K14,Интервалы!$G$2:$G$513,0))) | M14: =IF(Акты!$B$12="","",Акты!$B$12) | N14: =IF(M14="","",Акты!$E$12) | O14: =IF(M14="","",Акты!$D$12) | P14: =IF(M14="","",SUMIF($L$7:$L$518,8,$I$7:$I$518)) | Q14: =IF(M14="","",Акты!$G$12)
A15: =IF(K15="","",9) | B15: =IF(K15="","",INDEX(Интервалы!$A$2:$A$513,MATCH(K15,Интервалы!$G$2:$G$513,0))) | C15: =IF(K15="","",INDEX(Интервалы!$C$2:$C$513,MATCH(K15,Интервалы!$G$2:$G$513,0))) | D15: =IF(K15="","",INDEX(Интервалы!$D$2:$D$513,MATCH(K15,Интервалы!$G$2:$G$513,0))) | E15: =IF(K15="","",D15-C15+1) | F15: =IF(K15="","",INDEX(Интервалы!$E$2:$E$513,MATCH(K15,Интервалы!$G$2:$G$513,0))) | G15: =IF(K15="","",IF(H15=1,INDEX('По дням'!$B$2:$B$4000,MATCH(C15,'По дням'!$A$2:$A$4000,0)),"по периодам ставки")) | H15: =IF(K15="","",INDEX(Интервалы!$I$2:$I$513,MATCH(K15,Интервалы!$G$2:$G$513,0))) | I15: =IF(K15="","",INDEX(Интервалы!$F$2:$F$513,MATCH(K15,Интервалы!$G$2:$G$513,0))) | J15: =IF(K15="","",INDEX(Интервалы!$H$2:$H$513,MATCH(K15,Интервалы!$G$2:$G$513,0))) | K15: =IFERROR(SMALL(Интервалы!$G$2:$G$513,9),"") | L15: =IF(K15="","",INDEX(Интервалы!$B$2:$B$513,MATCH(K15,Интервалы!$G$2:$G$513,0))) | M15: =IF(Акты!$B$13="","",Акты!$B$13) | N15: =IF(M15="","",Акты!$E$13) | O15: =IF(M15="","",Акты!$D$13) | P15: =IF(M15="","",SUMIF($L$7:$L$518,9,$I$7:$I$518)) | Q15: =IF(M15="","",Акты!$G$13)
A16: =IF(K16="","",10) | B16: =IF(K16="","",INDEX(Интервалы!$A$2:$A$513,MATCH(K16,Интервалы!$G$2:$G$513,0))) | C16: =IF(K16="","",INDEX(Интервалы!$C$2:$C$513,MATCH(K16,Интервалы!$G$2:$G$513,0))) | D16: =IF(K16="","",INDEX(Интервалы!$D$2:$D$513,MATCH(K16,Интервалы!$G$2:$G$513,0))) | E16: =IF(K16="","",D16-C16+1) | F16: =IF(K16="","",INDEX(Интервалы!$E$2:$E$513,MATCH(K16,Интервалы!$G$2:$G$513,0))) | G16: =IF(K16="","",IF(H16=1,INDEX('По дням'!$B$2:$B$4000,MATCH(C16,'По дням'!$A$2:$A$4000,0)),"по периодам ставки")) | H16: =IF(K16="","",INDEX(Интервалы!$I$2:$I$513,MATCH(K16,Интервалы!$G$2:$G$513,0))) | I16: =IF(K16="","",INDEX(Интервалы!$F$2:$F$513,MATCH(K16,Интервалы!$G$2:$G$513,0))) | J16: =IF(K16="","",INDEX(Интервалы!$H$2:$H$513,MATCH(K16,Интервалы!$G$2:$G$513,0))) | K16: =IFERROR(SMALL(Интервалы!$G$2:$G$513,10),"") | L16: =IF(K16="","",INDEX(Интервалы!$B$2:$B$513,MATCH(K16,Интервалы!$G$2:$G$513,0))) | M16: =IF(Акты!$B$14="","",Акты!$B$14) | N16: =IF(M16="","",Акты!$E$14) | O16: =IF(M16="","",Акты!$D$14) | P16: =IF(M16="","",SUMIF($L$7:$L$518,10,$I$7:$I$518)) | Q16: =IF(M16="","",Акты!$G$14)
