Workbook

Sheet Условия
A1: Калькулятор условий аванса
A2: Сравните сценарии А и Б. Числовые поля заполните числами; подтверждённое отсутствие расхода — 0, неизвестное значение не заменяйте нулём. Итоги доступны после проверки условий и профиля.
A4: Условие | B4: Сценарий А | C4: Сценарий Б | D4: Содержание показателя и источник данных
A5: Сумма договора, руб. | D5: Цена договора. Используйте единый порядок учёта НДС во всех исходных суммах и расходах.
A6: Размер аванса, % от суммы договора | D6: Доля цены договора, выплачиваемая авансом. Для оценки потребности в финансировании рассмотрите также сценарий без аванса.
A7: Месяц поступления аванса | D7: Целый месяц 1–36. При нулевом авансе — 0 или пусто. Погашение ранее получения аванса требует исправления графика.
A8: Порядок погашения аванса | D8: Выберите предусмотренный договором порядок погашения из справочника этого листа.
A9: Доля выполнения, с которой начинается погашение, % | D9: Для третьего порядка: число от 0 до менее 100. Для других порядков — 0 или пусто.
A10: Ставка обеспечения аванса, % годовых | D10: Годовая ставка комиссии за обеспечение по предложению банка или страховщика на дату расчёта. При отсутствии обеспечения укажите 0.
A11: Срок действия обеспечения, мес. | D11: При платном обеспечении: положительное целое число месяцев. Без обеспечения — 0 или пусто.
A12: Месяц оплаты обеспечения | D12: При платном обеспечении: целый месяц 1–36. Без обеспечения — 0 или пусто.
A13: Гарантийное удержание, % от каждой КС | D13: Доля стоимости каждого акта, удерживаемая в качестве гарантийного обеспечения. Рассматривается совместно с погашением аванса.
A14: Месяц возврата гарантийного удержания | D14: Целый месяц 0–36; 0 — возврата нет. Возврат возможен только в пределах удержания, накопленного к сроку оплаты КС.
A15: Доля возвращаемого удержания, % | D15: Процент от общего удержания по графику. Ранний возврат всей будущей суммы не допускается; проверьте остаток в выбранном месяце.
A16: Срок объекта, мес. | D16: Продолжительность работ по графику. Используется для проверки: объём в графике КС за пределами срока — признак ошибки ввода.
... A20: Стартовые затраты до первой КС, руб. | D20: Дополнительные стартовые расходы в первом месяце. Не включайте повторно затраты, уже учтённые в себестоимости. При отсутствии — 0.
A22: Расчётные показатели
A23: Сумма аванса, руб. | B23: =IF(B26<>"Условия заполнены","",ROUND(B5*B6/100,2)) | C23: =IF(C26<>"Условия заполнены","",ROUND(C5*C6/100,2))
A24: Стоимость обеспечения аванса, руб. | B24: =IF(B26<>"Условия заполнены","",IF(OR(B6=0,B10=0),0,ROUND(B23*B10/100*B11/12,2))) | C24: =IF(C26<>"Условия заполнены","",IF(OR(C6=0,C10=0),0,ROUND(C23*C10/100*C11/12,2)))
A25: Код порядка погашения (1, 2 или 3) | B25: =IF(B6=0,0,IFERROR(MATCH(B8,$A$29:$A$31,0),0)) | C25: =IF(C6=0,0,IFERROR(MATCH(C8,$A$29:$A$31,0),0))
A26: Проверка условий | B26: =IFERROR(IF(OR(LEN(B5)=0,LEN(B6)=0,LEN(B10)=0,LEN(B13)=0,LEN(B16)=0,LEN(B17)=0,LEN(B18)=0,LEN(B19)=0,LEN(B20)=0),"НЕ ЗАПОЛНЕНО: обязательные суммы, проценты и сроки",IF(OR(NOT(ISNUMBER(B5)),NOT(ISNUMBER(B6)),NOT(ISNUMBER(B10)),NOT(ISNUMBER(B13)),NOT(ISNUMBER(B16)),NOT(ISNUMBER(B17)),NOT(ISNUMBER(B18)),NOT(ISNUMBER(B19)),NOT(ISNUMBER(B20))),"ОШИБКА: обязательные показатели вводятся числами",IF(OR(B5<=0,B6<0,B6>100,B10<0,B13<0,B13>100,B18<0,B20<0),"ОШИБКА: проверьте знак сумм и диапазон процентов",IF(OR(B16<1,B16>36,B16<>INT(B16),B17<0,B17>36,B17<>INT(B17),B19<0,B19>35,B19<>INT(B19)),"ОШИБКА: сроки — целые месяцы в пределах горизонта",IF(AND(B6>0,OR(NOT(ISNUMBER(B7)),B7<1,B7>36,B7<>INT(B7))),"ОШИБКА: укажите целый месяц получения аванса 1–36",IF(AND(B6>0,B25=0),"ОШИБКА: выберите порядок погашения из списка",IF(AND(B6>0,B25=3,OR(LEN(B9)=0,NOT(ISNUMBER(B9)),B9<0,B9>=100)),"ОШИБКА: порог погашения от 0 до менее 100%",IF(AND(B6>0,B10>0,OR(NOT(ISNUMBER(B11)),B11<=0,B11<>INT(B11),NOT(ISNUMBER(B12)),B12<1,B12>36,B12<>INT(B12))),"ОШИБКА: проверьте срок и месяц оплаты обеспечения",IF(AND(B13>0,OR(NOT(ISNUMBER(B14)),B14<0,B14>36,B14<>INT(B14),NOT(ISNUMBER(B15)),B15<0,B15>100,LEN(B14)=0,LEN(B15)=0)),"ОШИБКА: проверьте месяц и долю возврата удержания",IF(COUNT('График КС'!B5:B40)<>COUNTA('График КС'!B5:B40),"ОШИБКА: доли графика должны быть числами",IF(OR(COUNTIF('График КС'!B5:B40,"<0")>0,COUNTIF('График КС'!B5:B40,">100")>0),"ОШИБКА: доля графика вне диапазона 0–100%",IF(ABS(SUM('График КС'!B5:B40)-100)>0.000001,"НЕ ЗАПОЛНЕНО: сумма долей графика должна быть 100%",IF(SUMIF('График КС'!$A$5:$A$40,">"&B16,'График КС'!B5:B40)>0,"ОШИБКА: работы в графике выходят за срок объекта","Условия заполнены"))))))))))))),"ОШИБКА: проверьте числовые исходные данные") | C26: =IFERROR(IF(OR(LEN(C5)=0,LEN(C6)=0,LEN(C10)=0,LEN(C13)=0,LEN(C16)=0,LEN(C17)=0,LEN(C18)=0,LEN(C19)=0,LEN(C20)=0),"НЕ ЗАПОЛНЕНО: обязательные суммы, проценты и сроки",IF(OR(NOT(ISNUMBER(C5)),NOT(ISNUMBER(C6)),NOT(ISNUMBER(C10)),NOT(ISNUMBER(C13)),NOT(ISNUMBER(C16)),NOT(ISNUMBER(C17)),NOT(ISNUMBER(C18)),NOT(ISNUMBER(C19)),NOT(ISNUMBER(C20))),"ОШИБКА: обязательные показатели вводятся числами",IF(OR(C5<=0,C6<0,C6>100,C10<0,C13<0,C13>100,C18<0,C20<0),"ОШИБКА: проверьте знак сумм и диапазон процентов",IF(OR(C16<1,C16>36,C16<>INT(C16),C17<0,C17>36,C17<>INT(C17),C19<0,C19>35,C19<>INT(C19)),"ОШИБКА: сроки — целые месяцы в пределах горизонта",IF(AND(C6>0,OR(NOT(ISNUMBER(C7)),C7<1,C7>36,C7<>INT(C7))),"ОШИБКА: укажите целый месяц получения аванса 1–36",IF(AND(C6>0,C25=0),"ОШИБКА: выберите порядок погашения из списка",IF(AND(C6>0,C25=3,OR(LEN(C9)=0,NOT(ISNUMBER(C9)),C9<0,C9>=100)),"ОШИБКА: порог погашения от 0 до менее 100%",IF(AND(C6>0,C10>0,OR(NOT(ISNUMBER(C11)),C11<=0,C11<>INT(C11),NOT(ISNUMBER(C12)),C12<1,C12>36,C12<>INT(C12))),"ОШИБКА: проверьте срок и месяц оплаты обеспечения",IF(AND(C13>0,OR(NOT(ISNUMBER(C14)),C14<0,C14>36,C14<>INT(C14),NOT(ISNUMBER(C15)),C15<0,C15>100,LEN(C14)=0,LEN(C15)=0)),"ОШИБКА: проверьте месяц и долю возврата удержания",IF(COUNT('График КС'!C5:C40)<>COUNTA('График КС'!C5:C40),"ОШИБКА: доли графика должны быть числами",IF(OR(COUNTIF('График КС'!C5:C40,"<0")>0,COUNTIF('График КС'!C5:C40,">100")>0),"ОШИБКА: доля графика вне диапазона 0–100%",IF(ABS(SUM('График КС'!C5:C40)-100)>0.000001,"НЕ ЗАПОЛНЕНО: сумма долей графика должна быть 100%",IF(SUMIF('График КС'!$A$5:$A$40,">"&C16,'График КС'!C5:C40)>0,"ОШИБКА: работы в графике выходят за срок объекта","Условия заполнены"))))))))))))),"ОШИБКА: проверьте числовые исходные данные")
A28: Справочник: допустимые значения порядка погашения
A29: пропорционально из каждой КС | B29: 1 | D29: Из стоимости каждого акта погашается согласованная доля аванса.
A30: единовременно из последней КС | B30: 2 | D30: Аванс погашается из стоимости последнего акта. Проверьте остаток к оплате в соответствующем месяце.
A31: с отсрочкой до доли выполнения | B31: 3 | D31: Погашение начинается после достижения указанной доли выполнения и распределяется на оставшийся объём.
A34: Проверка исходных ставок и сроков
A35: Ставки и сроки берите из договора и предложения банка. Проценты вводите числом: 20 означает 20%, не 0,2. В календарных полях используются порядковые месяцы, а не даты.
A37: Контроль условий перед переговорами
A38: Готовность показана на листе «Сравнение», строка 18. При сообщении о профиле проверьте колонку P. Это месячный денежный расчёт, не прибыль и не внутримесячный максимум потребности.

Sheet График КС
A1: Помесячное распределение стоимости выполненных работ
A2: В жёлтых колонках укажите долю выполненных работ каждого месяца, числом от 0 до 100. Сумма каждого сценария — 100. Месяцы без работ можно оставить пустыми или указать 0.
A4: Месяц | B4: Доля объёма, % — сценарий А | C4: Доля объёма, % — сценарий Б | D4: Проверка
A5: 1 | D5: =IF(COUNTA(B5:C5)=0,"",IF(OR(AND(B5<>"",NOT(ISNUMBER(B5))),AND(C5<>"",NOT(ISNUMBER(C5)))),"ОШИБКА: доля должна быть числом",IF(OR(B5<0,C5<0,B5>100,C5>100),"ОШИБКА: доля вне 0–100%","")))
A6: 2 | D6: =IF(COUNTA(B6:C6)=0,"",IF(OR(AND(B6<>"",NOT(ISNUMBER(B6))),AND(C6<>"",NOT(ISNUMBER(C6)))),"ОШИБКА: доля должна быть числом",IF(OR(B6<0,C6<0,B6>100,C6>100),"ОШИБКА: доля вне 0–100%","")))
A7: 3 | D7: =IF(COUNTA(B7:C7)=0,"",IF(OR(AND(B7<>"",NOT(ISNUMBER(B7))),AND(C7<>"",NOT(ISNUMBER(C7)))),"ОШИБКА: доля должна быть числом",IF(OR(B7<0,C7<0,B7>100,C7>100),"ОШИБКА: доля вне 0–100%","")))
A8: 4 | D8: =IF(COUNTA(B8:C8)=0,"",IF(OR(AND(B8<>"",NOT(ISNUMBER(B8))),AND(C8<>"",NOT(ISNUMBER(C8)))),"ОШИБКА: доля должна быть числом",IF(OR(B8<0,C8<0,B8>100,C8>100),"ОШИБКА: доля вне 0–100%","")))
A9: 5 | D9: =IF(COUNTA(B9:C9)=0,"",IF(OR(AND(B9<>"",NOT(ISNUMBER(B9))),AND(C9<>"",NOT(ISNUMBER(C9)))),"ОШИБКА: доля должна быть числом",IF(OR(B9<0,C9<0,B9>100,C9>100),"ОШИБКА: доля вне 0–100%","")))
A10: 6 | D10: =IF(COUNTA(B10:C10)=0,"",IF(OR(AND(B10<>"",NOT(ISNUMBER(B10))),AND(C10<>"",NOT(ISNUMBER(C10)))),"ОШИБКА: доля должна быть числом",IF(OR(B10<0,C10<0,B10>100,C10>100),"ОШИБКА: доля вне 0–100%","")))
A11: 7 | D11: =IF(COUNTA(B11:C11)=0,"",IF(OR(AND(B11<>"",NOT(ISNUMBER(B11))),AND(C11<>"",NOT(ISNUMBER(C11)))),"ОШИБКА: доля должна быть числом",IF(OR(B11<0,C11<0,B11>100,C11>100),"ОШИБКА: доля вне 0–100%","")))
A12: 8 | D12: =IF(COUNTA(B12:C12)=0,"",IF(OR(AND(B12<>"",NOT(ISNUMBER(B12))),AND(C12<>"",NOT(ISNUMBER(C12)))),"ОШИБКА: доля должна быть числом",IF(OR(B12<0,C12<0,B12>100,C12>100),"ОШИБКА: доля вне 0–100%","")))
A13: 9 | D13: =IF(COUNTA(B13:C13)=0,"",IF(OR(AND(B13<>"",NOT(ISNUMBER(B13))),AND(C13<>"",NOT(ISNUMBER(C13)))),"ОШИБКА: доля должна быть числом",IF(OR(B13<0,C13<0,B13>100,C13>100),"ОШИБКА: доля вне 0–100%","")))
A14: 10 | D14: =IF(COUNTA(B14:C14)=0,"",IF(OR(AND(B14<>"",NOT(ISNUMBER(B14))),AND(C14<>"",NOT(ISNUMBER(C14)))),"ОШИБКА: доля должна быть числом",IF(OR(B14<0,C14<0,B14>100,C14>100),"ОШИБКА: доля вне 0–100%","")))
A15: 11 | D15: =IF(COUNTA(B15:C15)=0,"",IF(OR(AND(B15<>"",NOT(ISNUMBER(B15))),AND(C15<>"",NOT(ISNUMBER(C15)))),"ОШИБКА: доля должна быть числом",IF(OR(B15<0,C15<0,B15>100,C15>100),"ОШИБКА: доля вне 0–100%","")))
A16: 12 | D16: =IF(COUNTA(B16:C16)=0,"",IF(OR(AND(B16<>"",NOT(ISNUMBER(B16))),AND(C16<>"",NOT(ISNUMBER(C16)))),"ОШИБКА: доля должна быть числом",IF(OR(B16<0,C16<0,B16>100,C16>100),"ОШИБКА: доля вне 0–100%","")))
... A40: 36 | D40: =IF(COUNTA(B40:C40)=0,"",IF(OR(AND(B40<>"",NOT(ISNUMBER(B40))),AND(C40<>"",NOT(ISNUMBER(C40)))),"ОШИБКА: доля должна быть числом",IF(OR(B40<0,C40<0,B40>100,C40>100),"ОШИБКА: доля вне 0–100%","")))
A42: Итого | B42: =ROUND(SUM($B$5:$B$40),4) | C42: =ROUND(SUM($C$5:$C$40),4) | D42: =IF(AND(ROUND($B42,2)=100,ROUND($C42,2)=100),"Сумма долей выполнения в каждом сценарии составляет 100%.","Сумма долей выполнения отличается от 100%: проверьте полноту графика.")
A44: Горизонт расчёта составляет 36 месяцев с месячным шагом. Для более длительного проекта подготовьте отдельный график с соответствующим горизонтом. Единицу периода в данном расчёте сохраняйте. Остаток «Начислено, но не поступило» сопоставьте с договорными датами платежей после окончания расчёта.

Sheet Профиль А
A1: Кассовый профиль по объекту — сценарий А
A2: Помесячные денежные потоки. Колонка P показывает противоречия по срокам и суммам; при них итог сравнения блокируется. Возврат удержания ограничен суммой, накопленной к плановой дате оплаты КС.
A4: Месяц | B4: Выполнено за месяц, руб. | C4: Накопленный объём, руб. | D4: Накопленная доля, % | E4: Погашено аванса нарастающим, руб. | F4: Погашение аванса за месяц, руб. | G4: Гарантийное удержание за месяц, руб. | H4: Начислено к оплате за месяц, руб. | I4: Поступление аванса, руб. | J4: Оплата КС с отсрочкой, руб. | K4: Возврат гарантийного удержания, руб. | L4: Расходы за месяц, руб. | M4: Сальдо месяца, руб. | N4: Накопленный остаток, руб. | O4: Отрицательный остаток | P4: Проверка
A5: 1 | B5: =IF('Условия'!$B$26<>"Условия заполнены","",ROUND(IFERROR('Условия'!$B$5*INDEX('График КС'!$B$5:$B$40,MATCH($A5,'График КС'!$A$5:$A$40,0))/100,0),2)) | C5: =IF('Условия'!$B$26<>"Условия заполнены","",SUMIFS($B$5:$B$40,$A$5:$A$40,"<="&$A5)) | D5: =IF('Условия'!$B$26<>"Условия заполнены","",SUMIFS('График КС'!$B$5:$B$40,'График КС'!$A$5:$A$40,"<="&$A5)) | E5: =IF('Условия'!$B$26<>"Условия заполнены","",IF('Условия'!$B$25=0,0,IFERROR(MAX(0,MIN('Условия'!$B$23,IF('Условия'!$B$25=1,ROUND('Условия'!$B$23*$D5/'График КС'!$B$42,2),IF('Условия'!$B$25=2,IF($D5>='График КС'!$B$42,'Условия'!$B$23,0),ROUND('Условия'!$B$23*($D5-'Условия'!$B$9)/('График КС'!$B$42-'Условия'!$B$9),2))))),0))) | F5: =IF('Условия'!$B$26<>"Условия заполнены","",ROUND($E5,2)) | G5: =IF('Условия'!$B$26<>"Условия заполнены","",ROUND($B5*'Условия'!$B$13/100,2)) | H5: =IF('Условия'!$B$26<>"Условия заполнены","",ROUND($B5-$F5-$G5,2)) | I5: =IF('Условия'!$B$26<>"Условия заполнены","",IF($A5='Условия'!$B$7,'Условия'!$B$23,0)) | J5: =IF('Условия'!$B$26<>"Условия заполнены","",IFERROR(INDEX($H$5:$H$40,MATCH($A5-'Условия'!$B$17,$A$5:$A$40,0)),0)) | K5: =IF('Условия'!$B$26<>"Условия заполнены","",IF(AND('Условия'!$B$13>0,'Условия'!$B$14>0,$A5='Условия'!$B$14),ROUND(MIN(ROUND(SUM($G$5:$G$40)*'Условия'!$B$15/100,2),SUMIFS($G$5:$G$40,$A$5:$A$40,"<="&($A5-'Условия'!$B$17))),2),0)) | L5: =IF('Условия'!$B$26<>"Условия заполнены","",ROUND(SUMIFS($B$5:$B$40,$A$5:$A$40,"<="&($A5+'Условия'!$B$19))*'Условия'!$B$18/100,2)+IF($A5=1,'Условия'!$B$20,0)+IF($A5='Условия'!$B$12,'Условия'!$B$24,0)) | M5: =IF('Условия'!$B$26<>"Условия заполнены","",ROUND($I5+$J5+$K5-$L5,2)) | N5: =IF('Условия'!$B$26<>"Условия заполнены","",ROUND($M5,2)) | O5: =IF('Условия'!$B$26<>"Условия заполнены","",IF($N5<0,$A5,"")) | P5: =IF('Условия'!$B$26<>"Условия заполнены","",IF($H5<-0.01,"ОШИБКА: погашение и удержание больше стоимости КС",IF(AND($F5>0.01,$A5<'Условия'!$B$7),"ОШИБКА: аванс погашается до поступления",IF(AND('Условия'!$B$13>0,'Условия'!$B$14>0,$A5='Условия'!$B$14,ROUND(SUM($G$5:$G$40)*'Условия'!$B$15/100,2)>SUMIFS($G$5:$G$40,$A$5:$A$40,"<="&($A5-'Условия'!$B$17))+0.01),"ОШИБКА: возврат больше накопленного удержания",""))))
A6: 2 | B6: =IF('Условия'!$B$26<>"Условия заполнены","",ROUND(IFERROR('Условия'!$B$5*INDEX('График КС'!$B$5:$B$40,MATCH($A6,'График КС'!$A$5:$A$40,0))/100,0),2)) | C6: =IF('Условия'!$B$26<>"Условия заполнены","",SUMIFS($B$5:$B$40,$A$5:$A$40,"<="&$A6)) | D6: =IF('Условия'!$B$26<>"Условия заполнены","",SUMIFS('График КС'!$B$5:$B$40,'График КС'!$A$5:$A$40,"<="&$A6)) | E6: =IF('Условия'!$B$26<>"Условия заполнены","",IF('Условия'!$B$25=0,0,IFERROR(MAX(0,MIN('Условия'!$B$23,IF('Условия'!$B$25=1,ROUND('Условия'!$B$23*$D6/'График КС'!$B$42,2),IF('Условия'!$B$25=2,IF($D6>='График КС'!$B$42,'Условия'!$B$23,0),ROUND('Условия'!$B$23*($D6-'Условия'!$B$9)/('График КС'!$B$42-'Условия'!$B$9),2))))),0))) | F6: =IF('Условия'!$B$26<>"Условия заполнены","",ROUND($E6-$E5,2)) | G6: =IF('Условия'!$B$26<>"Условия заполнены","",ROUND($B6*'Условия'!$B$13/100,2)) | H6: =IF('Условия'!$B$26<>"Условия заполнены","",ROUND($B6-$F6-$G6,2)) | I6: =IF('Условия'!$B$26<>"Условия заполнены","",IF($A6='Условия'!$B$7,'Условия'!$B$23,0)) | J6: =IF('Условия'!$B$26<>"Условия заполнены","",IFERROR(INDEX($H$5:$H$40,MATCH($A6-'Условия'!$B$17,$A$5:$A$40,0)),0)) | K6: =IF('Условия'!$B$26<>"Условия заполнены","",IF(AND('Условия'!$B$13>0,'Условия'!$B$14>0,$A6='Условия'!$B$14),ROUND(MIN(ROUND(SUM($G$5:$G$40)*'Условия'!$B$15/100,2),SUMIFS($G$5:$G$40,$A$5:$A$40,"<="&($A6-'Условия'!$B$17))),2),0)) | L6: =IF('Условия'!$B$26<>"Условия заполнены","",ROUND(IFERROR(INDEX($B$5:$B$40,MATCH($A6+'Условия'!$B$19,$A$5:$A$40,0)),0)*'Условия'!$B$18/100,2)+IF($A6=1,'Условия'!$B$20,0)+IF($A6='Условия'!$B$12,'Условия'!$B$24,0)) | M6: =IF('Условия'!$B$26<>"Условия заполнены","",ROUND($I6+$J6+$K6-$L6,2)) | N6: =IF('Условия'!$B$26<>"Условия заполнены","",ROUND($N5+$M6,2)) | O6: =IF('Условия'!$B$26<>"Условия заполнены","",IF($N6<0,$A6,"")) | P6: =IF('Условия'!$B$26<>"Условия заполнены","",IF($H6<-0.01,"ОШИБКА: погашение и удержание больше стоимости КС",IF(AND($F6>0.01,$A6<'Условия'!$B$7),"ОШИБКА: аванс погашается до поступления",IF(AND('Условия'!$B$13>0,'Условия'!$B$14>0,$A6='Условия'!$B$14,ROUND(SUM($G$5:$G$40)*'Условия'!$B$15/100,2)>SUMIFS($G$5:$G$40,$A$5:$A$40,"<="&($A6-'Условия'!$B$17))+0.01),"ОШИБКА: возврат больше накопленного удержания",""))))
A7: 3 | B7: =IF('Условия'!$B$26<>"Условия заполнены","",ROUND(IFERROR('Условия'!$B$5*INDEX('График КС'!$B$5:$B$40,MATCH($A7,'График КС'!$A$5:$A$40,0))/100,0),2)) | C7: =IF('Условия'!$B$26<>"Условия заполнены","",SUMIFS($B$5:$B$40,$A$5:$A$40,"<="&$A7)) | D7: =IF('Условия'!$B$26<>"Условия заполнены","",SUMIFS('График КС'!$B$5:$B$40,'График КС'!$A$5:$A$40,"<="&$A7)) | E7: =IF('Условия'!$B$26<>"Условия заполнены","",IF('Условия'!$B$25=0,0,IFERROR(MAX(0,MIN('Условия'!$B$23,IF('Условия'!$B$25=1,ROUND('Условия'!$B$23*$D7/'График КС'!$B$42,2),IF('Условия'!$B$25=2,IF($D7>='График КС'!$B$42,'Условия'!$B$23,0),ROUND('Условия'!$B$23*($D7-'Условия'!$B$9)/('График КС'!$B$42-'Условия'!$B$9),2))))),0))) | F7: =IF('Условия'!$B$26<>"Условия заполнены","",ROUND($E7-$E6,2)) | G7: =IF('Условия'!$B$26<>"Условия заполнены","",ROUND($B7*'Условия'!$B$13/100,2)) | H7: =IF('Условия'!$B$26<>"Условия заполнены","",ROUND($B7-$F7-$G7,2)) | I7: =IF('Условия'!$B$26<>"Условия заполнены","",IF($A7='Условия'!$B$7,'Условия'!$B$23,0)) | J7: =IF('Условия'!$B$26<>"Условия заполнены","",IFERROR(INDEX($H$5:$H$40,MATCH($A7-'Условия'!$B$17,$A$5:$A$40,0)),0)) | K7: =IF('Условия'!$B$26<>"Условия заполнены","",IF(AND('Условия'!$B$13>0,'Условия'!$B$14>0,$A7='Условия'!$B$14),ROUND(MIN(ROUND(SUM($G$5:$G$40)*'Условия'!$B$15/100,2),SUMIFS($G$5:$G$40,$A$5:$A$40,"<="&($A7-'Условия'!$B$17))),2),0)) | L7: =IF('Условия'!$B$26<>"Условия заполнены","",ROUND(IFERROR(INDEX($B$5:$B$40,MATCH($A7+'Условия'!$B$19,$A$5:$A$40,0)),0)*'Условия'!$B$18/100,2)+IF($A7=1,'Условия'!$B$20,0)+IF($A7='Условия'!$B$12,'Условия'!$B$24,0)) | M7: =IF('Условия'!$B$26<>"Условия заполнены","",ROUND($I7+$J7+$K7-$L7,2)) | N7: =IF('Условия'!$B$26<>"Условия заполнены","",ROUND($N6+$M7,2)) | O7: =IF('Условия'!$B$26<>"Условия заполнены","",IF($N7<0,$A7,"")) | P7: =IF('Условия'!$B$26<>"Условия заполнены","",IF($H7<-0.01,"ОШИБКА: погашение и удержание больше стоимости КС",IF(AND($F7>0.01,$A7<'Условия'!$B$7),"ОШИБКА: аванс погашается до поступления",IF(AND('Условия'!$B$13>0,'Условия'!$B$14>0,$A7='Условия'!$B$14,ROUND(SUM($G$5:$G$40)*'Условия'!$B$15/100,2)>SUMIFS($G$5:$G$40,$A$5:$A$40,"<="&($A7-'Условия'!$B$17))+0.01),"ОШИБКА: возврат больше накопленного удержания",""))))
A8: 4 | B8: =IF('Условия'!$B$26<>"Условия заполнены","",ROUND(IFERROR('Условия'!$B$5*INDEX('График КС'!$B$5:$B$40,MATCH($A8,'График КС'!$A$5:$A$40,0))/100,0),2)) | C8: =IF('Условия'!$B$26<>"Условия заполнены","",SUMIFS($B$5:$B$40,$A$5:$A$40,"<="&$A8)) | D8: =IF('Условия'!$B$26<>"Условия заполнены","",SUMIFS('График КС'!$B$5:$B$40,'График КС'!$A$5:$A$40,"<="&$A8)) | E8: =IF('Условия'!$B$26<>"Условия заполнены","",IF('Условия'!$B$25=0,0,IFERROR(MAX(0,MIN('Условия'!$B$23,IF('Условия'!$B$25=1,ROUND('Условия'!$B$23*$D8/'График КС'!$B$42,2),IF('Условия'!$B$25=2,IF($D8>='График КС'!$B$42,'Условия'!$B$23,0),ROUND('Условия'!$B$23*($D8-'Условия'!$B$9)/('График КС'!$B$42-'Условия'!$B$9),2))))),0))) | F8: =IF('Условия'!$B$26<>"Условия заполнены","",ROUND($E8-$E7,2)) | G8: =IF('Условия'!$B$26<>"Условия заполнены","",ROUND($B8*'Условия'!$B$13/100,2)) | H8: =IF('Условия'!$B$26<>"Условия заполнены","",ROUND($B8-$F8-$G8,2)) | I8: =IF('Условия'!$B$26<>"Условия заполнены","",IF($A8='Условия'!$B$7,'Условия'!$B$23,0)) | J8: =IF('Условия'!$B$26<>"Условия заполнены","",IFERROR(INDEX($H$5:$H$40,MATCH($A8-'Условия'!$B$17,$A$5:$A$40,0)),0)) | K8: =IF('Условия'!$B$26<>"Условия заполнены","",IF(AND('Условия'!$B$13>0,'Условия'!$B$14>0,$A8='Условия'!$B$14),ROUND(MIN(ROUND(SUM($G$5:$G$40)*'Условия'!$B$15/100,2),SUMIFS($G$5:$G$40,$A$5:$A$40,"<="&($A8-'Условия'!$B$17))),2),0)) | L8: =IF('Условия'!$B$26<>"Условия заполнены","",ROUND(IFERROR(INDEX($B$5:$B$40,MATCH($A8+'Условия'!$B$19,$A$5:$A$40,0)),0)*'Условия'!$B$18/100,2)+IF($A8=1,'Условия'!$B$20,0)+IF($A8='Условия'!$B$12,'Условия'!$B$24,0)) | M8: =IF('Условия'!$B$26<>"Условия заполнены","",ROUND($I8+$J8+$K8-$L8,2)) | N8: =IF('Условия'!$B$26<>"Условия заполнены","",ROUND($N7+$M8,2)) | O8: =IF('Условия'!$B$26<>"Условия заполнены","",IF($N8<0,$A8,"")) | P8: =IF('Условия'!$B$26<>"Условия заполнены","",IF($H8<-0.01,"ОШИБКА: погашение и удержание больше стоимости КС",IF(AND($F8>0.01,$A8<'Условия'!$B$7),"ОШИБКА: аванс погашается до поступления",IF(AND('Условия'!$B$13>0,'Условия'!$B$14>0,$A8='Условия'!$B$14,ROUND(SUM($G$5:$G$40)*'Условия'!$B$15/100,2)>SUMIFS($G$5:$G$40,$A$5:$A$40,"<="&($A8-'Условия'!$B$17))+0.01),"ОШИБКА: возврат больше накопленного удержания",""))))
A9: 5 | B9: =IF('Условия'!$B$26<>"Условия заполнены","",ROUND(IFERROR('Условия'!$B$5*INDEX('График КС'!$B$5:$B$40,MATCH($A9,'График КС'!$A$5:$A$40,0))/100,0),2)) | C9: =IF('Условия'!$B$26<>"Условия заполнены","",SUMIFS($B$5:$B$40,$A$5:$A$40,"<="&$A9)) | D9: =IF('Условия'!$B$26<>"Условия заполнены","",SUMIFS('График КС'!$B$5:$B$40,'График КС'!$A$5:$A$40,"<="&$A9)) | E9: =IF('Условия'!$B$26<>"Условия заполнены","",IF('Условия'!$B$25=0,0,IFERROR(MAX(0,MIN('Условия'!$B$23,IF('Условия'!$B$25=1,ROUND('Условия'!$B$23*$D9/'График КС'!$B$42,2),IF('Условия'!$B$25=2,IF($D9>='График КС'!$B$42,'Условия'!$B$23,0),ROUND('Условия'!$B$23*($D9-'Условия'!$B$9)/('График КС'!$B$42-'Условия'!$B$9),2))))),0))) | F9: =IF('Условия'!$B$26<>"Условия заполнены","",ROUND($E9-$E8,2)) | G9: =IF('Условия'!$B$26<>"Условия заполнены","",ROUND($B9*'Условия'!$B$13/100,2)) | H9: =IF('Условия'!$B$26<>"Условия заполнены","",ROUND($B9-$F9-$G9,2)) | I9: =IF('Условия'!$B$26<>"Условия заполнены","",IF($A9='Условия'!$B$7,'Условия'!$B$23,0)) | J9: =IF('Условия'!$B$26<>"Условия заполнены","",IFERROR(INDEX($H$5:$H$40,MATCH($A9-'Условия'!$B$17,$A$5:$A$40,0)),0)) | K9: =IF('Условия'!$B$26<>"Условия заполнены","",IF(AND('Условия'!$B$13>0,'Условия'!$B$14>0,$A9='Условия'!$B$14),ROUND(MIN(ROUND(SUM($G$5:$G$40)*'Условия'!$B$15/100,2),SUMIFS($G$5:$G$40,$A$5:$A$40,"<="&($A9-'Условия'!$B$17))),2),0)) | L9: =IF('Условия'!$B$26<>"Условия заполнены","",ROUND(IFERROR(INDEX($B$5:$B$40,MATCH($A9+'Условия'!$B$19,$A$5:$A$40,0)),0)*'Условия'!$B$18/100,2)+IF($A9=1,'Условия'!$B$20,0)+IF($A9='Условия'!$B$12,'Условия'!$B$24,0)) | M9: =IF('Условия'!$B$26<>"Условия заполнены","",ROUND($I9+$J9+$K9-$L9,2)) | N9: =IF('Условия'!$B$26<>"Условия заполнены","",ROUND($N8+$M9,2)) | O9: =IF('Условия'!$B$26<>"Условия заполнены","",IF($N9<0,$A9,"")) | P9: =IF('Условия'!$B$26<>"Условия заполнены","",IF($H9<-0.01,"ОШИБКА: погашение и удержание больше стоимости КС",IF(AND($F9>0.01,$A9<'Условия'!$B$7),"ОШИБКА: аванс погашается до поступления",IF(AND('Условия'!$B$13>0,'Условия'!$B$14>0,$A9='Условия'!$B$14,ROUND(SUM($G$5:$G$40)*'Условия'!$B$15/100,2)>SUMIFS($G$5:$G$40,$A$5:$A$40,"<="&($A9-'Условия'!$B$17))+0.01),"ОШИБКА: возврат больше накопленного удержания",""))))
A10: 6 | B10: =IF('Условия'!$B$26<>"Условия заполнены","",ROUND(IFERROR('Условия'!$B$5*INDEX('График КС'!$B$5:$B$40,MATCH($A10,'График КС'!$A$5:$A$40,0))/100,0),2)) | C10: =IF('Условия'!$B$26<>"Условия заполнены","",SUMIFS($B$5:$B$40,$A$5:$A$40,"<="&$A10)) | D10: =IF('Условия'!$B$26<>"Условия заполнены","",SUMIFS('График КС'!$B$5:$B$40,'График КС'!$A$5:$A$40,"<="&$A10)) | E10: =IF('Условия'!$B$26<>"Условия заполнены","",IF('Условия'!$B$25=0,0,IFERROR(MAX(0,MIN('Условия'!$B$23,IF('Условия'!$B$25=1,ROUND('Условия'!$B$23*$D10/'График КС'!$B$42,2),IF('Условия'!$B$25=2,IF($D10>='График КС'!$B$42,'Условия'!$B$23,0),ROUND('Условия'!$B$23*($D10-'Условия'!$B$9)/('График КС'!$B$42-'Условия'!$B$9),2))))),0))) | F10: =IF('Условия'!$B$26<>"Условия заполнены","",ROUND($E10-$E9,2)) | G10: =IF('Условия'!$B$26<>"Условия заполнены","",ROUND($B10*'Условия'!$B$13/100,2)) | H10: =IF('Условия'!$B$26<>"Условия заполнены","",ROUND($B10-$F10-$G10,2)) | I10: =IF('Условия'!$B$26<>"Условия заполнены","",IF($A10='Условия'!$B$7,'Условия'!$B$23,0)) | J10: =IF('Условия'!$B$26<>"Условия заполнены","",IFERROR(INDEX($H$5:$H$40,MATCH($A10-'Условия'!$B$17,$A$5:$A$40,0)),0)) | K10: =IF('Условия'!$B$26<>"Условия заполнены","",IF(AND('Условия'!$B$13>0,'Условия'!$B$14>0,$A10='Условия'!$B$14),ROUND(MIN(ROUND(SUM($G$5:$G$40)*'Условия'!$B$15/100,2),SUMIFS($G$5:$G$40,$A$5:$A$40,"<="&($A10-'Условия'!$B$17))),2),0)) | L10: =IF('Условия'!$B$26<>"Условия заполнены","",ROUND(IFERROR(INDEX($B$5:$B$40,MATCH($A10+'Условия'!$B$19,$A$5:$A$40,0)),0)*'Условия'!$B$18/100,2)+IF($A10=1,'Условия'!$B$20,0)+IF($A10='Условия'!$B$12,'Условия'!$B$24,0)) | M10: =IF('Условия'!$B$26<>"Условия заполнены","",ROUND($I10+$J10+$K10-$L10,2)) | N10: =IF('Условия'!$B$26<>"Условия заполнены","",ROUND($N9+$M10,2)) | O10: =IF('Условия'!$B$26<>"Условия заполнены","",IF($N10<0,$A10,"")) | P10: =IF('Условия'!$B$26<>"Условия заполнены","",IF($H10<-0.01,"ОШИБКА: погашение и удержание больше стоимости КС",IF(AND($F10>0.01,$A10<'Условия'!$B$7),"ОШИБКА: аванс погашается до поступления",IF(AND('Условия'!$B$13>0,'Условия'!$B$14>0,$A10='Условия'!$B$14,ROUND(SUM($G$5:$G$40)*'Условия'!$B$15/100,2)>SUMIFS($G$5:$G$40,$A$5:$A$40,"<="&($A10-'Условия'!$B$17))+0.01),"ОШИБКА: возврат больше накопленного удержания",""))))
A11: 7 | B11: =IF('Условия'!$B$26<>"Условия заполнены","",ROUND(IFERROR('Условия'!$B$5*INDEX('График КС'!$B$5:$B$40,MATCH($A11,'График КС'!$A$5:$A$40,0))/100,0),2)) | C11: =IF('Условия'!$B$26<>"Условия заполнены","",SUMIFS($B$5:$B$40,$A$5:$A$40,"<="&$A11)) | D11: =IF('Условия'!$B$26<>"Условия заполнены","",SUMIFS('График КС'!$B$5:$B$40,'График КС'!$A$5:$A$40,"<="&$A11)) | E11: =IF('Условия'!$B$26<>"Условия заполнены","",IF('Условия'!$B$25=0,0,IFERROR(MAX(0,MIN('Условия'!$B$23,IF('Условия'!$B$25=1,ROUND('Условия'!$B$23*$D11/'График КС'!$B$42,2),IF('Условия'!$B$25=2,IF($D11>='График КС'!$B$42,'Условия'!$B$23,0),ROUND('Условия'!$B$23*($D11-'Условия'!$B$9)/('График КС'!$B$42-'Условия'!$B$9),2))))),0))) | F11: =IF('Условия'!$B$26<>"Условия заполнены","",ROUND($E11-$E10,2)) | G11: =IF('Условия'!$B$26<>"Условия заполнены","",ROUND($B11*'Условия'!$B$13/100,2)) | H11: =IF('Условия'!$B$26<>"Условия заполнены","",ROUND($B11-$F11-$G11,2)) | I11: =IF('Условия'!$B$26<>"Условия заполнены","",IF($A11='Условия'!$B$7,'Условия'!$B$23,0)) | J11: =IF('Условия'!$B$26<>"Условия заполнены","",IFERROR(INDEX($H$5:$H$40,MATCH($A11-'Условия'!$B$17,$A$5:$A$40,0)),0)) | K11: =IF('Условия'!$B$26<>"Условия заполнены","",IF(AND('Условия'!$B$13>0,'Условия'!$B$14>0,$A11='Условия'!$B$14),ROUND(MIN(ROUND(SUM($G$5:$G$40)*'Условия'!$B$15/100,2),SUMIFS($G$5:$G$40,$A$5:$A$40,"<="&($A11-'Условия'!$B$17))),2),0)) | L11: =IF('Условия'!$B$26<>"Условия заполнены","",ROUND(IFERROR(INDEX($B$5:$B$40,MATCH($A11+'Условия'!$B$19,$A$5:$A$40,0)),0)*'Условия'!$B$18/100,2)+IF($A11=1,'Условия'!$B$20,0)+IF($A11='Условия'!$B$12,'Условия'!$B$24,0)) | M11: =IF('Условия'!$B$26<>"Условия заполнены","",ROUND($I11+$J11+$K11-$L11,2)) | N11: =IF('Условия'!$B$26<>"Условия заполнены","",ROUND($N10+$M11,2)) | O11: =IF('Условия'!$B$26<>"Условия заполнены","",IF($N11<0,$A11,"")) | P11: =IF('Условия'!$B$26<>"Условия заполнены","",IF($H11<-0.01,"ОШИБКА: погашение и удержание больше стоимости КС",IF(AND($F11>0.01,$A11<'Условия'!$B$7),"ОШИБКА: аванс погашается до поступления",IF(AND('Условия'!$B$13>0,'Условия'!$B$14>0,$A11='Условия'!$B$14,ROUND(SUM($G$5:$G$40)*'Условия'!$B$15/100,2)>SUMIFS($G$5:$G$40,$A$5:$A$40,"<="&($A11-'Условия'!$B$17))+0.01),"ОШИБКА: возврат больше накопленного удержания",""))))
A12: 8 | B12: =IF('Условия'!$B$26<>"Условия заполнены","",ROUND(IFERROR('Условия'!$B$5*INDEX('График КС'!$B$5:$B$40,MATCH($A12,'График КС'!$A$5:$A$40,0))/100,0),2)) | C12: =IF('Условия'!$B$26<>"Условия заполнены","",SUMIFS($B$5:$B$40,$A$5:$A$40,"<="&$A12)) | D12: =IF('Условия'!$B$26<>"Условия заполнены","",SUMIFS('График КС'!$B$5:$B$40,'График КС'!$A$5:$A$40,"<="&$A12)) | E12: =IF('Условия'!$B$26<>"Условия заполнены","",IF('Условия'!$B$25=0,0,IFERROR(MAX(0,MIN('Условия'!$B$23,IF('Условия'!$B$25=1,ROUND('Условия'!$B$23*$D12/'График КС'!$B$42,2),IF('Условия'!$B$25=2,IF($D12>='График КС'!$B$42,'Условия'!$B$23,0),ROUND('Условия'!$B$23*($D12-'Условия'!$B$9)/('График КС'!$B$42-'Условия'!$B$9),2))))),0))) | F12: =IF('Условия'!$B$26<>"Условия заполнены","",ROUND($E12-$E11,2)) | G12: =IF('Условия'!$B$26<>"Условия заполнены","",ROUND($B12*'Условия'!$B$13/100,2)) | H12: =IF('Условия'!$B$26<>"Условия заполнены","",ROUND($B12-$F12-$G12,2)) | I12: =IF('Условия'!$B$26<>"Условия заполнены","",IF($A12='Условия'!$B$7,'Условия'!$B$23,0)) | J12: =IF('Условия'!$B$26<>"Условия заполнены","",IFERROR(INDEX($H$5:$H$40,MATCH($A12-'Условия'!$B$17,$A$5:$A$40,0)),0)) | K12: =IF('Условия'!$B$26<>"Условия заполнены","",IF(AND('Условия'!$B$13>0,'Условия'!$B$14>0,$A12='Условия'!$B$14),ROUND(MIN(ROUND(SUM($G$5:$G$40)*'Условия'!$B$15/100,2),SUMIFS($G$5:$G$40,$A$5:$A$40,"<="&($A12-'Условия'!$B$17))),2),0)) | L12: =IF('Условия'!$B$26<>"Условия заполнены","",ROUND(IFERROR(INDEX($B$5:$B$40,MATCH($A12+'Условия'!$B$19,$A$5:$A$40,0)),0)*'Условия'!$B$18/100,2)+IF($A12=1,'Условия'!$B$20,0)+IF($A12='Условия'!$B$12,'Условия'!$B$24,0)) | M12: =IF('Условия'!$B$26<>"Условия заполнены","",ROUND($I12+$J12+$K12-$L12,2)) | N12: =IF('Условия'!$B$26<>"Условия заполнены","",ROUND($N11+$M12,2)) | O12: =IF('Условия'!$B$26<>"Условия заполнены","",IF($N12<0,$A12,"")) | P12: =IF('Условия'!$B$26<>"Условия заполнены","",IF($H12<-0.01,"ОШИБКА: погашение и удержание больше стоимости КС",IF(AND($F12>0.01,$A12<'Условия'!$B$7),"ОШИБКА: аванс погашается до поступления",IF(AND('Условия'!$B$13>0,'Условия'!$B$14>0,$A12='Условия'!$B$14,ROUND(SUM($G$5:$G$40)*'Условия'!$B$15/100,2)>SUMIFS($G$5:$G$40,$A$5:$A$40,"<="&($A12-'Условия'!$B$17))+0.01),"ОШИБКА: возврат больше накопленного удержания",""))))
A13: 9 | B13: =IF('Условия'!$B$26<>"Условия заполнены","",ROUND(IFERROR('Условия'!$B$5*INDEX('График КС'!$B$5:$B$40,MATCH($A13,'График КС'!$A$5:$A$40,0))/100,0),2)) | C13: =IF('Условия'!$B$26<>"Условия заполнены","",SUMIFS($B$5:$B$40,$A$5:$A$40,"<="&$A13)) | D13: =IF('Условия'!$B$26<>"Условия заполнены","",SUMIFS('График КС'!$B$5:$B$40,'График КС'!$A$5:$A$40,"<="&$A13)) | E13: =IF('Условия'!$B$26<>"Условия заполнены","",IF('Условия'!$B$25=0,0,IFERROR(MAX(0,MIN('Условия'!$B$23,IF('Условия'!$B$25=1,ROUND('Условия'!$B$23*$D13/'График КС'!$B$42,2),IF('Условия'!$B$25=2,IF($D13>='График КС'!$B$42,'Условия'!$B$23,0),ROUND('Условия'!$B$23*($D13-'Условия'!$B$9)/('График КС'!$B$42-'Условия'!$B$9),2))))),0))) | F13: =IF('Условия'!$B$26<>"Условия заполнены","",ROUND($E13-$E12,2)) | G13: =IF('Условия'!$B$26<>"Условия заполнены","",ROUND($B13*'Условия'!$B$13/100,2)) | H13: =IF('Условия'!$B$26<>"Условия заполнены","",ROUND($B13-$F13-$G13,2)) | I13: =IF('Условия'!$B$26<>"Условия заполнены","",IF($A13='Условия'!$B$7,'Условия'!$B$23,0)) | J13: =IF('Условия'!$B$26<>"Условия заполнены","",IFERROR(INDEX($H$5:$H$40,MATCH($A13-'Условия'!$B$17,$A$5:$A$40,0)),0)) | K13: =IF('Условия'!$B$26<>"Условия заполнены","",IF(AND('Условия'!$B$13>0,'Условия'!$B$14>0,$A13='Условия'!$B$14),ROUND(MIN(ROUND(SUM($G$5:$G$40)*'Условия'!$B$15/100,2),SUMIFS($G$5:$G$40,$A$5:$A$40,"<="&($A13-'Условия'!$B$17))),2),0)) | L13: =IF('Условия'!$B$26<>"Условия заполнены","",ROUND(IFERROR(INDEX($B$5:$B$40,MATCH($A13+'Условия'!$B$19,$A$5:$A$40,0)),0)*'Условия'!$B$18/100,2)+IF($A13=1,'Условия'!$B$20,0)+IF($A13='Условия'!$B$12,'Условия'!$B$24,0)) | M13: =IF('Условия'!$B$26<>"Условия заполнены","",ROUND($I13+$J13+$K13-$L13,2)) | N13: =IF('Условия'!$B$26<>"Условия заполнены","",ROUND($N12+$M13,2)) | O13: =IF('Условия'!$B$26<>"Условия заполнены","",IF($N13<0,$A13,"")) | P13: =IF('Условия'!$B$26<>"Условия заполнены","",IF($H13<-0.01,"ОШИБКА: погашение и удержание больше стоимости КС",IF(AND($F13>0.01,$A13<'Условия'!$B$7),"ОШИБКА: аванс погашается до поступления",IF(AND('Условия'!$B$13>0,'Условия'!$B$14>0,$A13='Условия'!$B$14,ROUND(SUM($G$5:$G$40)*'Условия'!$B$15/100,2)>SUMIFS($G$5:$G$40,$A$5:$A$40,"<="&($A13-'Условия'!$B$17))+0.01),"ОШИБКА: возврат больше накопленного удержания",""))))
A14: 10 | B14: =IF('Условия'!$B$26<>"Условия заполнены","",ROUND(IFERROR('Условия'!$B$5*INDEX('График КС'!$B$5:$B$40,MATCH($A14,'График КС'!$A$5:$A$40,0))/100,0),2)) | C14: =IF('Условия'!$B$26<>"Условия заполнены","",SUMIFS($B$5:$B$40,$A$5:$A$40,"<="&$A14)) | D14: =IF('Условия'!$B$26<>"Условия заполнены","",SUMIFS('График КС'!$B$5:$B$40,'График КС'!$A$5:$A$40,"<="&$A14)) | E14: =IF('Условия'!$B$26<>"Условия заполнены","",IF('Условия'!$B$25=0,0,IFERROR(MAX(0,MIN('Условия'!$B$23,IF('Условия'!$B$25=1,ROUND('Условия'!$B$23*$D14/'График КС'!$B$42,2),IF('Условия'!$B$25=2,IF($D14>='График КС'!$B$42,'Условия'!$B$23,0),ROUND('Условия'!$B$23*($D14-'Условия'!$B$9)/('График КС'!$B$42-'Условия'!$B$9),2))))),0))) | F14: =IF('Условия'!$B$26<>"Условия заполнены","",ROUND($E14-$E13,2)) | G14: =IF('Условия'!$B$26<>"Условия заполнены","",ROUND($B14*'Условия'!$B$13/100,2)) | H14: =IF('Условия'!$B$26<>"Условия заполнены","",ROUND($B14-$F14-$G14,2)) | I14: =IF('Условия'!$B$26<>"Условия заполнены","",IF($A14='Условия'!$B$7,'Условия'!$B$23,0)) | J14: =IF('Условия'!$B$26<>"Условия заполнены","",IFERROR(INDEX($H$5:$H$40,MATCH($A14-'Условия'!$B$17,$A$5:$A$40,0)),0)) | K14: =IF('Условия'!$B$26<>"Условия заполнены","",IF(AND('Условия'!$B$13>0,'Условия'!$B$14>0,$A14='Условия'!$B$14),ROUND(MIN(ROUND(SUM($G$5:$G$40)*'Условия'!$B$15/100,2),SUMIFS($G$5:$G$40,$A$5:$A$40,"<="&($A14-'Условия'!$B$17))),2),0)) | L14: =IF('Условия'!$B$26<>"Условия заполнены","",ROUND(IFERROR(INDEX($B$5:$B$40,MATCH($A14+'Условия'!$B$19,$A$5:$A$40,0)),0)*'Условия'!$B$18/100,2)+IF($A14=1,'Условия'!$B$20,0)+IF($A14='Условия'!$B$12,'Условия'!$B$24,0)) | M14: =IF('Условия'!$B$26<>"Условия заполнены","",ROUND($I14+$J14+$K14-$L14,2)) | N14: =IF('Условия'!$B$26<>"Условия заполнены","",ROUND($N13+$M14,2)) | O14: =IF('Условия'!$B$26<>"Условия заполнены","",IF($N14<0,$A14,"")) | P14: =IF('Условия'!$B$26<>"Условия заполнены","",IF($H14<-0.01,"ОШИБКА: погашение и удержание больше стоимости КС",IF(AND($F14>0.01,$A14<'Условия'!$B$7),"ОШИБКА: аванс погашается до поступления",IF(AND('Условия'!$B$13>0,'Условия'!$B$14>0,$A14='Условия'!$B$14,ROUND(SUM($G$5:$G$40)*'Условия'!$B$15/100,2)>SUMIFS($G$5:$G$40,$A$5:$A$40,"<="&($A14-'Условия'!$B$17))+0.01),"ОШИБКА: возврат больше накопленного удержания",""))))
A15: 11 | B15: =IF('Условия'!$B$26<>"Условия заполнены","",ROUND(IFERROR('Условия'!$B$5*INDEX('График КС'!$B$5:$B$40,MATCH($A15,'График КС'!$A$5:$A$40,0))/100,0),2)) | C15: =IF('Условия'!$B$26<>"Условия заполнены","",SUMIFS($B$5:$B$40,$A$5:$A$40,"<="&$A15)) | D15: =IF('Условия'!$B$26<>"Условия заполнены","",SUMIFS('График КС'!$B$5:$B$40,'График КС'!$A$5:$A$40,"<="&$A15)) | E15: =IF('Условия'!$B$26<>"Условия заполнены","",IF('Условия'!$B$25=0,0,IFERROR(MAX(0,MIN('Условия'!$B$23,IF('Условия'!$B$25=1,ROUND('Условия'!$B$23*$D15/'График КС'!$B$42,2),IF('Условия'!$B$25=2,IF($D15>='График КС'!$B$42,'Условия'!$B$23,0),ROUND('Условия'!$B$23*($D15-'Условия'!$B$9)/('График КС'!$B$42-'Условия'!$B$9),2))))),0))) | F15: =IF('Условия'!$B$26<>"Условия заполнены","",ROUND($E15-$E14,2)) | G15: =IF('Условия'!$B$26<>"Условия заполнены","",ROUND($B15*'Условия'!$B$13/100,2)) | H15: =IF('Условия'!$B$26<>"Условия заполнены","",ROUND($B15-$F15-$G15,2)) | I15: =IF('Условия'!$B$26<>"Условия заполнены","",IF($A15='Условия'!$B$7,'Условия'!$B$23,0)) | J15: =IF('Условия'!$B$26<>"Условия заполнены","",IFERROR(INDEX($H$5:$H$40,MATCH($A15-'Условия'!$B$17,$A$5:$A$40,0)),0)) | K15: =IF('Условия'!$B$26<>"Условия заполнены","",IF(AND('Условия'!$B$13>0,'Условия'!$B$14>0,$A15='Условия'!$B$14),ROUND(MIN(ROUND(SUM($G$5:$G$40)*'Условия'!$B$15/100,2),SUMIFS($G$5:$G$40,$A$5:$A$40,"<="&($A15-'Условия'!$B$17))),2),0)) | L15: =IF('Условия'!$B$26<>"Условия заполнены","",ROUND(IFERROR(INDEX($B$5:$B$40,MATCH($A15+'Условия'!$B$19,$A$5:$A$40,0)),0)*'Условия'!$B$18/100,2)+IF($A15=1,'Условия'!$B$20,0)+IF($A15='Условия'!$B$12,'Условия'!$B$24,0)) | M15: =IF('Условия'!$B$26<>"Условия заполнены","",ROUND($I15+$J15+$K15-$L15,2)) | N15: =IF('Условия'!$B$26<>"Условия заполнены","",ROUND($N14+$M15,2)) | O15: =IF('Условия'!$B$26<>"Условия заполнены","",IF($N15<0,$A15,"")) | P15: =IF('Условия'!$B$26<>"Условия заполнены","",IF($H15<-0.01,"ОШИБКА: погашение и удержание больше стоимости КС",IF(AND($F15>0.01,$A15<'Условия'!$B$7),"ОШИБКА: аванс погашается до поступления",IF(AND('Условия'!$B$13>0,'Условия'!$B$14>0,$A15='Условия'!$B$14,ROUND(SUM($G$5:$G$40)*'Условия'!$B$15/100,2)>SUMIFS($G$5:$G$40,$A$5:$A$40,"<="&($A15-'Условия'!$B$17))+0.01),"ОШИБКА: возврат больше накопленного удержания",""))))
A16: 12 | B16: =IF('Условия'!$B$26<>"Условия заполнены","",ROUND(IFERROR('Условия'!$B$5*INDEX('График КС'!$B$5:$B$40,MATCH($A16,'График КС'!$A$5:$A$40,0))/100,0),2)) | C16: =IF('Условия'!$B$26<>"Условия заполнены","",SUMIFS($B$5:$B$40,$A$5:$A$40,"<="&$A16)) | D16: =IF('Условия'!$B$26<>"Условия заполнены","",SUMIFS('График КС'!$B$5:$B$40,'График КС'!$A$5:$A$40,"<="&$A16)) | E16: =IF('Условия'!$B$26<>"Условия заполнены","",IF('Условия'!$B$25=0,0,IFERROR(MAX(0,MIN('Условия'!$B$23,IF('Условия'!$B$25=1,ROUND('Условия'!$B$23*$D16/'График КС'!$B$42,2),IF('Условия'!$B$25=2,IF($D16>='График КС'!$B$42,'Условия'!$B$23,0),ROUND('Условия'!$B$23*($D16-'Условия'!$B$9)/('График КС'!$B$42-'Условия'!$B$9),2))))),0))) | F16: =IF('Условия'!$B$26<>"Условия заполнены","",ROUND($E16-$E15,2)) | G16: =IF('Условия'!$B$26<>"Условия заполнены","",ROUND($B16*'Условия'!$B$13/100,2)) | H16: =IF('Условия'!$B$26<>"Условия заполнены","",ROUND($B16-$F16-$G16,2)) | I16: =IF('Условия'!$B$26<>"Условия заполнены","",IF($A16='Условия'!$B$7,'Условия'!$B$23,0)) | J16: =IF('Условия'!$B$26<>"Условия заполнены","",IFERROR(INDEX($H$5:$H$40,MATCH($A16-'Условия'!$B$17,$A$5:$A$40,0)),0)) | K16: =IF('Условия'!$B$26<>"Условия заполнены","",IF(AND('Условия'!$B$13>0,'Условия'!$B$14>0,$A16='Условия'!$B$14),ROUND(MIN(ROUND(SUM($G$5:$G$40)*'Условия'!$B$15/100,2),SUMIFS($G$5:$G$40,$A$5:$A$40,"<="&($A16-'Условия'!$B$17))),2),0)) | L16: =IF('Условия'!$B$26<>"Условия заполнены","",ROUND(IFERROR(INDEX($B$5:$B$40,MATCH($A16+'Условия'!$B$19,$A$5:$A$40,0)),0)*'Условия'!$B$18/100,2)+IF($A16=1,'Условия'!$B$20,0)+IF($A16='Условия'!$B$12,'Условия'!$B$24,0)) | M16: =IF('Условия'!$B$26<>"Условия заполнены","",ROUND($I16+$J16+$K16-$L16,2)) | N16: =IF('Условия'!$B$26<>"Условия заполнены","",ROUND($N15+$M16,2)) | O16: =IF('Условия'!$B$26<>"Условия заполнены","",IF($N16<0,$A16,"")) | P16: =IF('Условия'!$B$26<>"Условия заполнены","",IF($H16<-0.01,"ОШИБКА: погашение и удержание больше стоимости КС",IF(AND($F16>0.01,$A16<'Условия'!$B$7),"ОШИБКА: аванс погашается до поступления",IF(AND('Условия'!$B$13>0,'Условия'!$B$14>0,$A16='Условия'!$B$14,ROUND(SUM($G$5:$G$40)*'Условия'!$B$15/100,2)>SUMIFS($G$5:$G$40,$A$5:$A$40,"<="&($A16-'Условия'!$B$17))+0.01),"ОШИБКА: возврат больше накопленного удержания",""))))
A17: 13 | B17: =IF('Условия'!$B$26<>"Условия заполнены","",ROUND(IFERROR('Условия'!$B$5*INDEX('График КС'!$B$5:$B$40,MATCH($A17,'График КС'!$A$5:$A$40,0))/100,0),2)) | C17: =IF('Условия'!$B$26<>"Условия заполнены","",SUMIFS($B$5:$B$40,$A$5:$A$40,"<="&$A17)) | D17: =IF('Условия'!$B$26<>"Условия заполнены","",SUMIFS('График КС'!$B$5:$B$40,'График КС'!$A$5:$A$40,"<="&$A17)) | E17: =IF('Условия'!$B$26<>"Условия заполнены","",IF('Условия'!$B$25=0,0,IFERROR(MAX(0,MIN('Условия'!$B$23,IF('Условия'!$B$25=1,ROUND('Условия'!$B$23*$D17/'График КС'!$B$42,2),IF('Условия'!$B$25=2,IF($D17>='График КС'!$B$42,'Условия'!$B$23,0),ROUND('Условия'!$B$23*($D17-'Условия'!$B$9)/('График КС'!$B$42-'Условия'!$B$9),2))))),0))) | F17: =IF('Условия'!$B$26<>"Условия заполнены","",ROUND($E17-$E16,2)) | G17: =IF('Условия'!$B$26<>"Условия заполнены","",ROUND($B17*'Условия'!$B$13/100,2)) | H17: =IF('Условия'!$B$26<>"Условия заполнены","",ROUND($B17-$F17-$G17,2)) | I17: =IF('Условия'!$B$26<>"Условия заполнены","",IF($A17='Условия'!$B$7,'Условия'!$B$23,0)) | J17: =IF('Условия'!$B$26<>"Условия заполнены","",IFERROR(INDEX($H$5:$H$40,MATCH($A17-'Условия'!$B$17,$A$5:$A$40,0)),0)) | K17: =IF('Условия'!$B$26<>"Условия заполнены","",IF(AND('Условия'!$B$13>0,'Условия'!$B$14>0,$A17='Условия'!$B$14),ROUND(MIN(ROUND(SUM($G$5:$G$40)*'Условия'!$B$15/100,2),SUMIFS($G$5:$G$40,$A$5:$A$40,"<="&($A17-'Условия'!$B$17))),2),0)) | L17: =IF('Условия'!$B$26<>"Условия заполнены","",ROUND(IFERROR(INDEX($B$5:$B$40,MATCH($A17+'Условия'!$B$19,$A$5:$A$40,0)),0)*'Условия'!$B$18/100,2)+IF($A17=1,'Условия'!$B$20,0)+IF($A17='Условия'!$B$12,'Условия'!$B$24,0)) | M17: =IF('Условия'!$B$26<>"Условия заполнены","",ROUND($I17+$J17+$K17-$L17,2)) | N17: =IF('Условия'!$B$26<>"Условия заполнены","",ROUND($N16+$M17,2)) | O17: =IF('Условия'!$B$26<>"Условия заполнены","",IF($N17<0,$A17,"")) | P17: =IF('Условия'!$B$26<>"Условия заполнены","",IF($H17<-0.01,"ОШИБКА: погашение и удержание больше стоимости КС",IF(AND($F17>0.01,$A17<'Условия'!$B$7),"ОШИБКА: аванс погашается до поступления",IF(AND('Условия'!$B$13>0,'Условия'!$B$14>0,$A17='Условия'!$B$14,ROUND(SUM($G$5:$G$40)*'Условия'!$B$15/100,2)>SUMIFS($G$5:$G$40,$A$5:$A$40,"<="&($A17-'Условия'!$B$17))+0.01),"ОШИБКА: возврат больше накопленного удержания",""))))
... A40: 36 | B40: =IF('Условия'!$B$26<>"Условия заполнены","",ROUND(IFERROR('Условия'!$B$5*INDEX('График КС'!$B$5:$B$40,MATCH($A40,'График КС'!$A$5:$A$40,0))/100,0),2)) | C40: =IF('Условия'!$B$26<>"Условия заполнены","",SUMIFS($B$5:$B$40,$A$5:$A$40,"<="&$A40)) | D40: =IF('Условия'!$B$26<>"Условия заполнены","",SUMIFS('График КС'!$B$5:$B$40,'График КС'!$A$5:$A$40,"<="&$A40)) | E40: =IF('Условия'!$B$26<>"Условия заполнены","",IF('Условия'!$B$25=0,0,IFERROR(MAX(0,MIN('Условия'!$B$23,IF('Условия'!$B$25=1,ROUND('Условия'!$B$23*$D40/'График КС'!$B$42,2),IF('Условия'!$B$25=2,IF($D40>='График КС'!$B$42,'Условия'!$B$23,0),ROUND('Условия'!$B$23*($D40-'Условия'!$B$9)/('График КС'!$B$42-'Условия'!$B$9),2))))),0))) | F40: =IF('Условия'!$B$26<>"Условия заполнены","",ROUND($E40-$E39,2)) | G40: =IF('Условия'!$B$26<>"Условия заполнены","",ROUND($B40*'Условия'!$B$13/100,2)) | H40: =IF('Условия'!$B$26<>"Условия заполнены","",ROUND($B40-$F40-$G40,2)) | I40: =IF('Условия'!$B$26<>"Условия заполнены","",IF($A40='Условия'!$B$7,'Условия'!$B$23,0)) | J40: =IF('Условия'!$B$26<>"Условия заполнены","",IFERROR(INDEX($H$5:$H$40,MATCH($A40-'Условия'!$B$17,$A$5:$A$40,0)),0)) | K40: =IF('Условия'!$B$26<>"Условия заполнены","",IF(AND('Условия'!$B$13>0,'Условия'!$B$14>0,$A40='Условия'!$B$14),ROUND(MIN(ROUND(SUM($G$5:$G$40)*'Условия'!$B$15/100,2),SUMIFS($G$5:$G$40,$A$5:$A$40,"<="&($A40-'Условия'!$B$17))),2),0)) | L40: =IF('Условия'!$B$26<>"Условия заполнены","",ROUND(IFERROR(INDEX($B$5:$B$40,MATCH($A40+'Условия'!$B$19,$A$5:$A$40,0)),0)*'Условия'!$B$18/100,2)+IF($A40=1,'Условия'!$B$20,0)+IF($A40='Условия'!$B$12,'Условия'!$B$24,0)) | M40: =IF('Условия'!$B$26<>"Условия заполнены","",ROUND($I40+$J40+$K40-$L40,2)) | N40: =IF('Условия'!$B$26<>"Условия заполнены","",ROUND($N39+$M40,2)) | O40: =IF('Условия'!$B$26<>"Условия заполнены","",IF($N40<0,$A40,"")) | P40: =IF('Условия'!$B$26<>"Условия заполнены","",IF($H40<-0.01,"ОШИБКА: погашение и удержание больше стоимости КС",IF(AND($F40>0.01,$A40<'Условия'!$B$7),"ОШИБКА: аванс погашается до поступления",IF(AND('Условия'!$B$13>0,'Условия'!$B$14>0,$A40='Условия'!$B$14,ROUND(SUM($G$5:$G$40)*'Условия'!$B$15/100,2)>SUMIFS($G$5:$G$40,$A$5:$A$40,"<="&($A40-'Условия'!$B$17))+0.01),"ОШИБКА: возврат больше накопленного удержания",""))))
A42: Итого | B42: =IF('Условия'!$B$26<>"Условия заполнены","",ROUND(SUM($B$5:$B$40),2)) | F42: =IF('Условия'!$B$26<>"Условия заполнены","",ROUND(SUM($F$5:$F$40),2)) | G42: =IF('Условия'!$B$26<>"Условия заполнены","",ROUND(SUM($G$5:$G$40),2)) | H42: =IF('Условия'!$B$26<>"Условия заполнены","",ROUND(SUM($H$5:$H$40),2)) | I42: =IF('Условия'!$B$26<>"Условия заполнены","",ROUND(SUM($I$5:$I$40),2)) | J42: =IF('Условия'!$B$26<>"Условия заполнены","",ROUND(SUM($J$5:$J$40),2)) | K42: =IF('Условия'!$B$26<>"Условия заполнены","",ROUND(SUM($K$5:$K$40),2)) | L42: =IF('Условия'!$B$26<>"Условия заполнены","",ROUND(SUM($L$5:$L$40),2)) | M42: =IF('Условия'!$B$26<>"Условия заполнены","",ROUND(SUM($M$5:$M$40),2)) | N42: =IF('Условия'!$B$26<>"Условия заполнены","",$N$40) | P42: Итог колонки «Накопленный остаток» — это остаток последнего месяца, а не сумма колонки.

Sheet Профиль Б
A1: Кассовый профиль по объекту — сценарий Б
A2: Помесячные денежные потоки. Колонка P показывает противоречия по срокам и суммам; при них итог сравнения блокируется. Возврат удержания ограничен суммой, накопленной к плановой дате оплаты КС.
A4: Месяц | B4: Выполнено за месяц, руб. | C4: Накопленный объём, руб. | D4: Накопленная доля, % | E4: Погашено аванса нарастающим, руб. | F4: Погашение аванса за месяц, руб. | G4: Гарантийное удержание за месяц, руб. | H4: Начислено к оплате за месяц, руб. | I4: Поступление аванса, руб. | J4: Оплата КС с отсрочкой, руб. | K4: Возврат гарантийного удержания, руб. | L4: Расходы за месяц, руб. | M4: Сальдо месяца, руб. | N4: Накопленный остаток, руб. | O4: Отрицательный остаток | P4: Проверка
A5: 1 | B5: =IF('Условия'!$C$26<>"Условия заполнены","",ROUND(IFERROR('Условия'!$C$5*INDEX('График КС'!$C$5:$C$40,MATCH($A5,'График КС'!$A$5:$A$40,0))/100,0),2)) | C5: =IF('Условия'!$C$26<>"Условия заполнены","",SUMIFS($B$5:$B$40,$A$5:$A$40,"<="&$A5)) | D5: =IF('Условия'!$C$26<>"Условия заполнены","",SUMIFS('График КС'!$C$5:$C$40,'График КС'!$A$5:$A$40,"<="&$A5)) | E5: =IF('Условия'!$C$26<>"Условия заполнены","",IF('Условия'!$C$25=0,0,IFERROR(MAX(0,MIN('Условия'!$C$23,IF('Условия'!$C$25=1,ROUND('Условия'!$C$23*$D5/'График КС'!$C$42,2),IF('Условия'!$C$25=2,IF($D5>='График КС'!$C$42,'Условия'!$C$23,0),ROUND('Условия'!$C$23*($D5-'Условия'!$C$9)/('График КС'!$C$42-'Условия'!$C$9),2))))),0))) | F5: =IF('Условия'!$C$26<>"Условия заполнены","",ROUND($E5,2)) | G5: =IF('Условия'!$C$26<>"Условия заполнены","",ROUND($B5*'Условия'!$C$13/100,2)) | H5: =IF('Условия'!$C$26<>"Условия заполнены","",ROUND($B5-$F5-$G5,2)) | I5: =IF('Условия'!$C$26<>"Условия заполнены","",IF($A5='Условия'!$C$7,'Условия'!$C$23,0)) | J5: =IF('Условия'!$C$26<>"Условия заполнены","",IFERROR(INDEX($H$5:$H$40,MATCH($A5-'Условия'!$C$17,$A$5:$A$40,0)),0)) | K5: =IF('Условия'!$C$26<>"Условия заполнены","",IF(AND('Условия'!$C$13>0,'Условия'!$C$14>0,$A5='Условия'!$C$14),ROUND(MIN(ROUND(SUM($G$5:$G$40)*'Условия'!$C$15/100,2),SUMIFS($G$5:$G$40,$A$5:$A$40,"<="&($A5-'Условия'!$C$17))),2),0)) | L5: =IF('Условия'!$C$26<>"Условия заполнены","",ROUND(SUMIFS($B$5:$B$40,$A$5:$A$40,"<="&($A5+'Условия'!$C$19))*'Условия'!$C$18/100,2)+IF($A5=1,'Условия'!$C$20,0)+IF($A5='Условия'!$C$12,'Условия'!$C$24,0)) | M5: =IF('Условия'!$C$26<>"Условия заполнены","",ROUND($I5+$J5+$K5-$L5,2)) | N5: =IF('Условия'!$C$26<>"Условия заполнены","",ROUND($M5,2)) | O5: =IF('Условия'!$C$26<>"Условия заполнены","",IF($N5<0,$A5,"")) | P5: =IF('Условия'!$C$26<>"Условия заполнены","",IF($H5<-0.01,"ОШИБКА: погашение и удержание больше стоимости КС",IF(AND($F5>0.01,$A5<'Условия'!$C$7),"ОШИБКА: аванс погашается до поступления",IF(AND('Условия'!$C$13>0,'Условия'!$C$14>0,$A5='Условия'!$C$14,ROUND(SUM($G$5:$G$40)*'Условия'!$C$15/100,2)>SUMIFS($G$5:$G$40,$A$5:$A$40,"<="&($A5-'Условия'!$C$17))+0.01),"ОШИБКА: возврат больше накопленного удержания",""))))
A6: 2 | B6: =IF('Условия'!$C$26<>"Условия заполнены","",ROUND(IFERROR('Условия'!$C$5*INDEX('График КС'!$C$5:$C$40,MATCH($A6,'График КС'!$A$5:$A$40,0))/100,0),2)) | C6: =IF('Условия'!$C$26<>"Условия заполнены","",SUMIFS($B$5:$B$40,$A$5:$A$40,"<="&$A6)) | D6: =IF('Условия'!$C$26<>"Условия заполнены","",SUMIFS('График КС'!$C$5:$C$40,'График КС'!$A$5:$A$40,"<="&$A6)) | E6: =IF('Условия'!$C$26<>"Условия заполнены","",IF('Условия'!$C$25=0,0,IFERROR(MAX(0,MIN('Условия'!$C$23,IF('Условия'!$C$25=1,ROUND('Условия'!$C$23*$D6/'График КС'!$C$42,2),IF('Условия'!$C$25=2,IF($D6>='График КС'!$C$42,'Условия'!$C$23,0),ROUND('Условия'!$C$23*($D6-'Условия'!$C$9)/('График КС'!$C$42-'Условия'!$C$9),2))))),0))) | F6: =IF('Условия'!$C$26<>"Условия заполнены","",ROUND($E6-$E5,2)) | G6: =IF('Условия'!$C$26<>"Условия заполнены","",ROUND($B6*'Условия'!$C$13/100,2)) | H6: =IF('Условия'!$C$26<>"Условия заполнены","",ROUND($B6-$F6-$G6,2)) | I6: =IF('Условия'!$C$26<>"Условия заполнены","",IF($A6='Условия'!$C$7,'Условия'!$C$23,0)) | J6: =IF('Условия'!$C$26<>"Условия заполнены","",IFERROR(INDEX($H$5:$H$40,MATCH($A6-'Условия'!$C$17,$A$5:$A$40,0)),0)) | K6: =IF('Условия'!$C$26<>"Условия заполнены","",IF(AND('Условия'!$C$13>0,'Условия'!$C$14>0,$A6='Условия'!$C$14),ROUND(MIN(ROUND(SUM($G$5:$G$40)*'Условия'!$C$15/100,2),SUMIFS($G$5:$G$40,$A$5:$A$40,"<="&($A6-'Условия'!$C$17))),2),0)) | L6: =IF('Условия'!$C$26<>"Условия заполнены","",ROUND(IFERROR(INDEX($B$5:$B$40,MATCH($A6+'Условия'!$C$19,$A$5:$A$40,0)),0)*'Условия'!$C$18/100,2)+IF($A6=1,'Условия'!$C$20,0)+IF($A6='Условия'!$C$12,'Условия'!$C$24,0)) | M6: =IF('Условия'!$C$26<>"Условия заполнены","",ROUND($I6+$J6+$K6-$L6,2)) | N6: =IF('Условия'!$C$26<>"Условия заполнены","",ROUND($N5+$M6,2)) | O6: =IF('Условия'!$C$26<>"Условия заполнены","",IF($N6<0,$A6,"")) | P6: =IF('Условия'!$C$26<>"Условия заполнены","",IF($H6<-0.01,"ОШИБКА: погашение и удержание больше стоимости КС",IF(AND($F6>0.01,$A6<'Условия'!$C$7),"ОШИБКА: аванс погашается до поступления",IF(AND('Условия'!$C$13>0,'Условия'!$C$14>0,$A6='Условия'!$C$14,ROUND(SUM($G$5:$G$40)*'Условия'!$C$15/100,2)>SUMIFS($G$5:$G$40,$A$5:$A$40,"<="&($A6-'Условия'!$C$17))+0.01),"ОШИБКА: возврат больше накопленного удержания",""))))
A7: 3 | B7: =IF('Условия'!$C$26<>"Условия заполнены","",ROUND(IFERROR('Условия'!$C$5*INDEX('График КС'!$C$5:$C$40,MATCH($A7,'График КС'!$A$5:$A$40,0))/100,0),2)) | C7: =IF('Условия'!$C$26<>"Условия заполнены","",SUMIFS($B$5:$B$40,$A$5:$A$40,"<="&$A7)) | D7: =IF('Условия'!$C$26<>"Условия заполнены","",SUMIFS('График КС'!$C$5:$C$40,'График КС'!$A$5:$A$40,"<="&$A7)) | E7: =IF('Условия'!$C$26<>"Условия заполнены","",IF('Условия'!$C$25=0,0,IFERROR(MAX(0,MIN('Условия'!$C$23,IF('Условия'!$C$25=1,ROUND('Условия'!$C$23*$D7/'График КС'!$C$42,2),IF('Условия'!$C$25=2,IF($D7>='График КС'!$C$42,'Условия'!$C$23,0),ROUND('Условия'!$C$23*($D7-'Условия'!$C$9)/('График КС'!$C$42-'Условия'!$C$9),2))))),0))) | F7: =IF('Условия'!$C$26<>"Условия заполнены","",ROUND($E7-$E6,2)) | G7: =IF('Условия'!$C$26<>"Условия заполнены","",ROUND($B7*'Условия'!$C$13/100,2)) | H7: =IF('Условия'!$C$26<>"Условия заполнены","",ROUND($B7-$F7-$G7,2)) | I7: =IF('Условия'!$C$26<>"Условия заполнены","",IF($A7='Условия'!$C$7,'Условия'!$C$23,0)) | J7: =IF('Условия'!$C$26<>"Условия заполнены","",IFERROR(INDEX($H$5:$H$40,MATCH($A7-'Условия'!$C$17,$A$5:$A$40,0)),0)) | K7: =IF('Условия'!$C$26<>"Условия заполнены","",IF(AND('Условия'!$C$13>0,'Условия'!$C$14>0,$A7='Условия'!$C$14),ROUND(MIN(ROUND(SUM($G$5:$G$40)*'Условия'!$C$15/100,2),SUMIFS($G$5:$G$40,$A$5:$A$40,"<="&($A7-'Условия'!$C$17))),2),0)) | L7: =IF('Условия'!$C$26<>"Условия заполнены","",ROUND(IFERROR(INDEX($B$5:$B$40,MATCH($A7+'Условия'!$C$19,$A$5:$A$40,0)),0)*'Условия'!$C$18/100,2)+IF($A7=1,'Условия'!$C$20,0)+IF($A7='Условия'!$C$12,'Условия'!$C$24,0)) | M7: =IF('Условия'!$C$26<>"Условия заполнены","",ROUND($I7+$J7+$K7-$L7,2)) | N7: =IF('Условия'!$C$26<>"Условия заполнены","",ROUND($N6+$M7,2)) | O7: =IF('Условия'!$C$26<>"Условия заполнены","",IF($N7<0,$A7,"")) | P7: =IF('Условия'!$C$26<>"Условия заполнены","",IF($H7<-0.01,"ОШИБКА: погашение и удержание больше стоимости КС",IF(AND($F7>0.01,$A7<'Условия'!$C$7),"ОШИБКА: аванс погашается до поступления",IF(AND('Условия'!$C$13>0,'Условия'!$C$14>0,$A7='Условия'!$C$14,ROUND(SUM($G$5:$G$40)*'Условия'!$C$15/100,2)>SUMIFS($G$5:$G$40,$A$5:$A$40,"<="&($A7-'Условия'!$C$17))+0.01),"ОШИБКА: возврат больше накопленного удержания",""))))
A8: 4 | B8: =IF('Условия'!$C$26<>"Условия заполнены","",ROUND(IFERROR('Условия'!$C$5*INDEX('График КС'!$C$5:$C$40,MATCH($A8,'График КС'!$A$5:$A$40,0))/100,0),2)) | C8: =IF('Условия'!$C$26<>"Условия заполнены","",SUMIFS($B$5:$B$40,$A$5:$A$40,"<="&$A8)) | D8: =IF('Условия'!$C$26<>"Условия заполнены","",SUMIFS('График КС'!$C$5:$C$40,'График КС'!$A$5:$A$40,"<="&$A8)) | E8: =IF('Условия'!$C$26<>"Условия заполнены","",IF('Условия'!$C$25=0,0,IFERROR(MAX(0,MIN('Условия'!$C$23,IF('Условия'!$C$25=1,ROUND('Условия'!$C$23*$D8/'График КС'!$C$42,2),IF('Условия'!$C$25=2,IF($D8>='График КС'!$C$42,'Условия'!$C$23,0),ROUND('Условия'!$C$23*($D8-'Условия'!$C$9)/('График КС'!$C$42-'Условия'!$C$9),2))))),0))) | F8: =IF('Условия'!$C$26<>"Условия заполнены","",ROUND($E8-$E7,2)) | G8: =IF('Условия'!$C$26<>"Условия заполнены","",ROUND($B8*'Условия'!$C$13/100,2)) | H8: =IF('Условия'!$C$26<>"Условия заполнены","",ROUND($B8-$F8-$G8,2)) | I8: =IF('Условия'!$C$26<>"Условия заполнены","",IF($A8='Условия'!$C$7,'Условия'!$C$23,0)) | J8: =IF('Условия'!$C$26<>"Условия заполнены","",IFERROR(INDEX($H$5:$H$40,MATCH($A8-'Условия'!$C$17,$A$5:$A$40,0)),0)) | K8: =IF('Условия'!$C$26<>"Условия заполнены","",IF(AND('Условия'!$C$13>0,'Условия'!$C$14>0,$A8='Условия'!$C$14),ROUND(MIN(ROUND(SUM($G$5:$G$40)*'Условия'!$C$15/100,2),SUMIFS($G$5:$G$40,$A$5:$A$40,"<="&($A8-'Условия'!$C$17))),2),0)) | L8: =IF('Условия'!$C$26<>"Условия заполнены","",ROUND(IFERROR(INDEX($B$5:$B$40,MATCH($A8+'Условия'!$C$19,$A$5:$A$40,0)),0)*'Условия'!$C$18/100,2)+IF($A8=1,'Условия'!$C$20,0)+IF($A8='Условия'!$C$12,'Условия'!$C$24,0)) | M8: =IF('Условия'!$C$26<>"Условия заполнены","",ROUND($I8+$J8+$K8-$L8,2)) | N8: =IF('Условия'!$C$26<>"Условия заполнены","",ROUND($N7+$M8,2)) | O8: =IF('Условия'!$C$26<>"Условия заполнены","",IF($N8<0,$A8,"")) | P8: =IF('Условия'!$C$26<>"Условия заполнены","",IF($H8<-0.01,"ОШИБКА: погашение и удержание больше стоимости КС",IF(AND($F8>0.01,$A8<'Условия'!$C$7),"ОШИБКА: аванс погашается до поступления",IF(AND('Условия'!$C$13>0,'Условия'!$C$14>0,$A8='Условия'!$C$14,ROUND(SUM($G$5:$G$40)*'Условия'!$C$15/100,2)>SUMIFS($G$5:$G$40,$A$5:$A$40,"<="&($A8-'Условия'!$C$17))+0.01),"ОШИБКА: возврат больше накопленного удержания",""))))
A9: 5 | B9: =IF('Условия'!$C$26<>"Условия заполнены","",ROUND(IFERROR('Условия'!$C$5*INDEX('График КС'!$C$5:$C$40,MATCH($A9,'График КС'!$A$5:$A$40,0))/100,0),2)) | C9: =IF('Условия'!$C$26<>"Условия заполнены","",SUMIFS($B$5:$B$40,$A$5:$A$40,"<="&$A9)) | D9: =IF('Условия'!$C$26<>"Условия заполнены","",SUMIFS('График КС'!$C$5:$C$40,'График КС'!$A$5:$A$40,"<="&$A9)) | E9: =IF('Условия'!$C$26<>"Условия заполнены","",IF('Условия'!$C$25=0,0,IFERROR(MAX(0,MIN('Условия'!$C$23,IF('Условия'!$C$25=1,ROUND('Условия'!$C$23*$D9/'График КС'!$C$42,2),IF('Условия'!$C$25=2,IF($D9>='График КС'!$C$42,'Условия'!$C$23,0),ROUND('Условия'!$C$23*($D9-'Условия'!$C$9)/('График КС'!$C$42-'Условия'!$C$9),2))))),0))) | F9: =IF('Условия'!$C$26<>"Условия заполнены","",ROUND($E9-$E8,2)) | G9: =IF('Условия'!$C$26<>"Условия заполнены","",ROUND($B9*'Условия'!$C$13/100,2)) | H9: =IF('Условия'!$C$26<>"Условия заполнены","",ROUND($B9-$F9-$G9,2)) | I9: =IF('Условия'!$C$26<>"Условия заполнены","",IF($A9='Условия'!$C$7,'Условия'!$C$23,0)) | J9: =IF('Условия'!$C$26<>"Условия заполнены","",IFERROR(INDEX($H$5:$H$40,MATCH($A9-'Условия'!$C$17,$A$5:$A$40,0)),0)) | K9: =IF('Условия'!$C$26<>"Условия заполнены","",IF(AND('Условия'!$C$13>0,'Условия'!$C$14>0,$A9='Условия'!$C$14),ROUND(MIN(ROUND(SUM($G$5:$G$40)*'Условия'!$C$15/100,2),SUMIFS($G$5:$G$40,$A$5:$A$40,"<="&($A9-'Условия'!$C$17))),2),0)) | L9: =IF('Условия'!$C$26<>"Условия заполнены","",ROUND(IFERROR(INDEX($B$5:$B$40,MATCH($A9+'Условия'!$C$19,$A$5:$A$40,0)),0)*'Условия'!$C$18/100,2)+IF($A9=1,'Условия'!$C$20,0)+IF($A9='Условия'!$C$12,'Условия'!$C$24,0)) | M9: =IF('Условия'!$C$26<>"Условия заполнены","",ROUND($I9+$J9+$K9-$L9,2)) | N9: =IF('Условия'!$C$26<>"Условия заполнены","",ROUND($N8+$M9,2)) | O9: =IF('Условия'!$C$26<>"Условия заполнены","",IF($N9<0,$A9,"")) | P9: =IF('Условия'!$C$26<>"Условия заполнены","",IF($H9<-0.01,"ОШИБКА: погашение и удержание больше стоимости КС",IF(AND($F9>0.01,$A9<'Условия'!$C$7),"ОШИБКА: аванс погашается до поступления",IF(AND('Условия'!$C$13>0,'Условия'!$C$14>0,$A9='Условия'!$C$14,ROUND(SUM($G$5:$G$40)*'Условия'!$C$15/100,2)>SUMIFS($G$5:$G$40,$A$5:$A$40,"<="&($A9-'Условия'!$C$17))+0.01),"ОШИБКА: возврат больше накопленного удержания",""))))
A10: 6 | B10: =IF('Условия'!$C$26<>"Условия заполнены","",ROUND(IFERROR('Условия'!$C$5*INDEX('График КС'!$C$5:$C$40,MATCH($A10,'График КС'!$A$5:$A$40,0))/100,0),2)) | C10: =IF('Условия'!$C$26<>"Условия заполнены","",SUMIFS($B$5:$B$40,$A$5:$A$40,"<="&$A10)) | D10: =IF('Условия'!$C$26<>"Условия заполнены","",SUMIFS('График КС'!$C$5:$C$40,'График КС'!$A$5:$A$40,"<="&$A10)) | E10: =IF('Условия'!$C$26<>"Условия заполнены","",IF('Условия'!$C$25=0,0,IFERROR(MAX(0,MIN('Условия'!$C$23,IF('Условия'!$C$25=1,ROUND('Условия'!$C$23*$D10/'График КС'!$C$42,2),IF('Условия'!$C$25=2,IF($D10>='График КС'!$C$42,'Условия'!$C$23,0),ROUND('Условия'!$C$23*($D10-'Условия'!$C$9)/('График КС'!$C$42-'Условия'!$C$9),2))))),0))) | F10: =IF('Условия'!$C$26<>"Условия заполнены","",ROUND($E10-$E9,2)) | G10: =IF('Условия'!$C$26<>"Условия заполнены","",ROUND($B10*'Условия'!$C$13/100,2)) | H10: =IF('Условия'!$C$26<>"Условия заполнены","",ROUND($B10-$F10-$G10,2)) | I10: =IF('Условия'!$C$26<>"Условия заполнены","",IF($A10='Условия'!$C$7,'Условия'!$C$23,0)) | J10: =IF('Условия'!$C$26<>"Условия заполнены","",IFERROR(INDEX($H$5:$H$40,MATCH($A10-'Условия'!$C$17,$A$5:$A$40,0)),0)) | K10: =IF('Условия'!$C$26<>"Условия заполнены","",IF(AND('Условия'!$C$13>0,'Условия'!$C$14>0,$A10='Условия'!$C$14),ROUND(MIN(ROUND(SUM($G$5:$G$40)*'Условия'!$C$15/100,2),SUMIFS($G$5:$G$40,$A$5:$A$40,"<="&($A10-'Условия'!$C$17))),2),0)) | L10: =IF('Условия'!$C$26<>"Условия заполнены","",ROUND(IFERROR(INDEX($B$5:$B$40,MATCH($A10+'Условия'!$C$19,$A$5:$A$40,0)),0)*'Условия'!$C$18/100,2)+IF($A10=1,'Условия'!$C$20,0)+IF($A10='Условия'!$C$12,'Условия'!$C$24,0)) | M10: =IF('Условия'!$C$26<>"Условия заполнены","",ROUND($I10+$J10+$K10-$L10,2)) | N10: =IF('Условия'!$C$26<>"Условия заполнены","",ROUND($N9+$M10,2)) | O10: =IF('Условия'!$C$26<>"Условия заполнены","",IF($N10<0,$A10,"")) | P10: =IF('Условия'!$C$26<>"Условия заполнены","",IF($H10<-0.01,"ОШИБКА: погашение и удержание больше стоимости КС",IF(AND($F10>0.01,$A10<'Условия'!$C$7),"ОШИБКА: аванс погашается до поступления",IF(AND('Условия'!$C$13>0,'Условия'!$C$14>0,$A10='Условия'!$C$14,ROUND(SUM($G$5:$G$40)*'Условия'!$C$15/100,2)>SUMIFS($G$5:$G$40,$A$5:$A$40,"<="&($A10-'Условия'!$C$17))+0.01),"ОШИБКА: возврат больше накопленного удержания",""))))
