Workbook

Sheet Взаиморасчёты
A1: Реестр взаиморасчётов
A2: Одна строка — одна операция. Начисления вводите положительными суммами, оплаты и зачёты — тоже положительными: знак ставит тип операции. Каждая операция, влияющая на долг, относится к конкретному акту: идентификатор акта в колонке F должен совпадать со строкой листа «Долг по актам». Система не распределяет платежи между актами сама — очередность зачёта определяется назначением платежа и договором, и правовой вывод за вас никто не делает. Строк 500; записи ниже таблицы блокируют итог, а не отбрасываются.
A4: № | B4: Дата | C4: Тип операции | D4: Документ (№, дата) | E4: Сумма, руб. | F4: Акт (идентификатор, как в «Долг по актам») | G4: Влияние на бесспорный долг | H4: Спорная сумма (граница B2) | I4: Проверка строки | J4: Бесспорный долг нарастающим итогом | L4: Начислено по актам | M4: =SUMIF(C5:C504,"Начисление по акту",E5:E504)
A5: 1 | G5: =IF(OR(C5="",E5=""),0,IF(C5="Начисление по акту",E5,IF(OR(C5="Оплата",C5="Зачёт аванса по договору"),-E5,IF(C5="Корректировка (подписана обеими сторонами)",E5,0)))) | H5: =IF(OR(C5="Удержание",C5="Зачёт встречного требования",C5="Неустойка заявлена"),N(E5),0) | I5: =IF(AND(B5="",C5="",D5="",E5="",F5=""),"",IF(OR(B5="",C5="",E5=""),"БЛОК: нужны дата, тип операции и сумма",IF(N(E5)<=0,"БЛОК: сумма должна быть больше нуля",IF(AND(G5<>0,F5=""),"БЛОК: не указан акт — платёж не отнесён к конкретному акту. Распределите его документально (назначение платежа, соглашение, письмо) и укажите акт: без этого долг на первый день просрочки и проценты посчитать нельзя",IF(AND(F5<>"",COUNTIF('Долг по актам'!$B$5:$B$34,F5)=0),"БЛОК: такого акта нет на листе «Долг по актам» — добавьте акт или исправьте идентификатор",IF(SUMPRODUCT((($C$5:$C$504="Оплата")+($C$5:$C$504="Зачёт аванса по договору")>0)*($C$5:$C$504<>C5)*($E$5:$E$504=E5)*(($D$5:$D$504=D5)*(D5<>"")+($B$5:$B$504=B5)*(B5<>"")>0))>0,"БЛОК: двойной учёт аванса — эта сумма введена и как «Оплата», и как «Зачёт аванса по договору» с тем же документом или той же датой. Аванс, зачтённый в акт, учитывается один раз: оставьте одну операцию","ок")))))) | J5: =IF(AND(B5="",C5="",E5=""),"",SUM($G$5:G5)) | L5: Оплачено | M5: =SUMIF(C5:C504,"Оплата",E5:E504)
A6: 2 | G6: =IF(OR(C6="",E6=""),0,IF(C6="Начисление по акту",E6,IF(OR(C6="Оплата",C6="Зачёт аванса по договору"),-E6,IF(C6="Корректировка (подписана обеими сторонами)",E6,0)))) | H6: =IF(OR(C6="Удержание",C6="Зачёт встречного требования",C6="Неустойка заявлена"),N(E6),0) | I6: =IF(AND(B6="",C6="",D6="",E6="",F6=""),"",IF(OR(B6="",C6="",E6=""),"БЛОК: нужны дата, тип операции и сумма",IF(N(E6)<=0,"БЛОК: сумма должна быть больше нуля",IF(AND(G6<>0,F6=""),"БЛОК: не указан акт — платёж не отнесён к конкретному акту. Распределите его документально (назначение платежа, соглашение, письмо) и укажите акт: без этого долг на первый день просрочки и проценты посчитать нельзя",IF(AND(F6<>"",COUNTIF('Долг по актам'!$B$5:$B$34,F6)=0),"БЛОК: такого акта нет на листе «Долг по актам» — добавьте акт или исправьте идентификатор",IF(SUMPRODUCT((($C$5:$C$504="Оплата")+($C$5:$C$504="Зачёт аванса по договору")>0)*($C$5:$C$504<>C6)*($E$5:$E$504=E6)*(($D$5:$D$504=D6)*(D6<>"")+($B$5:$B$504=B6)*(B6<>"")>0))>0,"БЛОК: двойной учёт аванса — эта сумма введена и как «Оплата», и как «Зачёт аванса по договору» с тем же документом или той же датой. Аванс, зачтённый в акт, учитывается один раз: оставьте одну операцию","ок")))))) | J6: =IF(AND(B6="",C6="",E6=""),"",SUM($G$5:G6)) | L6: Зачтён аванс | M6: =SUMIF(C5:C504,"Зачёт аванса по договору",E5:E504)
A7: 3 | G7: =IF(OR(C7="",E7=""),0,IF(C7="Начисление по акту",E7,IF(OR(C7="Оплата",C7="Зачёт аванса по договору"),-E7,IF(C7="Корректировка (подписана обеими сторонами)",E7,0)))) | H7: =IF(OR(C7="Удержание",C7="Зачёт встречного требования",C7="Неустойка заявлена"),N(E7),0) | I7: =IF(AND(B7="",C7="",D7="",E7="",F7=""),"",IF(OR(B7="",C7="",E7=""),"БЛОК: нужны дата, тип операции и сумма",IF(N(E7)<=0,"БЛОК: сумма должна быть больше нуля",IF(AND(G7<>0,F7=""),"БЛОК: не указан акт — платёж не отнесён к конкретному акту. Распределите его документально (назначение платежа, соглашение, письмо) и укажите акт: без этого долг на первый день просрочки и проценты посчитать нельзя",IF(AND(F7<>"",COUNTIF('Долг по актам'!$B$5:$B$34,F7)=0),"БЛОК: такого акта нет на листе «Долг по актам» — добавьте акт или исправьте идентификатор",IF(SUMPRODUCT((($C$5:$C$504="Оплата")+($C$5:$C$504="Зачёт аванса по договору")>0)*($C$5:$C$504<>C7)*($E$5:$E$504=E7)*(($D$5:$D$504=D7)*(D7<>"")+($B$5:$B$504=B7)*(B7<>"")>0))>0,"БЛОК: двойной учёт аванса — эта сумма введена и как «Оплата», и как «Зачёт аванса по договору» с тем же документом или той же датой. Аванс, зачтённый в акт, учитывается один раз: оставьте одну операцию","ок")))))) | J7: =IF(AND(B7="",C7="",E7=""),"",SUM($G$5:G7)) | L7: Корректировки | M7: =SUMIF(C5:C504,"Корректировка (подписана обеими сторонами)",E5:E504)
A8: 4 | G8: =IF(OR(C8="",E8=""),0,IF(C8="Начисление по акту",E8,IF(OR(C8="Оплата",C8="Зачёт аванса по договору"),-E8,IF(C8="Корректировка (подписана обеими сторонами)",E8,0)))) | H8: =IF(OR(C8="Удержание",C8="Зачёт встречного требования",C8="Неустойка заявлена"),N(E8),0) | I8: =IF(AND(B8="",C8="",D8="",E8="",F8=""),"",IF(OR(B8="",C8="",E8=""),"БЛОК: нужны дата, тип операции и сумма",IF(N(E8)<=0,"БЛОК: сумма должна быть больше нуля",IF(AND(G8<>0,F8=""),"БЛОК: не указан акт — платёж не отнесён к конкретному акту. Распределите его документально (назначение платежа, соглашение, письмо) и укажите акт: без этого долг на первый день просрочки и проценты посчитать нельзя",IF(AND(F8<>"",COUNTIF('Долг по актам'!$B$5:$B$34,F8)=0),"БЛОК: такого акта нет на листе «Долг по актам» — добавьте акт или исправьте идентификатор",IF(SUMPRODUCT((($C$5:$C$504="Оплата")+($C$5:$C$504="Зачёт аванса по договору")>0)*($C$5:$C$504<>C8)*($E$5:$E$504=E8)*(($D$5:$D$504=D8)*(D8<>"")+($B$5:$B$504=B8)*(B8<>"")>0))>0,"БЛОК: двойной учёт аванса — эта сумма введена и как «Оплата», и как «Зачёт аванса по договору» с тем же документом или той же датой. Аванс, зачтённый в акт, учитывается один раз: оставьте одну операцию","ок")))))) | J8: =IF(AND(B8="",C8="",E8=""),"",SUM($G$5:G8)) | L8: Спорные операции (удержание, зачёт, неустойка) | M8: =SUM(H5:H504)
A9: 5 | G9: =IF(OR(C9="",E9=""),0,IF(C9="Начисление по акту",E9,IF(OR(C9="Оплата",C9="Зачёт аванса по договору"),-E9,IF(C9="Корректировка (подписана обеими сторонами)",E9,0)))) | H9: =IF(OR(C9="Удержание",C9="Зачёт встречного требования",C9="Неустойка заявлена"),N(E9),0) | I9: =IF(AND(B9="",C9="",D9="",E9="",F9=""),"",IF(OR(B9="",C9="",E9=""),"БЛОК: нужны дата, тип операции и сумма",IF(N(E9)<=0,"БЛОК: сумма должна быть больше нуля",IF(AND(G9<>0,F9=""),"БЛОК: не указан акт — платёж не отнесён к конкретному акту. Распределите его документально (назначение платежа, соглашение, письмо) и укажите акт: без этого долг на первый день просрочки и проценты посчитать нельзя",IF(AND(F9<>"",COUNTIF('Долг по актам'!$B$5:$B$34,F9)=0),"БЛОК: такого акта нет на листе «Долг по актам» — добавьте акт или исправьте идентификатор",IF(SUMPRODUCT((($C$5:$C$504="Оплата")+($C$5:$C$504="Зачёт аванса по договору")>0)*($C$5:$C$504<>C9)*($E$5:$E$504=E9)*(($D$5:$D$504=D9)*(D9<>"")+($B$5:$B$504=B9)*(B9<>"")>0))>0,"БЛОК: двойной учёт аванса — эта сумма введена и как «Оплата», и как «Зачёт аванса по договору» с тем же документом или той же датой. Аванс, зачтённый в акт, учитывается один раз: оставьте одну операцию","ок")))))) | J9: =IF(AND(B9="",C9="",E9=""),"",SUM($G$5:G9)) | L9: Операций ниже таблицы (не учтены) | M9: =COUNTA(A505:J3000)
A10: 6 | G10: =IF(OR(C10="",E10=""),0,IF(C10="Начисление по акту",E10,IF(OR(C10="Оплата",C10="Зачёт аванса по договору"),-E10,IF(C10="Корректировка (подписана обеими сторонами)",E10,0)))) | H10: =IF(OR(C10="Удержание",C10="Зачёт встречного требования",C10="Неустойка заявлена"),N(E10),0) | I10: =IF(AND(B10="",C10="",D10="",E10="",F10=""),"",IF(OR(B10="",C10="",E10=""),"БЛОК: нужны дата, тип операции и сумма",IF(N(E10)<=0,"БЛОК: сумма должна быть больше нуля",IF(AND(G10<>0,F10=""),"БЛОК: не указан акт — платёж не отнесён к конкретному акту. Распределите его документально (назначение платежа, соглашение, письмо) и укажите акт: без этого долг на первый день просрочки и проценты посчитать нельзя",IF(AND(F10<>"",COUNTIF('Долг по актам'!$B$5:$B$34,F10)=0),"БЛОК: такого акта нет на листе «Долг по актам» — добавьте акт или исправьте идентификатор",IF(SUMPRODUCT((($C$5:$C$504="Оплата")+($C$5:$C$504="Зачёт аванса по договору")>0)*($C$5:$C$504<>C10)*($E$5:$E$504=E10)*(($D$5:$D$504=D10)*(D10<>"")+($B$5:$B$504=B10)*(B10<>"")>0))>0,"БЛОК: двойной учёт аванса — эта сумма введена и как «Оплата», и как «Зачёт аванса по договору» с тем же документом или той же датой. Аванс, зачтённый в акт, учитывается один раз: оставьте одну операцию","ок")))))) | J10: =IF(AND(B10="",C10="",E10=""),"",SUM($G$5:G10)) | L10: ТЕКУЩИЙ БЕССПОРНЫЙ ДОЛГ, руб. | M10: =IF(OR(M9>0,M12>0,M13>0),"ИТОГ ЗАБЛОКИРОВАН: см. колонку «Проверка строки» и строки свода",M4-M5-M6+M7)
A11: 7 | G11: =IF(OR(C11="",E11=""),0,IF(C11="Начисление по акту",E11,IF(OR(C11="Оплата",C11="Зачёт аванса по договору"),-E11,IF(C11="Корректировка (подписана обеими сторонами)",E11,0)))) | H11: =IF(OR(C11="Удержание",C11="Зачёт встречного требования",C11="Неустойка заявлена"),N(E11),0) | I11: =IF(AND(B11="",C11="",D11="",E11="",F11=""),"",IF(OR(B11="",C11="",E11=""),"БЛОК: нужны дата, тип операции и сумма",IF(N(E11)<=0,"БЛОК: сумма должна быть больше нуля",IF(AND(G11<>0,F11=""),"БЛОК: не указан акт — платёж не отнесён к конкретному акту. Распределите его документально (назначение платежа, соглашение, письмо) и укажите акт: без этого долг на первый день просрочки и проценты посчитать нельзя",IF(AND(F11<>"",COUNTIF('Долг по актам'!$B$5:$B$34,F11)=0),"БЛОК: такого акта нет на листе «Долг по актам» — добавьте акт или исправьте идентификатор",IF(SUMPRODUCT((($C$5:$C$504="Оплата")+($C$5:$C$504="Зачёт аванса по договору")>0)*($C$5:$C$504<>C11)*($E$5:$E$504=E11)*(($D$5:$D$504=D11)*(D11<>"")+($B$5:$B$504=B11)*(B11<>"")>0))>0,"БЛОК: двойной учёт аванса — эта сумма введена и как «Оплата», и как «Зачёт аванса по договору» с тем же документом или той же датой. Аванс, зачтённый в акт, учитывается один раз: оставьте одну операцию","ок")))))) | J11: =IF(AND(B11="",C11="",E11=""),"",SUM($G$5:G11)) | L11: Граница | M11: =IF(M8>0,"ГРАНИЦА B2: спорные операции на сумму "&FIXED(M8,2)&" руб. — к специалисту","нет")
A12: 8 | G12: =IF(OR(C12="",E12=""),0,IF(C12="Начисление по акту",E12,IF(OR(C12="Оплата",C12="Зачёт аванса по договору"),-E12,IF(C12="Корректировка (подписана обеими сторонами)",E12,0)))) | H12: =IF(OR(C12="Удержание",C12="Зачёт встречного требования",C12="Неустойка заявлена"),N(E12),0) | I12: =IF(AND(B12="",C12="",D12="",E12="",F12=""),"",IF(OR(B12="",C12="",E12=""),"БЛОК: нужны дата, тип операции и сумма",IF(N(E12)<=0,"БЛОК: сумма должна быть больше нуля",IF(AND(G12<>0,F12=""),"БЛОК: не указан акт — платёж не отнесён к конкретному акту. Распределите его документально (назначение платежа, соглашение, письмо) и укажите акт: без этого долг на первый день просрочки и проценты посчитать нельзя",IF(AND(F12<>"",COUNTIF('Долг по актам'!$B$5:$B$34,F12)=0),"БЛОК: такого акта нет на листе «Долг по актам» — добавьте акт или исправьте идентификатор",IF(SUMPRODUCT((($C$5:$C$504="Оплата")+($C$5:$C$504="Зачёт аванса по договору")>0)*($C$5:$C$504<>C12)*($E$5:$E$504=E12)*(($D$5:$D$504=D12)*(D12<>"")+($B$5:$B$504=B12)*(B12<>"")>0))>0,"БЛОК: двойной учёт аванса — эта сумма введена и как «Оплата», и как «Зачёт аванса по договору» с тем же документом или той же датой. Аванс, зачтённый в акт, учитывается один раз: оставьте одну операцию","ок")))))) | J12: =IF(AND(B12="",C12="",E12=""),"",SUM($G$5:G12)) | L12: Операций без типа или суммы | M12: =SUMPRODUCT((B5:B504<>"")*(((C5:C504="")+(E5:E504=""))>0))
A13: 9 | G13: =IF(OR(C13="",E13=""),0,IF(C13="Начисление по акту",E13,IF(OR(C13="Оплата",C13="Зачёт аванса по договору"),-E13,IF(C13="Корректировка (подписана обеими сторонами)",E13,0)))) | H13: =IF(OR(C13="Удержание",C13="Зачёт встречного требования",C13="Неустойка заявлена"),N(E13),0) | I13: =IF(AND(B13="",C13="",D13="",E13="",F13=""),"",IF(OR(B13="",C13="",E13=""),"БЛОК: нужны дата, тип операции и сумма",IF(N(E13)<=0,"БЛОК: сумма должна быть больше нуля",IF(AND(G13<>0,F13=""),"БЛОК: не указан акт — платёж не отнесён к конкретному акту. Распределите его документально (назначение платежа, соглашение, письмо) и укажите акт: без этого долг на первый день просрочки и проценты посчитать нельзя",IF(AND(F13<>"",COUNTIF('Долг по актам'!$B$5:$B$34,F13)=0),"БЛОК: такого акта нет на листе «Долг по актам» — добавьте акт или исправьте идентификатор",IF(SUMPRODUCT((($C$5:$C$504="Оплата")+($C$5:$C$504="Зачёт аванса по договору")>0)*($C$5:$C$504<>C13)*($E$5:$E$504=E13)*(($D$5:$D$504=D13)*(D13<>"")+($B$5:$B$504=B13)*(B13<>"")>0))>0,"БЛОК: двойной учёт аванса — эта сумма введена и как «Оплата», и как «Зачёт аванса по договору» с тем же документом или той же датой. Аванс, зачтённый в акт, учитывается один раз: оставьте одну операцию","ок")))))) | J13: =IF(AND(B13="",C13="",E13=""),"",SUM($G$5:G13)) | L13: Строк с ошибкой в колонке «Проверка строки» | M13: =COUNTIF(I5:I504,"БЛОК*")
A14: 10 | G14: =IF(OR(C14="",E14=""),0,IF(C14="Начисление по акту",E14,IF(OR(C14="Оплата",C14="Зачёт аванса по договору"),-E14,IF(C14="Корректировка (подписана обеими сторонами)",E14,0)))) | H14: =IF(OR(C14="Удержание",C14="Зачёт встречного требования",C14="Неустойка заявлена"),N(E14),0) | I14: =IF(AND(B14="",C14="",D14="",E14="",F14=""),"",IF(OR(B14="",C14="",E14=""),"БЛОК: нужны дата, тип операции и сумма",IF(N(E14)<=0,"БЛОК: сумма должна быть больше нуля",IF(AND(G14<>0,F14=""),"БЛОК: не указан акт — платёж не отнесён к конкретному акту. Распределите его документально (назначение платежа, соглашение, письмо) и укажите акт: без этого долг на первый день просрочки и проценты посчитать нельзя",IF(AND(F14<>"",COUNTIF('Долг по актам'!$B$5:$B$34,F14)=0),"БЛОК: такого акта нет на листе «Долг по актам» — добавьте акт или исправьте идентификатор",IF(SUMPRODUCT((($C$5:$C$504="Оплата")+($C$5:$C$504="Зачёт аванса по договору")>0)*($C$5:$C$504<>C14)*($E$5:$E$504=E14)*(($D$5:$D$504=D14)*(D14<>"")+($B$5:$B$504=B14)*(B14<>"")>0))>0,"БЛОК: двойной учёт аванса — эта сумма введена и как «Оплата», и как «Зачёт аванса по договору» с тем же документом или той же датой. Аванс, зачтённый в акт, учитывается один раз: оставьте одну операцию","ок")))))) | J14: =IF(AND(B14="",C14="",E14=""),"",SUM($G$5:G14))
A15: 11 | G15: =IF(OR(C15="",E15=""),0,IF(C15="Начисление по акту",E15,IF(OR(C15="Оплата",C15="Зачёт аванса по договору"),-E15,IF(C15="Корректировка (подписана обеими сторонами)",E15,0)))) | H15: =IF(OR(C15="Удержание",C15="Зачёт встречного требования",C15="Неустойка заявлена"),N(E15),0) | I15: =IF(AND(B15="",C15="",D15="",E15="",F15=""),"",IF(OR(B15="",C15="",E15=""),"БЛОК: нужны дата, тип операции и сумма",IF(N(E15)<=0,"БЛОК: сумма должна быть больше нуля",IF(AND(G15<>0,F15=""),"БЛОК: не указан акт — платёж не отнесён к конкретному акту. Распределите его документально (назначение платежа, соглашение, письмо) и укажите акт: без этого долг на первый день просрочки и проценты посчитать нельзя",IF(AND(F15<>"",COUNTIF('Долг по актам'!$B$5:$B$34,F15)=0),"БЛОК: такого акта нет на листе «Долг по актам» — добавьте акт или исправьте идентификатор",IF(SUMPRODUCT((($C$5:$C$504="Оплата")+($C$5:$C$504="Зачёт аванса по договору")>0)*($C$5:$C$504<>C15)*($E$5:$E$504=E15)*(($D$5:$D$504=D15)*(D15<>"")+($B$5:$B$504=B15)*(B15<>"")>0))>0,"БЛОК: двойной учёт аванса — эта сумма введена и как «Оплата», и как «Зачёт аванса по договору» с тем же документом или той же датой. Аванс, зачтённый в акт, учитывается один раз: оставьте одну операцию","ок")))))) | J15: =IF(AND(B15="",C15="",E15=""),"",SUM($G$5:G15)) | L15: Это ТЕКУЩИЙ остаток: из него уже вычтены все оплаты, в том числе поступившие после начала просрочки. В расчёт процентов (файл 08) его переносить нельзя — там нужен долг на первый день просрочки по каждому акту. Оба числа берите на листе «Долг по актам».
A16: 12 | G16: =IF(OR(C16="",E16=""),0,IF(C16="Начисление по акту",E16,IF(OR(C16="Оплата",C16="Зачёт аванса по договору"),-E16,IF(C16="Корректировка (подписана обеими сторонами)",E16,0)))) | H16: =IF(OR(C16="Удержание",C16="Зачёт встречного требования",C16="Неустойка заявлена"),N(E16),0) | I16: =IF(AND(B16="",C16="",D16="",E16="",F16=""),"",IF(OR(B16="",C16="",E16=""),"БЛОК: нужны дата, тип операции и сумма",IF(N(E16)<=0,"БЛОК: сумма должна быть больше нуля",IF(AND(G16<>0,F16=""),"БЛОК: не указан акт — платёж не отнесён к конкретному акту. Распределите его документально (назначение платежа, соглашение, письмо) и укажите акт: без этого долг на первый день просрочки и проценты посчитать нельзя",IF(AND(F16<>"",COUNTIF('Долг по актам'!$B$5:$B$34,F16)=0),"БЛОК: такого акта нет на листе «Долг по актам» — добавьте акт или исправьте идентификатор",IF(SUMPRODUCT((($C$5:$C$504="Оплата")+($C$5:$C$504="Зачёт аванса по договору")>0)*($C$5:$C$504<>C16)*($E$5:$E$504=E16)*(($D$5:$D$504=D16)*(D16<>"")+($B$5:$B$504=B16)*(B16<>"")>0))>0,"БЛОК: двойной учёт аванса — эта сумма введена и как «Оплата», и как «Зачёт аванса по договору» с тем же документом или той же датой. Аванс, зачтённый в акт, учитывается один раз: оставьте одну операцию","ок")))))) | J16: =IF(AND(B16="",C16="",E16=""),"",SUM($G$5:G16))
A17: 13 | G17: =IF(OR(C17="",E17=""),0,IF(C17="Начисление по акту",E17,IF(OR(C17="Оплата",C17="Зачёт аванса по договору"),-E17,IF(C17="Корректировка (подписана обеими сторонами)",E17,0)))) | H17: =IF(OR(C17="Удержание",C17="Зачёт встречного требования",C17="Неустойка заявлена"),N(E17),0) | I17: =IF(AND(B17="",C17="",D17="",E17="",F17=""),"",IF(OR(B17="",C17="",E17=""),"БЛОК: нужны дата, тип операции и сумма",IF(N(E17)<=0,"БЛОК: сумма должна быть больше нуля",IF(AND(G17<>0,F17=""),"БЛОК: не указан акт — платёж не отнесён к конкретному акту. Распределите его документально (назначение платежа, соглашение, письмо) и укажите акт: без этого долг на первый день просрочки и проценты посчитать нельзя",IF(AND(F17<>"",COUNTIF('Долг по актам'!$B$5:$B$34,F17)=0),"БЛОК: такого акта нет на листе «Долг по актам» — добавьте акт или исправьте идентификатор",IF(SUMPRODUCT((($C$5:$C$504="Оплата")+($C$5:$C$504="Зачёт аванса по договору")>0)*($C$5:$C$504<>C17)*($E$5:$E$504=E17)*(($D$5:$D$504=D17)*(D17<>"")+($B$5:$B$504=B17)*(B17<>"")>0))>0,"БЛОК: двойной учёт аванса — эта сумма введена и как «Оплата», и как «Зачёт аванса по договору» с тем же документом или той же датой. Аванс, зачтённый в акт, учитывается один раз: оставьте одну операцию","ок")))))) | J17: =IF(AND(B17="",C17="",E17=""),"",SUM($G$5:G17))
A18: 14 | G18: =IF(OR(C18="",E18=""),0,IF(C18="Начисление по акту",E18,IF(OR(C18="Оплата",C18="Зачёт аванса по договору"),-E18,IF(C18="Корректировка (подписана обеими сторонами)",E18,0)))) | H18: =IF(OR(C18="Удержание",C18="Зачёт встречного требования",C18="Неустойка заявлена"),N(E18),0) | I18: =IF(AND(B18="",C18="",D18="",E18="",F18=""),"",IF(OR(B18="",C18="",E18=""),"БЛОК: нужны дата, тип операции и сумма",IF(N(E18)<=0,"БЛОК: сумма должна быть больше нуля",IF(AND(G18<>0,F18=""),"БЛОК: не указан акт — платёж не отнесён к конкретному акту. Распределите его документально (назначение платежа, соглашение, письмо) и укажите акт: без этого долг на первый день просрочки и проценты посчитать нельзя",IF(AND(F18<>"",COUNTIF('Долг по актам'!$B$5:$B$34,F18)=0),"БЛОК: такого акта нет на листе «Долг по актам» — добавьте акт или исправьте идентификатор",IF(SUMPRODUCT((($C$5:$C$504="Оплата")+($C$5:$C$504="Зачёт аванса по договору")>0)*($C$5:$C$504<>C18)*($E$5:$E$504=E18)*(($D$5:$D$504=D18)*(D18<>"")+($B$5:$B$504=B18)*(B18<>"")>0))>0,"БЛОК: двойной учёт аванса — эта сумма введена и как «Оплата», и как «Зачёт аванса по договору» с тем же документом или той же датой. Аванс, зачтённый в акт, учитывается один раз: оставьте одну операцию","ок")))))) | J18: =IF(AND(B18="",C18="",E18=""),"",SUM($G$5:G18))
A19: 15 | G19: =IF(OR(C19="",E19=""),0,IF(C19="Начисление по акту",E19,IF(OR(C19="Оплата",C19="Зачёт аванса по договору"),-E19,IF(C19="Корректировка (подписана обеими сторонами)",E19,0)))) | H19: =IF(OR(C19="Удержание",C19="Зачёт встречного требования",C19="Неустойка заявлена"),N(E19),0) | I19: =IF(AND(B19="",C19="",D19="",E19="",F19=""),"",IF(OR(B19="",C19="",E19=""),"БЛОК: нужны дата, тип операции и сумма",IF(N(E19)<=0,"БЛОК: сумма должна быть больше нуля",IF(AND(G19<>0,F19=""),"БЛОК: не указан акт — платёж не отнесён к конкретному акту. Распределите его документально (назначение платежа, соглашение, письмо) и укажите акт: без этого долг на первый день просрочки и проценты посчитать нельзя",IF(AND(F19<>"",COUNTIF('Долг по актам'!$B$5:$B$34,F19)=0),"БЛОК: такого акта нет на листе «Долг по актам» — добавьте акт или исправьте идентификатор",IF(SUMPRODUCT((($C$5:$C$504="Оплата")+($C$5:$C$504="Зачёт аванса по договору")>0)*($C$5:$C$504<>C19)*($E$5:$E$504=E19)*(($D$5:$D$504=D19)*(D19<>"")+($B$5:$B$504=B19)*(B19<>"")>0))>0,"БЛОК: двойной учёт аванса — эта сумма введена и как «Оплата», и как «Зачёт аванса по договору» с тем же документом или той же датой. Аванс, зачтённый в акт, учитывается один раз: оставьте одну операцию","ок")))))) | J19: =IF(AND(B19="",C19="",E19=""),"",SUM($G$5:G19))
A20: 16 | G20: =IF(OR(C20="",E20=""),0,IF(C20="Начисление по акту",E20,IF(OR(C20="Оплата",C20="Зачёт аванса по договору"),-E20,IF(C20="Корректировка (подписана обеими сторонами)",E20,0)))) | H20: =IF(OR(C20="Удержание",C20="Зачёт встречного требования",C20="Неустойка заявлена"),N(E20),0) | I20: =IF(AND(B20="",C20="",D20="",E20="",F20=""),"",IF(OR(B20="",C20="",E20=""),"БЛОК: нужны дата, тип операции и сумма",IF(N(E20)<=0,"БЛОК: сумма должна быть больше нуля",IF(AND(G20<>0,F20=""),"БЛОК: не указан акт — платёж не отнесён к конкретному акту. Распределите его документально (назначение платежа, соглашение, письмо) и укажите акт: без этого долг на первый день просрочки и проценты посчитать нельзя",IF(AND(F20<>"",COUNTIF('Долг по актам'!$B$5:$B$34,F20)=0),"БЛОК: такого акта нет на листе «Долг по актам» — добавьте акт или исправьте идентификатор",IF(SUMPRODUCT((($C$5:$C$504="Оплата")+($C$5:$C$504="Зачёт аванса по договору")>0)*($C$5:$C$504<>C20)*($E$5:$E$504=E20)*(($D$5:$D$504=D20)*(D20<>"")+($B$5:$B$504=B20)*(B20<>"")>0))>0,"БЛОК: двойной учёт аванса — эта сумма введена и как «Оплата», и как «Зачёт аванса по договору» с тем же документом или той же датой. Аванс, зачтённый в акт, учитывается один раз: оставьте одну операцию","ок")))))) | J20: =IF(AND(B20="",C20="",E20=""),"",SUM($G$5:G20))
A21: 17 | G21: =IF(OR(C21="",E21=""),0,IF(C21="Начисление по акту",E21,IF(OR(C21="Оплата",C21="Зачёт аванса по договору"),-E21,IF(C21="Корректировка (подписана обеими сторонами)",E21,0)))) | H21: =IF(OR(C21="Удержание",C21="Зачёт встречного требования",C21="Неустойка заявлена"),N(E21),0) | I21: =IF(AND(B21="",C21="",D21="",E21="",F21=""),"",IF(OR(B21="",C21="",E21=""),"БЛОК: нужны дата, тип операции и сумма",IF(N(E21)<=0,"БЛОК: сумма должна быть больше нуля",IF(AND(G21<>0,F21=""),"БЛОК: не указан акт — платёж не отнесён к конкретному акту. Распределите его документально (назначение платежа, соглашение, письмо) и укажите акт: без этого долг на первый день просрочки и проценты посчитать нельзя",IF(AND(F21<>"",COUNTIF('Долг по актам'!$B$5:$B$34,F21)=0),"БЛОК: такого акта нет на листе «Долг по актам» — добавьте акт или исправьте идентификатор",IF(SUMPRODUCT((($C$5:$C$504="Оплата")+($C$5:$C$504="Зачёт аванса по договору")>0)*($C$5:$C$504<>C21)*($E$5:$E$504=E21)*(($D$5:$D$504=D21)*(D21<>"")+($B$5:$B$504=B21)*(B21<>"")>0))>0,"БЛОК: двойной учёт аванса — эта сумма введена и как «Оплата», и как «Зачёт аванса по договору» с тем же документом или той же датой. Аванс, зачтённый в акт, учитывается один раз: оставьте одну операцию","ок")))))) | J21: =IF(AND(B21="",C21="",E21=""),"",SUM($G$5:G21))
A22: 18 | G22: =IF(OR(C22="",E22=""),0,IF(C22="Начисление по акту",E22,IF(OR(C22="Оплата",C22="Зачёт аванса по договору"),-E22,IF(C22="Корректировка (подписана обеими сторонами)",E22,0)))) | H22: =IF(OR(C22="Удержание",C22="Зачёт встречного требования",C22="Неустойка заявлена"),N(E22),0) | I22: =IF(AND(B22="",C22="",D22="",E22="",F22=""),"",IF(OR(B22="",C22="",E22=""),"БЛОК: нужны дата, тип операции и сумма",IF(N(E22)<=0,"БЛОК: сумма должна быть больше нуля",IF(AND(G22<>0,F22=""),"БЛОК: не указан акт — платёж не отнесён к конкретному акту. Распределите его документально (назначение платежа, соглашение, письмо) и укажите акт: без этого долг на первый день просрочки и проценты посчитать нельзя",IF(AND(F22<>"",COUNTIF('Долг по актам'!$B$5:$B$34,F22)=0),"БЛОК: такого акта нет на листе «Долг по актам» — добавьте акт или исправьте идентификатор",IF(SUMPRODUCT((($C$5:$C$504="Оплата")+($C$5:$C$504="Зачёт аванса по договору")>0)*($C$5:$C$504<>C22)*($E$5:$E$504=E22)*(($D$5:$D$504=D22)*(D22<>"")+($B$5:$B$504=B22)*(B22<>"")>0))>0,"БЛОК: двойной учёт аванса — эта сумма введена и как «Оплата», и как «Зачёт аванса по договору» с тем же документом или той же датой. Аванс, зачтённый в акт, учитывается один раз: оставьте одну операцию","ок")))))) | J22: =IF(AND(B22="",C22="",E22=""),"",SUM($G$5:G22))
A23: 19 | G23: =IF(OR(C23="",E23=""),0,IF(C23="Начисление по акту",E23,IF(OR(C23="Оплата",C23="Зачёт аванса по договору"),-E23,IF(C23="Корректировка (подписана обеими сторонами)",E23,0)))) | H23: =IF(OR(C23="Удержание",C23="Зачёт встречного требования",C23="Неустойка заявлена"),N(E23),0) | I23: =IF(AND(B23="",C23="",D23="",E23="",F23=""),"",IF(OR(B23="",C23="",E23=""),"БЛОК: нужны дата, тип операции и сумма",IF(N(E23)<=0,"БЛОК: сумма должна быть больше нуля",IF(AND(G23<>0,F23=""),"БЛОК: не указан акт — платёж не отнесён к конкретному акту. Распределите его документально (назначение платежа, соглашение, письмо) и укажите акт: без этого долг на первый день просрочки и проценты посчитать нельзя",IF(AND(F23<>"",COUNTIF('Долг по актам'!$B$5:$B$34,F23)=0),"БЛОК: такого акта нет на листе «Долг по актам» — добавьте акт или исправьте идентификатор",IF(SUMPRODUCT((($C$5:$C$504="Оплата")+($C$5:$C$504="Зачёт аванса по договору")>0)*($C$5:$C$504<>C23)*($E$5:$E$504=E23)*(($D$5:$D$504=D23)*(D23<>"")+($B$5:$B$504=B23)*(B23<>"")>0))>0,"БЛОК: двойной учёт аванса — эта сумма введена и как «Оплата», и как «Зачёт аванса по договору» с тем же документом или той же датой. Аванс, зачтённый в акт, учитывается один раз: оставьте одну операцию","ок")))))) | J23: =IF(AND(B23="",C23="",E23=""),"",SUM($G$5:G23))
A24: 20 | G24: =IF(OR(C24="",E24=""),0,IF(C24="Начисление по акту",E24,IF(OR(C24="Оплата",C24="Зачёт аванса по договору"),-E24,IF(C24="Корректировка (подписана обеими сторонами)",E24,0)))) | H24: =IF(OR(C24="Удержание",C24="Зачёт встречного требования",C24="Неустойка заявлена"),N(E24),0) | I24: =IF(AND(B24="",C24="",D24="",E24="",F24=""),"",IF(OR(B24="",C24="",E24=""),"БЛОК: нужны дата, тип операции и сумма",IF(N(E24)<=0,"БЛОК: сумма должна быть больше нуля",IF(AND(G24<>0,F24=""),"БЛОК: не указан акт — платёж не отнесён к конкретному акту. Распределите его документально (назначение платежа, соглашение, письмо) и укажите акт: без этого долг на первый день просрочки и проценты посчитать нельзя",IF(AND(F24<>"",COUNTIF('Долг по актам'!$B$5:$B$34,F24)=0),"БЛОК: такого акта нет на листе «Долг по актам» — добавьте акт или исправьте идентификатор",IF(SUMPRODUCT((($C$5:$C$504="Оплата")+($C$5:$C$504="Зачёт аванса по договору")>0)*($C$5:$C$504<>C24)*($E$5:$E$504=E24)*(($D$5:$D$504=D24)*(D24<>"")+($B$5:$B$504=B24)*(B24<>"")>0))>0,"БЛОК: двойной учёт аванса — эта сумма введена и как «Оплата», и как «Зачёт аванса по договору» с тем же документом или той же датой. Аванс, зачтённый в акт, учитывается один раз: оставьте одну операцию","ок")))))) | J24: =IF(AND(B24="",C24="",E24=""),"",SUM($G$5:G24))
A25: 21 | G25: =IF(OR(C25="",E25=""),0,IF(C25="Начисление по акту",E25,IF(OR(C25="Оплата",C25="Зачёт аванса по договору"),-E25,IF(C25="Корректировка (подписана обеими сторонами)",E25,0)))) | H25: =IF(OR(C25="Удержание",C25="Зачёт встречного требования",C25="Неустойка заявлена"),N(E25),0) | I25: =IF(AND(B25="",C25="",D25="",E25="",F25=""),"",IF(OR(B25="",C25="",E25=""),"БЛОК: нужны дата, тип операции и сумма",IF(N(E25)<=0,"БЛОК: сумма должна быть больше нуля",IF(AND(G25<>0,F25=""),"БЛОК: не указан акт — платёж не отнесён к конкретному акту. Распределите его документально (назначение платежа, соглашение, письмо) и укажите акт: без этого долг на первый день просрочки и проценты посчитать нельзя",IF(AND(F25<>"",COUNTIF('Долг по актам'!$B$5:$B$34,F25)=0),"БЛОК: такого акта нет на листе «Долг по актам» — добавьте акт или исправьте идентификатор",IF(SUMPRODUCT((($C$5:$C$504="Оплата")+($C$5:$C$504="Зачёт аванса по договору")>0)*($C$5:$C$504<>C25)*($E$5:$E$504=E25)*(($D$5:$D$504=D25)*(D25<>"")+($B$5:$B$504=B25)*(B25<>"")>0))>0,"БЛОК: двойной учёт аванса — эта сумма введена и как «Оплата», и как «Зачёт аванса по договору» с тем же документом или той же датой. Аванс, зачтённый в акт, учитывается один раз: оставьте одну операцию","ок")))))) | J25: =IF(AND(B25="",C25="",E25=""),"",SUM($G$5:G25))
A26: 22 | G26: =IF(OR(C26="",E26=""),0,IF(C26="Начисление по акту",E26,IF(OR(C26="Оплата",C26="Зачёт аванса по договору"),-E26,IF(C26="Корректировка (подписана обеими сторонами)",E26,0)))) | H26: =IF(OR(C26="Удержание",C26="Зачёт встречного требования",C26="Неустойка заявлена"),N(E26),0) | I26: =IF(AND(B26="",C26="",D26="",E26="",F26=""),"",IF(OR(B26="",C26="",E26=""),"БЛОК: нужны дата, тип операции и сумма",IF(N(E26)<=0,"БЛОК: сумма должна быть больше нуля",IF(AND(G26<>0,F26=""),"БЛОК: не указан акт — платёж не отнесён к конкретному акту. Распределите его документально (назначение платежа, соглашение, письмо) и укажите акт: без этого долг на первый день просрочки и проценты посчитать нельзя",IF(AND(F26<>"",COUNTIF('Долг по актам'!$B$5:$B$34,F26)=0),"БЛОК: такого акта нет на листе «Долг по актам» — добавьте акт или исправьте идентификатор",IF(SUMPRODUCT((($C$5:$C$504="Оплата")+($C$5:$C$504="Зачёт аванса по договору")>0)*($C$5:$C$504<>C26)*($E$5:$E$504=E26)*(($D$5:$D$504=D26)*(D26<>"")+($B$5:$B$504=B26)*(B26<>"")>0))>0,"БЛОК: двойной учёт аванса — эта сумма введена и как «Оплата», и как «Зачёт аванса по договору» с тем же документом или той же датой. Аванс, зачтённый в акт, учитывается один раз: оставьте одну операцию","ок")))))) | J26: =IF(AND(B26="",C26="",E26=""),"",SUM($G$5:G26))
A27: 23 | G27: =IF(OR(C27="",E27=""),0,IF(C27="Начисление по акту",E27,IF(OR(C27="Оплата",C27="Зачёт аванса по договору"),-E27,IF(C27="Корректировка (подписана обеими сторонами)",E27,0)))) | H27: =IF(OR(C27="Удержание",C27="Зачёт встречного требования",C27="Неустойка заявлена"),N(E27),0) | I27: =IF(AND(B27="",C27="",D27="",E27="",F27=""),"",IF(OR(B27="",C27="",E27=""),"БЛОК: нужны дата, тип операции и сумма",IF(N(E27)<=0,"БЛОК: сумма должна быть больше нуля",IF(AND(G27<>0,F27=""),"БЛОК: не указан акт — платёж не отнесён к конкретному акту. Распределите его документально (назначение платежа, соглашение, письмо) и укажите акт: без этого долг на первый день просрочки и проценты посчитать нельзя",IF(AND(F27<>"",COUNTIF('Долг по актам'!$B$5:$B$34,F27)=0),"БЛОК: такого акта нет на листе «Долг по актам» — добавьте акт или исправьте идентификатор",IF(SUMPRODUCT((($C$5:$C$504="Оплата")+($C$5:$C$504="Зачёт аванса по договору")>0)*($C$5:$C$504<>C27)*($E$5:$E$504=E27)*(($D$5:$D$504=D27)*(D27<>"")+($B$5:$B$504=B27)*(B27<>"")>0))>0,"БЛОК: двойной учёт аванса — эта сумма введена и как «Оплата», и как «Зачёт аванса по договору» с тем же документом или той же датой. Аванс, зачтённый в акт, учитывается один раз: оставьте одну операцию","ок")))))) | J27: =IF(AND(B27="",C27="",E27=""),"",SUM($G$5:G27))
... A504: 500 | G504: =IF(OR(C504="",E504=""),0,IF(C504="Начисление по акту",E504,IF(OR(C504="Оплата",C504="Зачёт аванса по договору"),-E504,IF(C504="Корректировка (подписана обеими сторонами)",E504,0)))) | H504: =IF(OR(C504="Удержание",C504="Зачёт встречного требования",C504="Неустойка заявлена"),N(E504),0) | I504: =IF(AND(B504="",C504="",D504="",E504="",F504=""),"",IF(OR(B504="",C504="",E504=""),"БЛОК: нужны дата, тип операции и сумма",IF(N(E504)<=0,"БЛОК: сумма должна быть больше нуля",IF(AND(G504<>0,F504=""),"БЛОК: не указан акт — платёж не отнесён к конкретному акту. Распределите его документально (назначение платежа, соглашение, письмо) и укажите акт: без этого долг на первый день просрочки и проценты посчитать нельзя",IF(AND(F504<>"",COUNTIF('Долг по актам'!$B$5:$B$34,F504)=0),"БЛОК: такого акта нет на листе «Долг по актам» — добавьте акт или исправьте идентификатор",IF(SUMPRODUCT((($C$5:$C$504="Оплата")+($C$5:$C$504="Зачёт аванса по договору")>0)*($C$5:$C$504<>C504)*($E$5:$E$504=E504)*(($D$5:$D$504=D504)*(D504<>"")+($B$5:$B$504=B504)*(B504<>"")>0))>0,"БЛОК: двойной учёт аванса — эта сумма введена и как «Оплата», и как «Зачёт аванса по договору» с тем же документом или той же датой. Аванс, зачтённый в акт, учитывается один раз: оставьте одну операцию","ок")))))) | J504: =IF(AND(B504="",C504="",E504=""),"",SUM($G$5:G504))

Sheet Долг по актам
A1: Долг по актам: что переносить в расчёт процентов
A2: Одна строка — один акт (или часть долга) со своим сроком оплаты. Начисления, оплаты и зачёты берутся из листа «Взаиморасчёты» по идентификатору акта. Колонка H — долг на первый день просрочки: он нужен файлу 08, лист «Акты». Колонка J — текущий остаток: он нужен там же для сверки, но не как сумма долга. Оплаты, поступившие в первый день просрочки и позже, переносятся в файл 08, лист «Оплаты», с тем же идентификатором акта.
A4: № | B4: Акт (идентификатор) | C4: Документ (КС-2 / акт: №, дата) | D4: Последний день срока оплаты по этому акту | E4: Первый день просрочки | F4: Начислено и скорректировано, руб. | G4: Оплачено и зачтено до первого дня просрочки, руб. | H4: ДОЛГ НА ПЕРВЫЙ ДЕНЬ ПРОСРОЧКИ, руб. → файл 08, «Акты» | I4: Оплачено с первого дня просрочки, руб. → файл 08, «Оплаты» | J4: Текущий остаток по акту, руб. → файл 08, «Акты», сверка | K4: Проверка | L4: Переносить в файл 08 | N4: Актов к переносу в файл 08 | O4: =COUNTIF(L5:L34,"да")
A5: 1 | E5: =IF(ISNUMBER(D5),D5+1,"") | F5: =IF(B5="","",SUMIFS(Взаиморасчёты!$E$5:$E$504,Взаиморасчёты!$C$5:$C$504,"Начисление по акту",Взаиморасчёты!$F$5:$F$504,B5)+SUMIFS(Взаиморасчёты!$E$5:$E$504,Взаиморасчёты!$C$5:$C$504,"Корректировка (подписана обеими сторонами)",Взаиморасчёты!$F$5:$F$504,B5)) | G5: =IF(OR(B5="",E5=""),"",SUMIFS(Взаиморасчёты!$E$5:$E$504,Взаиморасчёты!$C$5:$C$504,"Оплата",Взаиморасчёты!$F$5:$F$504,B5,Взаиморасчёты!$B$5:$B$504,"<"&E5)+SUMIFS(Взаиморасчёты!$E$5:$E$504,Взаиморасчёты!$C$5:$C$504,"Зачёт аванса по договору",Взаиморасчёты!$F$5:$F$504,B5,Взаиморасчёты!$B$5:$B$504,"<"&E5)) | H5: =IF(OR(B5="",E5=""),"",IF(NOT(ISNUMBER(Взаиморасчёты!$M$10)),"ЗАБЛОКИРОВАН",F5-G5)) | I5: =IF(OR(B5="",E5=""),"",SUMIFS(Взаиморасчёты!$E$5:$E$504,Взаиморасчёты!$C$5:$C$504,"Оплата",Взаиморасчёты!$F$5:$F$504,B5,Взаиморасчёты!$B$5:$B$504,">="&E5)+SUMIFS(Взаиморасчёты!$E$5:$E$504,Взаиморасчёты!$C$5:$C$504,"Зачёт аванса по договору",Взаиморасчёты!$F$5:$F$504,B5,Взаиморасчёты!$B$5:$B$504,">="&E5)) | J5: =IF(OR(B5="",E5=""),"",IF(NOT(ISNUMBER(H5)),"ЗАБЛОКИРОВАН",H5-I5)) | K5: =IF(AND(B5="",C5="",D5=""),"",IF(B5="","БЛОК: нужен идентификатор акта — по нему распределяются оплаты",IF(COUNTIF($B$5:$B$34,B5)>1,"БЛОК: идентификатор акта повторяется — оплату нельзя отнести однозначно",IF(NOT(ISNUMBER(D5)),"БЛОК: нужен последний день срока оплаты по этому акту",IF(COUNTIF(Взаиморасчёты!$F$5:$F$504,B5)=0,"БЛОК: во «Взаиморасчётах» нет ни одной операции по этому акту",IF(NOT(ISNUMBER(Взаиморасчёты!$M$10)),"БЛОК: реестр «Взаиморасчёты» заблокирован (например, двойной учёт аванса или платёж без акта) — исправьте строки с «БЛОК»: до этого долг по акту не посчитан и в файл 08 не переносится",IF(N(H5)<0,"БЛОК: до первого дня просрочки оплачено и зачтено больше, чем начислено по акту — проверьте распределение",IF(N(J5)<0,"БЛОК: оплаты с первого дня просрочки больше долга на первый день просрочки — проверьте распределение","ок")))))))) | L5: =IF(OR(B5="",K5<>"ок"),"",IF(N(H5)>0,"да","нет: долга на первый день просрочки нет")) | N5: Строк с ошибкой в колонке «Проверка» | O5: =COUNTIF(K5:K34,"БЛОК*")
A6: 2 | E6: =IF(ISNUMBER(D6),D6+1,"") | F6: =IF(B6="","",SUMIFS(Взаиморасчёты!$E$5:$E$504,Взаиморасчёты!$C$5:$C$504,"Начисление по акту",Взаиморасчёты!$F$5:$F$504,B6)+SUMIFS(Взаиморасчёты!$E$5:$E$504,Взаиморасчёты!$C$5:$C$504,"Корректировка (подписана обеими сторонами)",Взаиморасчёты!$F$5:$F$504,B6)) | G6: =IF(OR(B6="",E6=""),"",SUMIFS(Взаиморасчёты!$E$5:$E$504,Взаиморасчёты!$C$5:$C$504,"Оплата",Взаиморасчёты!$F$5:$F$504,B6,Взаиморасчёты!$B$5:$B$504,"<"&E6)+SUMIFS(Взаиморасчёты!$E$5:$E$504,Взаиморасчёты!$C$5:$C$504,"Зачёт аванса по договору",Взаиморасчёты!$F$5:$F$504,B6,Взаиморасчёты!$B$5:$B$504,"<"&E6)) | H6: =IF(OR(B6="",E6=""),"",IF(NOT(ISNUMBER(Взаиморасчёты!$M$10)),"ЗАБЛОКИРОВАН",F6-G6)) | I6: =IF(OR(B6="",E6=""),"",SUMIFS(Взаиморасчёты!$E$5:$E$504,Взаиморасчёты!$C$5:$C$504,"Оплата",Взаиморасчёты!$F$5:$F$504,B6,Взаиморасчёты!$B$5:$B$504,">="&E6)+SUMIFS(Взаиморасчёты!$E$5:$E$504,Взаиморасчёты!$C$5:$C$504,"Зачёт аванса по договору",Взаиморасчёты!$F$5:$F$504,B6,Взаиморасчёты!$B$5:$B$504,">="&E6)) | J6: =IF(OR(B6="",E6=""),"",IF(NOT(ISNUMBER(H6)),"ЗАБЛОКИРОВАН",H6-I6)) | K6: =IF(AND(B6="",C6="",D6=""),"",IF(B6="","БЛОК: нужен идентификатор акта — по нему распределяются оплаты",IF(COUNTIF($B$5:$B$34,B6)>1,"БЛОК: идентификатор акта повторяется — оплату нельзя отнести однозначно",IF(NOT(ISNUMBER(D6)),"БЛОК: нужен последний день срока оплаты по этому акту",IF(COUNTIF(Взаиморасчёты!$F$5:$F$504,B6)=0,"БЛОК: во «Взаиморасчётах» нет ни одной операции по этому акту",IF(NOT(ISNUMBER(Взаиморасчёты!$M$10)),"БЛОК: реестр «Взаиморасчёты» заблокирован (например, двойной учёт аванса или платёж без акта) — исправьте строки с «БЛОК»: до этого долг по акту не посчитан и в файл 08 не переносится",IF(N(H6)<0,"БЛОК: до первого дня просрочки оплачено и зачтено больше, чем начислено по акту — проверьте распределение",IF(N(J6)<0,"БЛОК: оплаты с первого дня просрочки больше долга на первый день просрочки — проверьте распределение","ок")))))))) | L6: =IF(OR(B6="",K6<>"ок"),"",IF(N(H6)>0,"да","нет: долга на первый день просрочки нет")) | N6: Записей ниже таблицы (не учтены) | O6: =COUNTA(A35:L1000)
A7: 3 | E7: =IF(ISNUMBER(D7),D7+1,"") | F7: =IF(B7="","",SUMIFS(Взаиморасчёты!$E$5:$E$504,Взаиморасчёты!$C$5:$C$504,"Начисление по акту",Взаиморасчёты!$F$5:$F$504,B7)+SUMIFS(Взаиморасчёты!$E$5:$E$504,Взаиморасчёты!$C$5:$C$504,"Корректировка (подписана обеими сторонами)",Взаиморасчёты!$F$5:$F$504,B7)) | G7: =IF(OR(B7="",E7=""),"",SUMIFS(Взаиморасчёты!$E$5:$E$504,Взаиморасчёты!$C$5:$C$504,"Оплата",Взаиморасчёты!$F$5:$F$504,B7,Взаиморасчёты!$B$5:$B$504,"<"&E7)+SUMIFS(Взаиморасчёты!$E$5:$E$504,Взаиморасчёты!$C$5:$C$504,"Зачёт аванса по договору",Взаиморасчёты!$F$5:$F$504,B7,Взаиморасчёты!$B$5:$B$504,"<"&E7)) | H7: =IF(OR(B7="",E7=""),"",IF(NOT(ISNUMBER(Взаиморасчёты!$M$10)),"ЗАБЛОКИРОВАН",F7-G7)) | I7: =IF(OR(B7="",E7=""),"",SUMIFS(Взаиморасчёты!$E$5:$E$504,Взаиморасчёты!$C$5:$C$504,"Оплата",Взаиморасчёты!$F$5:$F$504,B7,Взаиморасчёты!$B$5:$B$504,">="&E7)+SUMIFS(Взаиморасчёты!$E$5:$E$504,Взаиморасчёты!$C$5:$C$504,"Зачёт аванса по договору",Взаиморасчёты!$F$5:$F$504,B7,Взаиморасчёты!$B$5:$B$504,">="&E7)) | J7: =IF(OR(B7="",E7=""),"",IF(NOT(ISNUMBER(H7)),"ЗАБЛОКИРОВАН",H7-I7)) | K7: =IF(AND(B7="",C7="",D7=""),"",IF(B7="","БЛОК: нужен идентификатор акта — по нему распределяются оплаты",IF(COUNTIF($B$5:$B$34,B7)>1,"БЛОК: идентификатор акта повторяется — оплату нельзя отнести однозначно",IF(NOT(ISNUMBER(D7)),"БЛОК: нужен последний день срока оплаты по этому акту",IF(COUNTIF(Взаиморасчёты!$F$5:$F$504,B7)=0,"БЛОК: во «Взаиморасчётах» нет ни одной операции по этому акту",IF(NOT(ISNUMBER(Взаиморасчёты!$M$10)),"БЛОК: реестр «Взаиморасчёты» заблокирован (например, двойной учёт аванса или платёж без акта) — исправьте строки с «БЛОК»: до этого долг по акту не посчитан и в файл 08 не переносится",IF(N(H7)<0,"БЛОК: до первого дня просрочки оплачено и зачтено больше, чем начислено по акту — проверьте распределение",IF(N(J7)<0,"БЛОК: оплаты с первого дня просрочки больше долга на первый день просрочки — проверьте распределение","ок")))))))) | L7: =IF(OR(B7="",K7<>"ок"),"",IF(N(H7)>0,"да","нет: долга на первый день просрочки нет")) | N7: Долг на первый день просрочки, всего по переносимым актам, руб. | O7: =IF(OR(O5>0,O6>0),"ИТОГ ЗАБЛОКИРОВАН: см. колонку «Проверка»",SUMIF(L5:L34,"да",H5:H34))
A8: 4 | E8: =IF(ISNUMBER(D8),D8+1,"") | F8: =IF(B8="","",SUMIFS(Взаиморасчёты!$E$5:$E$504,Взаиморасчёты!$C$5:$C$504,"Начисление по акту",Взаиморасчёты!$F$5:$F$504,B8)+SUMIFS(Взаиморасчёты!$E$5:$E$504,Взаиморасчёты!$C$5:$C$504,"Корректировка (подписана обеими сторонами)",Взаиморасчёты!$F$5:$F$504,B8)) | G8: =IF(OR(B8="",E8=""),"",SUMIFS(Взаиморасчёты!$E$5:$E$504,Взаиморасчёты!$C$5:$C$504,"Оплата",Взаиморасчёты!$F$5:$F$504,B8,Взаиморасчёты!$B$5:$B$504,"<"&E8)+SUMIFS(Взаиморасчёты!$E$5:$E$504,Взаиморасчёты!$C$5:$C$504,"Зачёт аванса по договору",Взаиморасчёты!$F$5:$F$504,B8,Взаиморасчёты!$B$5:$B$504,"<"&E8)) | H8: =IF(OR(B8="",E8=""),"",IF(NOT(ISNUMBER(Взаиморасчёты!$M$10)),"ЗАБЛОКИРОВАН",F8-G8)) | I8: =IF(OR(B8="",E8=""),"",SUMIFS(Взаиморасчёты!$E$5:$E$504,Взаиморасчёты!$C$5:$C$504,"Оплата",Взаиморасчёты!$F$5:$F$504,B8,Взаиморасчёты!$B$5:$B$504,">="&E8)+SUMIFS(Взаиморасчёты!$E$5:$E$504,Взаиморасчёты!$C$5:$C$504,"Зачёт аванса по договору",Взаиморасчёты!$F$5:$F$504,B8,Взаиморасчёты!$B$5:$B$504,">="&E8)) | J8: =IF(OR(B8="",E8=""),"",IF(NOT(ISNUMBER(H8)),"ЗАБЛОКИРОВАН",H8-I8)) | K8: =IF(AND(B8="",C8="",D8=""),"",IF(B8="","БЛОК: нужен идентификатор акта — по нему распределяются оплаты",IF(COUNTIF($B$5:$B$34,B8)>1,"БЛОК: идентификатор акта повторяется — оплату нельзя отнести однозначно",IF(NOT(ISNUMBER(D8)),"БЛОК: нужен последний день срока оплаты по этому акту",IF(COUNTIF(Взаиморасчёты!$F$5:$F$504,B8)=0,"БЛОК: во «Взаиморасчётах» нет ни одной операции по этому акту",IF(NOT(ISNUMBER(Взаиморасчёты!$M$10)),"БЛОК: реестр «Взаиморасчёты» заблокирован (например, двойной учёт аванса или платёж без акта) — исправьте строки с «БЛОК»: до этого долг по акту не посчитан и в файл 08 не переносится",IF(N(H8)<0,"БЛОК: до первого дня просрочки оплачено и зачтено больше, чем начислено по акту — проверьте распределение",IF(N(J8)<0,"БЛОК: оплаты с первого дня просрочки больше долга на первый день просрочки — проверьте распределение","ок")))))))) | L8: =IF(OR(B8="",K8<>"ок"),"",IF(N(H8)>0,"да","нет: долга на первый день просрочки нет")) | N8: Текущий остаток, всего по переносимым актам, руб. | O8: =IF(OR(O5>0,O6>0),"ИТОГ ЗАБЛОКИРОВАН: см. колонку «Проверка»",SUMIF(L5:L34,"да",J5:J34))
A9: 5 | E9: =IF(ISNUMBER(D9),D9+1,"") | F9: =IF(B9="","",SUMIFS(Взаиморасчёты!$E$5:$E$504,Взаиморасчёты!$C$5:$C$504,"Начисление по акту",Взаиморасчёты!$F$5:$F$504,B9)+SUMIFS(Взаиморасчёты!$E$5:$E$504,Взаиморасчёты!$C$5:$C$504,"Корректировка (подписана обеими сторонами)",Взаиморасчёты!$F$5:$F$504,B9)) | G9: =IF(OR(B9="",E9=""),"",SUMIFS(Взаиморасчёты!$E$5:$E$504,Взаиморасчёты!$C$5:$C$504,"Оплата",Взаиморасчёты!$F$5:$F$504,B9,Взаиморасчёты!$B$5:$B$504,"<"&E9)+SUMIFS(Взаиморасчёты!$E$5:$E$504,Взаиморасчёты!$C$5:$C$504,"Зачёт аванса по договору",Взаиморасчёты!$F$5:$F$504,B9,Взаиморасчёты!$B$5:$B$504,"<"&E9)) | H9: =IF(OR(B9="",E9=""),"",IF(NOT(ISNUMBER(Взаиморасчёты!$M$10)),"ЗАБЛОКИРОВАН",F9-G9)) | I9: =IF(OR(B9="",E9=""),"",SUMIFS(Взаиморасчёты!$E$5:$E$504,Взаиморасчёты!$C$5:$C$504,"Оплата",Взаиморасчёты!$F$5:$F$504,B9,Взаиморасчёты!$B$5:$B$504,">="&E9)+SUMIFS(Взаиморасчёты!$E$5:$E$504,Взаиморасчёты!$C$5:$C$504,"Зачёт аванса по договору",Взаиморасчёты!$F$5:$F$504,B9,Взаиморасчёты!$B$5:$B$504,">="&E9)) | J9: =IF(OR(B9="",E9=""),"",IF(NOT(ISNUMBER(H9)),"ЗАБЛОКИРОВАН",H9-I9)) | K9: =IF(AND(B9="",C9="",D9=""),"",IF(B9="","БЛОК: нужен идентификатор акта — по нему распределяются оплаты",IF(COUNTIF($B$5:$B$34,B9)>1,"БЛОК: идентификатор акта повторяется — оплату нельзя отнести однозначно",IF(NOT(ISNUMBER(D9)),"БЛОК: нужен последний день срока оплаты по этому акту",IF(COUNTIF(Взаиморасчёты!$F$5:$F$504,B9)=0,"БЛОК: во «Взаиморасчётах» нет ни одной операции по этому акту",IF(NOT(ISNUMBER(Взаиморасчёты!$M$10)),"БЛОК: реестр «Взаиморасчёты» заблокирован (например, двойной учёт аванса или платёж без акта) — исправьте строки с «БЛОК»: до этого долг по акту не посчитан и в файл 08 не переносится",IF(N(H9)<0,"БЛОК: до первого дня просрочки оплачено и зачтено больше, чем начислено по акту — проверьте распределение",IF(N(J9)<0,"БЛОК: оплаты с первого дня просрочки больше долга на первый день просрочки — проверьте распределение","ок")))))))) | L9: =IF(OR(B9="",K9<>"ок"),"",IF(N(H9)>0,"да","нет: долга на первый день просрочки нет"))
A10: 6 | E10: =IF(ISNUMBER(D10),D10+1,"") | F10: =IF(B10="","",SUMIFS(Взаиморасчёты!$E$5:$E$504,Взаиморасчёты!$C$5:$C$504,"Начисление по акту",Взаиморасчёты!$F$5:$F$504,B10)+SUMIFS(Взаиморасчёты!$E$5:$E$504,Взаиморасчёты!$C$5:$C$504,"Корректировка (подписана обеими сторонами)",Взаиморасчёты!$F$5:$F$504,B10)) | G10: =IF(OR(B10="",E10=""),"",SUMIFS(Взаиморасчёты!$E$5:$E$504,Взаиморасчёты!$C$5:$C$504,"Оплата",Взаиморасчёты!$F$5:$F$504,B10,Взаиморасчёты!$B$5:$B$504,"<"&E10)+SUMIFS(Взаиморасчёты!$E$5:$E$504,Взаиморасчёты!$C$5:$C$504,"Зачёт аванса по договору",Взаиморасчёты!$F$5:$F$504,B10,Взаиморасчёты!$B$5:$B$504,"<"&E10)) | H10: =IF(OR(B10="",E10=""),"",IF(NOT(ISNUMBER(Взаиморасчёты!$M$10)),"ЗАБЛОКИРОВАН",F10-G10)) | I10: =IF(OR(B10="",E10=""),"",SUMIFS(Взаиморасчёты!$E$5:$E$504,Взаиморасчёты!$C$5:$C$504,"Оплата",Взаиморасчёты!$F$5:$F$504,B10,Взаиморасчёты!$B$5:$B$504,">="&E10)+SUMIFS(Взаиморасчёты!$E$5:$E$504,Взаиморасчёты!$C$5:$C$504,"Зачёт аванса по договору",Взаиморасчёты!$F$5:$F$504,B10,Взаиморасчёты!$B$5:$B$504,">="&E10)) | J10: =IF(OR(B10="",E10=""),"",IF(NOT(ISNUMBER(H10)),"ЗАБЛОКИРОВАН",H10-I10)) | K10: =IF(AND(B10="",C10="",D10=""),"",IF(B10="","БЛОК: нужен идентификатор акта — по нему распределяются оплаты",IF(COUNTIF($B$5:$B$34,B10)>1,"БЛОК: идентификатор акта повторяется — оплату нельзя отнести однозначно",IF(NOT(ISNUMBER(D10)),"БЛОК: нужен последний день срока оплаты по этому акту",IF(COUNTIF(Взаиморасчёты!$F$5:$F$504,B10)=0,"БЛОК: во «Взаиморасчётах» нет ни одной операции по этому акту",IF(NOT(ISNUMBER(Взаиморасчёты!$M$10)),"БЛОК: реестр «Взаиморасчёты» заблокирован (например, двойной учёт аванса или платёж без акта) — исправьте строки с «БЛОК»: до этого долг по акту не посчитан и в файл 08 не переносится",IF(N(H10)<0,"БЛОК: до первого дня просрочки оплачено и зачтено больше, чем начислено по акту — проверьте распределение",IF(N(J10)<0,"БЛОК: оплаты с первого дня просрочки больше долга на первый день просрочки — проверьте распределение","ок")))))))) | L10: =IF(OR(B10="",K10<>"ок"),"",IF(N(H10)>0,"да","нет: долга на первый день просрочки нет"))
A11: 7 | E11: =IF(ISNUMBER(D11),D11+1,"") | F11: =IF(B11="","",SUMIFS(Взаиморасчёты!$E$5:$E$504,Взаиморасчёты!$C$5:$C$504,"Начисление по акту",Взаиморасчёты!$F$5:$F$504,B11)+SUMIFS(Взаиморасчёты!$E$5:$E$504,Взаиморасчёты!$C$5:$C$504,"Корректировка (подписана обеими сторонами)",Взаиморасчёты!$F$5:$F$504,B11)) | G11: =IF(OR(B11="",E11=""),"",SUMIFS(Взаиморасчёты!$E$5:$E$504,Взаиморасчёты!$C$5:$C$504,"Оплата",Взаиморасчёты!$F$5:$F$504,B11,Взаиморасчёты!$B$5:$B$504,"<"&E11)+SUMIFS(Взаиморасчёты!$E$5:$E$504,Взаиморасчёты!$C$5:$C$504,"Зачёт аванса по договору",Взаиморасчёты!$F$5:$F$504,B11,Взаиморасчёты!$B$5:$B$504,"<"&E11)) | H11: =IF(OR(B11="",E11=""),"",IF(NOT(ISNUMBER(Взаиморасчёты!$M$10)),"ЗАБЛОКИРОВАН",F11-G11)) | I11: =IF(OR(B11="",E11=""),"",SUMIFS(Взаиморасчёты!$E$5:$E$504,Взаиморасчёты!$C$5:$C$504,"Оплата",Взаиморасчёты!$F$5:$F$504,B11,Взаиморасчёты!$B$5:$B$504,">="&E11)+SUMIFS(Взаиморасчёты!$E$5:$E$504,Взаиморасчёты!$C$5:$C$504,"Зачёт аванса по договору",Взаиморасчёты!$F$5:$F$504,B11,Взаиморасчёты!$B$5:$B$504,">="&E11)) | J11: =IF(OR(B11="",E11=""),"",IF(NOT(ISNUMBER(H11)),"ЗАБЛОКИРОВАН",H11-I11)) | K11: =IF(AND(B11="",C11="",D11=""),"",IF(B11="","БЛОК: нужен идентификатор акта — по нему распределяются оплаты",IF(COUNTIF($B$5:$B$34,B11)>1,"БЛОК: идентификатор акта повторяется — оплату нельзя отнести однозначно",IF(NOT(ISNUMBER(D11)),"БЛОК: нужен последний день срока оплаты по этому акту",IF(COUNTIF(Взаиморасчёты!$F$5:$F$504,B11)=0,"БЛОК: во «Взаиморасчётах» нет ни одной операции по этому акту",IF(NOT(ISNUMBER(Взаиморасчёты!$M$10)),"БЛОК: реестр «Взаиморасчёты» заблокирован (например, двойной учёт аванса или платёж без акта) — исправьте строки с «БЛОК»: до этого долг по акту не посчитан и в файл 08 не переносится",IF(N(H11)<0,"БЛОК: до первого дня просрочки оплачено и зачтено больше, чем начислено по акту — проверьте распределение",IF(N(J11)<0,"БЛОК: оплаты с первого дня просрочки больше долга на первый день просрочки — проверьте распределение","ок")))))))) | L11: =IF(OR(B11="",K11<>"ок"),"",IF(N(H11)>0,"да","нет: долга на первый день просрочки нет"))
A12: 8 | E12: =IF(ISNUMBER(D12),D12+1,"") | F12: =IF(B12="","",SUMIFS(Взаиморасчёты!$E$5:$E$504,Взаиморасчёты!$C$5:$C$504,"Начисление по акту",Взаиморасчёты!$F$5:$F$504,B12)+SUMIFS(Взаиморасчёты!$E$5:$E$504,Взаиморасчёты!$C$5:$C$504,"Корректировка (подписана обеими сторонами)",Взаиморасчёты!$F$5:$F$504,B12)) | G12: =IF(OR(B12="",E12=""),"",SUMIFS(Взаиморасчёты!$E$5:$E$504,Взаиморасчёты!$C$5:$C$504,"Оплата",Взаиморасчёты!$F$5:$F$504,B12,Взаиморасчёты!$B$5:$B$504,"<"&E12)+SUMIFS(Взаиморасчёты!$E$5:$E$504,Взаиморасчёты!$C$5:$C$504,"Зачёт аванса по договору",Взаиморасчёты!$F$5:$F$504,B12,Взаиморасчёты!$B$5:$B$504,"<"&E12)) | H12: =IF(OR(B12="",E12=""),"",IF(NOT(ISNUMBER(Взаиморасчёты!$M$10)),"ЗАБЛОКИРОВАН",F12-G12)) | I12: =IF(OR(B12="",E12=""),"",SUMIFS(Взаиморасчёты!$E$5:$E$504,Взаиморасчёты!$C$5:$C$504,"Оплата",Взаиморасчёты!$F$5:$F$504,B12,Взаиморасчёты!$B$5:$B$504,">="&E12)+SUMIFS(Взаиморасчёты!$E$5:$E$504,Взаиморасчёты!$C$5:$C$504,"Зачёт аванса по договору",Взаиморасчёты!$F$5:$F$504,B12,Взаиморасчёты!$B$5:$B$504,">="&E12)) | J12: =IF(OR(B12="",E12=""),"",IF(NOT(ISNUMBER(H12)),"ЗАБЛОКИРОВАН",H12-I12)) | K12: =IF(AND(B12="",C12="",D12=""),"",IF(B12="","БЛОК: нужен идентификатор акта — по нему распределяются оплаты",IF(COUNTIF($B$5:$B$34,B12)>1,"БЛОК: идентификатор акта повторяется — оплату нельзя отнести однозначно",IF(NOT(ISNUMBER(D12)),"БЛОК: нужен последний день срока оплаты по этому акту",IF(COUNTIF(Взаиморасчёты!$F$5:$F$504,B12)=0,"БЛОК: во «Взаиморасчётах» нет ни одной операции по этому акту",IF(NOT(ISNUMBER(Взаиморасчёты!$M$10)),"БЛОК: реестр «Взаиморасчёты» заблокирован (например, двойной учёт аванса или платёж без акта) — исправьте строки с «БЛОК»: до этого долг по акту не посчитан и в файл 08 не переносится",IF(N(H12)<0,"БЛОК: до первого дня просрочки оплачено и зачтено больше, чем начислено по акту — проверьте распределение",IF(N(J12)<0,"БЛОК: оплаты с первого дня просрочки больше долга на первый день просрочки — проверьте распределение","ок")))))))) | L12: =IF(OR(B12="",K12<>"ок"),"",IF(N(H12)>0,"да","нет: долга на первый день просрочки нет"))
A13: 9 | E13: =IF(ISNUMBER(D13),D13+1,"") | F13: =IF(B13="","",SUMIFS(Взаиморасчёты!$E$5:$E$504,Взаиморасчёты!$C$5:$C$504,"Начисление по акту",Взаиморасчёты!$F$5:$F$504,B13)+SUMIFS(Взаиморасчёты!$E$5:$E$504,Взаиморасчёты!$C$5:$C$504,"Корректировка (подписана обеими сторонами)",Взаиморасчёты!$F$5:$F$504,B13)) | G13: =IF(OR(B13="",E13=""),"",SUMIFS(Взаиморасчёты!$E$5:$E$504,Взаиморасчёты!$C$5:$C$504,"Оплата",Взаиморасчёты!$F$5:$F$504,B13,Взаиморасчёты!$B$5:$B$504,"<"&E13)+SUMIFS(Взаиморасчёты!$E$5:$E$504,Взаиморасчёты!$C$5:$C$504,"Зачёт аванса по договору",Взаиморасчёты!$F$5:$F$504,B13,Взаиморасчёты!$B$5:$B$504,"<"&E13)) | H13: =IF(OR(B13="",E13=""),"",IF(NOT(ISNUMBER(Взаиморасчёты!$M$10)),"ЗАБЛОКИРОВАН",F13-G13)) | I13: =IF(OR(B13="",E13=""),"",SUMIFS(Взаиморасчёты!$E$5:$E$504,Взаиморасчёты!$C$5:$C$504,"Оплата",Взаиморасчёты!$F$5:$F$504,B13,Взаиморасчёты!$B$5:$B$504,">="&E13)+SUMIFS(Взаиморасчёты!$E$5:$E$504,Взаиморасчёты!$C$5:$C$504,"Зачёт аванса по договору",Взаиморасчёты!$F$5:$F$504,B13,Взаиморасчёты!$B$5:$B$504,">="&E13)) | J13: =IF(OR(B13="",E13=""),"",IF(NOT(ISNUMBER(H13)),"ЗАБЛОКИРОВАН",H13-I13)) | K13: =IF(AND(B13="",C13="",D13=""),"",IF(B13="","БЛОК: нужен идентификатор акта — по нему распределяются оплаты",IF(COUNTIF($B$5:$B$34,B13)>1,"БЛОК: идентификатор акта повторяется — оплату нельзя отнести однозначно",IF(NOT(ISNUMBER(D13)),"БЛОК: нужен последний день срока оплаты по этому акту",IF(COUNTIF(Взаиморасчёты!$F$5:$F$504,B13)=0,"БЛОК: во «Взаиморасчётах» нет ни одной операции по этому акту",IF(NOT(ISNUMBER(Взаиморасчёты!$M$10)),"БЛОК: реестр «Взаиморасчёты» заблокирован (например, двойной учёт аванса или платёж без акта) — исправьте строки с «БЛОК»: до этого долг по акту не посчитан и в файл 08 не переносится",IF(N(H13)<0,"БЛОК: до первого дня просрочки оплачено и зачтено больше, чем начислено по акту — проверьте распределение",IF(N(J13)<0,"БЛОК: оплаты с первого дня просрочки больше долга на первый день просрочки — проверьте распределение","ок")))))))) | L13: =IF(OR(B13="",K13<>"ок"),"",IF(N(H13)>0,"да","нет: долга на первый день просрочки нет"))
A14: 10 | E14: =IF(ISNUMBER(D14),D14+1,"") | F14: =IF(B14="","",SUMIFS(Взаиморасчёты!$E$5:$E$504,Взаиморасчёты!$C$5:$C$504,"Начисление по акту",Взаиморасчёты!$F$5:$F$504,B14)+SUMIFS(Взаиморасчёты!$E$5:$E$504,Взаиморасчёты!$C$5:$C$504,"Корректировка (подписана обеими сторонами)",Взаиморасчёты!$F$5:$F$504,B14)) | G14: =IF(OR(B14="",E14=""),"",SUMIFS(Взаиморасчёты!$E$5:$E$504,Взаиморасчёты!$C$5:$C$504,"Оплата",Взаиморасчёты!$F$5:$F$504,B14,Взаиморасчёты!$B$5:$B$504,"<"&E14)+SUMIFS(Взаиморасчёты!$E$5:$E$504,Взаиморасчёты!$C$5:$C$504,"Зачёт аванса по договору",Взаиморасчёты!$F$5:$F$504,B14,Взаиморасчёты!$B$5:$B$504,"<"&E14)) | H14: =IF(OR(B14="",E14=""),"",IF(NOT(ISNUMBER(Взаиморасчёты!$M$10)),"ЗАБЛОКИРОВАН",F14-G14)) | I14: =IF(OR(B14="",E14=""),"",SUMIFS(Взаиморасчёты!$E$5:$E$504,Взаиморасчёты!$C$5:$C$504,"Оплата",Взаиморасчёты!$F$5:$F$504,B14,Взаиморасчёты!$B$5:$B$504,">="&E14)+SUMIFS(Взаиморасчёты!$E$5:$E$504,Взаиморасчёты!$C$5:$C$504,"Зачёт аванса по договору",Взаиморасчёты!$F$5:$F$504,B14,Взаиморасчёты!$B$5:$B$504,">="&E14)) | J14: =IF(OR(B14="",E14=""),"",IF(NOT(ISNUMBER(H14)),"ЗАБЛОКИРОВАН",H14-I14)) | K14: =IF(AND(B14="",C14="",D14=""),"",IF(B14="","БЛОК: нужен идентификатор акта — по нему распределяются оплаты",IF(COUNTIF($B$5:$B$34,B14)>1,"БЛОК: идентификатор акта повторяется — оплату нельзя отнести однозначно",IF(NOT(ISNUMBER(D14)),"БЛОК: нужен последний день срока оплаты по этому акту",IF(COUNTIF(Взаиморасчёты!$F$5:$F$504,B14)=0,"БЛОК: во «Взаиморасчётах» нет ни одной операции по этому акту",IF(NOT(ISNUMBER(Взаиморасчёты!$M$10)),"БЛОК: реестр «Взаиморасчёты» заблокирован (например, двойной учёт аванса или платёж без акта) — исправьте строки с «БЛОК»: до этого долг по акту не посчитан и в файл 08 не переносится",IF(N(H14)<0,"БЛОК: до первого дня просрочки оплачено и зачтено больше, чем начислено по акту — проверьте распределение",IF(N(J14)<0,"БЛОК: оплаты с первого дня просрочки больше долга на первый день просрочки — проверьте распределение","ок")))))))) | L14: =IF(OR(B14="",K14<>"ок"),"",IF(N(H14)>0,"да","нет: долга на первый день просрочки нет"))
A15: 11 | E15: =IF(ISNUMBER(D15),D15+1,"") | F15: =IF(B15="","",SUMIFS(Взаиморасчёты!$E$5:$E$504,Взаиморасчёты!$C$5:$C$504,"Начисление по акту",Взаиморасчёты!$F$5:$F$504,B15)+SUMIFS(Взаиморасчёты!$E$5:$E$504,Взаиморасчёты!$C$5:$C$504,"Корректировка (подписана обеими сторонами)",Взаиморасчёты!$F$5:$F$504,B15)) | G15: =IF(OR(B15="",E15=""),"",SUMIFS(Взаиморасчёты!$E$5:$E$504,Взаиморасчёты!$C$5:$C$504,"Оплата",Взаиморасчёты!$F$5:$F$504,B15,Взаиморасчёты!$B$5:$B$504,"<"&E15)+SUMIFS(Взаиморасчёты!$E$5:$E$504,Взаиморасчёты!$C$5:$C$504,"Зачёт аванса по договору",Взаиморасчёты!$F$5:$F$504,B15,Взаиморасчёты!$B$5:$B$504,"<"&E15)) | H15: =IF(OR(B15="",E15=""),"",IF(NOT(ISNUMBER(Взаиморасчёты!$M$10)),"ЗАБЛОКИРОВАН",F15-G15)) | I15: =IF(OR(B15="",E15=""),"",SUMIFS(Взаиморасчёты!$E$5:$E$504,Взаиморасчёты!$C$5:$C$504,"Оплата",Взаиморасчёты!$F$5:$F$504,B15,Взаиморасчёты!$B$5:$B$504,">="&E15)+SUMIFS(Взаиморасчёты!$E$5:$E$504,Взаиморасчёты!$C$5:$C$504,"Зачёт аванса по договору",Взаиморасчёты!$F$5:$F$504,B15,Взаиморасчёты!$B$5:$B$504,">="&E15)) | J15: =IF(OR(B15="",E15=""),"",IF(NOT(ISNUMBER(H15)),"ЗАБЛОКИРОВАН",H15-I15)) | K15: =IF(AND(B15="",C15="",D15=""),"",IF(B15="","БЛОК: нужен идентификатор акта — по нему распределяются оплаты",IF(COUNTIF($B$5:$B$34,B15)>1,"БЛОК: идентификатор акта повторяется — оплату нельзя отнести однозначно",IF(NOT(ISNUMBER(D15)),"БЛОК: нужен последний день срока оплаты по этому акту",IF(COUNTIF(Взаиморасчёты!$F$5:$F$504,B15)=0,"БЛОК: во «Взаиморасчётах» нет ни одной операции по этому акту",IF(NOT(ISNUMBER(Взаиморасчёты!$M$10)),"БЛОК: реестр «Взаиморасчёты» заблокирован (например, двойной учёт аванса или платёж без акта) — исправьте строки с «БЛОК»: до этого долг по акту не посчитан и в файл 08 не переносится",IF(N(H15)<0,"БЛОК: до первого дня просрочки оплачено и зачтено больше, чем начислено по акту — проверьте распределение",IF(N(J15)<0,"БЛОК: оплаты с первого дня просрочки больше долга на первый день просрочки — проверьте распределение","ок")))))))) | L15: =IF(OR(B15="",K15<>"ок"),"",IF(N(H15)>0,"да","нет: долга на первый день просрочки нет"))
A16: 12 | E16: =IF(ISNUMBER(D16),D16+1,"") | F16: =IF(B16="","",SUMIFS(Взаиморасчёты!$E$5:$E$504,Взаиморасчёты!$C$5:$C$504,"Начисление по акту",Взаиморасчёты!$F$5:$F$504,B16)+SUMIFS(Взаиморасчёты!$E$5:$E$504,Взаиморасчёты!$C$5:$C$504,"Корректировка (подписана обеими сторонами)",Взаиморасчёты!$F$5:$F$504,B16)) | G16: =IF(OR(B16="",E16=""),"",SUMIFS(Взаиморасчёты!$E$5:$E$504,Взаиморасчёты!$C$5:$C$504,"Оплата",Взаиморасчёты!$F$5:$F$504,B16,Взаиморасчёты!$B$5:$B$504,"<"&E16)+SUMIFS(Взаиморасчёты!$E$5:$E$504,Взаиморасчёты!$C$5:$C$504,"Зачёт аванса по договору",Взаиморасчёты!$F$5:$F$504,B16,Взаиморасчёты!$B$5:$B$504,"<"&E16)) | H16: =IF(OR(B16="",E16=""),"",IF(NOT(ISNUMBER(Взаиморасчёты!$M$10)),"ЗАБЛОКИРОВАН",F16-G16)) | I16: =IF(OR(B16="",E16=""),"",SUMIFS(Взаиморасчёты!$E$5:$E$504,Взаиморасчёты!$C$5:$C$504,"Оплата",Взаиморасчёты!$F$5:$F$504,B16,Взаиморасчёты!$B$5:$B$504,">="&E16)+SUMIFS(Взаиморасчёты!$E$5:$E$504,Взаиморасчёты!$C$5:$C$504,"Зачёт аванса по договору",Взаиморасчёты!$F$5:$F$504,B16,Взаиморасчёты!$B$5:$B$504,">="&E16)) | J16: =IF(OR(B16="",E16=""),"",IF(NOT(ISNUMBER(H16)),"ЗАБЛОКИРОВАН",H16-I16)) | K16: =IF(AND(B16="",C16="",D16=""),"",IF(B16="","БЛОК: нужен идентификатор акта — по нему распределяются оплаты",IF(COUNTIF($B$5:$B$34,B16)>1,"БЛОК: идентификатор акта повторяется — оплату нельзя отнести однозначно",IF(NOT(ISNUMBER(D16)),"БЛОК: нужен последний день срока оплаты по этому акту",IF(COUNTIF(Взаиморасчёты!$F$5:$F$504,B16)=0,"БЛОК: во «Взаиморасчётах» нет ни одной операции по этому акту",IF(NOT(ISNUMBER(Взаиморасчёты!$M$10)),"БЛОК: реестр «Взаиморасчёты» заблокирован (например, двойной учёт аванса или платёж без акта) — исправьте строки с «БЛОК»: до этого долг по акту не посчитан и в файл 08 не переносится",IF(N(H16)<0,"БЛОК: до первого дня просрочки оплачено и зачтено больше, чем начислено по акту — проверьте распределение",IF(N(J16)<0,"БЛОК: оплаты с первого дня просрочки больше долга на первый день просрочки — проверьте распределение","ок")))))))) | L16: =IF(OR(B16="",K16<>"ок"),"",IF(N(H16)>0,"да","нет: долга на первый день просрочки нет"))
